[2021-02-19 16:21:03 +0000] [59854] [INFO] Starting gunicorn 20.0.4
[2021-02-19 16:21:03 +0000] [59854] [INFO] Listening at: http://127.0.0.1:46710 (59854)
[2021-02-19 16:21:03 +0000] [59854] [INFO] Using worker: sync
[2021-02-19 16:21:03 +0000] [59857] [INFO] Booting worker with pid: 59857
Internal Server Error: /admin/login/
Traceback (most recent call last):
  File "/home/vid/makereport/DTPreport/env/lib/python3.6/site-packages/django/db/backends/utils.py", line 84, in _execute
    return self.cursor.execute(sql, params)
  File "/home/vid/makereport/DTPreport/env/lib/python3.6/site-packages/django/db/backends/sqlite3/base.py", line 413, in execute
    return Database.Cursor.execute(self, query, params)
sqlite3.OperationalError: attempt to write a readonly database

The above exception was the direct cause of the following exception:

Traceback (most recent call last):
  File "/home/vid/makereport/DTPreport/env/lib/python3.6/site-packages/django/core/handlers/exception.py", line 47, in inner
    response = get_response(request)
  File "/home/vid/makereport/DTPreport/env/lib/python3.6/site-packages/django/core/handlers/base.py", line 181, in _get_response
    response = wrapped_callback(request, *callback_args, **callback_kwargs)
  File "/home/vid/makereport/DTPreport/env/lib/python3.6/site-packages/django/views/decorators/cache.py", line 44, in _wrapped_view_func
    response = view_func(request, *args, **kwargs)
  File "/home/vid/makereport/DTPreport/env/lib/python3.6/site-packages/django/contrib/admin/sites.py", line 410, in login
    return LoginView.as_view(**defaults)(request)
  File "/home/vid/makereport/DTPreport/env/lib/python3.6/site-packages/django/views/generic/base.py", line 70, in view
    return self.dispatch(request, *args, **kwargs)
  File "/home/vid/makereport/DTPreport/env/lib/python3.6/site-packages/django/utils/decorators.py", line 43, in _wrapper
    return bound_method(*args, **kwargs)
  File "/home/vid/makereport/DTPreport/env/lib/python3.6/site-packages/django/views/decorators/debug.py", line 89, in sensitive_post_parameters_wrapper
    return view(request, *args, **kwargs)
  File "/home/vid/makereport/DTPreport/env/lib/python3.6/site-packages/django/utils/decorators.py", line 43, in _wrapper
    return bound_method(*args, **kwargs)
  File "/home/vid/makereport/DTPreport/env/lib/python3.6/site-packages/django/utils/decorators.py", line 130, in _wrapped_view
    response = view_func(request, *args, **kwargs)
  File "/home/vid/makereport/DTPreport/env/lib/python3.6/site-packages/django/utils/decorators.py", line 43, in _wrapper
    return bound_method(*args, **kwargs)
  File "/home/vid/makereport/DTPreport/env/lib/python3.6/site-packages/django/views/decorators/cache.py", line 44, in _wrapped_view_func
    response = view_func(request, *args, **kwargs)
  File "/home/vid/makereport/DTPreport/env/lib/python3.6/site-packages/django/contrib/auth/views.py", line 63, in dispatch
    return super().dispatch(request, *args, **kwargs)
  File "/home/vid/makereport/DTPreport/env/lib/python3.6/site-packages/django/views/generic/base.py", line 98, in dispatch
    return handler(request, *args, **kwargs)
  File "/home/vid/makereport/DTPreport/env/lib/python3.6/site-packages/django/views/generic/edit.py", line 142, in post
    return self.form_valid(form)
  File "/home/vid/makereport/DTPreport/env/lib/python3.6/site-packages/django/contrib/auth/views.py", line 92, in form_valid
    auth_login(self.request, form.get_user())
  File "/home/vid/makereport/DTPreport/env/lib/python3.6/site-packages/django/contrib/auth/__init__.py", line 108, in login
    request.session.cycle_key()
  File "/home/vid/makereport/DTPreport/env/lib/python3.6/site-packages/django/contrib/sessions/backends/base.py", line 344, in cycle_key
    self.create()
  File "/home/vid/makereport/DTPreport/env/lib/python3.6/site-packages/django/contrib/sessions/backends/db.py", line 55, in create
    self.save(must_create=True)
  File "/home/vid/makereport/DTPreport/env/lib/python3.6/site-packages/django/contrib/sessions/backends/db.py", line 87, in save
    obj.save(force_insert=must_create, force_update=not must_create, using=using)
  File "/home/vid/makereport/DTPreport/env/lib/python3.6/site-packages/django/db/models/base.py", line 754, in save
    force_update=force_update, update_fields=update_fields)
  File "/home/vid/makereport/DTPreport/env/lib/python3.6/site-packages/django/db/models/base.py", line 792, in save_base
    force_update, using, update_fields,
  File "/home/vid/makereport/DTPreport/env/lib/python3.6/site-packages/django/db/models/base.py", line 895, in _save_table
    results = self._do_insert(cls._base_manager, using, fields, returning_fields, raw)
  File "/home/vid/makereport/DTPreport/env/lib/python3.6/site-packages/django/db/models/base.py", line 935, in _do_insert
    using=using, raw=raw,
  File "/home/vid/makereport/DTPreport/env/lib/python3.6/site-packages/django/db/models/manager.py", line 85, in manager_method
    return getattr(self.get_queryset(), name)(*args, **kwargs)
  File "/home/vid/makereport/DTPreport/env/lib/python3.6/site-packages/django/db/models/query.py", line 1254, in _insert
    return query.get_compiler(using=using).execute_sql(returning_fields)
  File "/home/vid/makereport/DTPreport/env/lib/python3.6/site-packages/django/db/models/sql/compiler.py", line 1397, in execute_sql
    cursor.execute(sql, params)
  File "/home/vid/makereport/DTPreport/env/lib/python3.6/site-packages/django/db/backends/utils.py", line 98, in execute
    return super().execute(sql, params)
  File "/home/vid/makereport/DTPreport/env/lib/python3.6/site-packages/django/db/backends/utils.py", line 66, in execute
    return self._execute_with_wrappers(sql, params, many=False, executor=self._execute)
  File "/home/vid/makereport/DTPreport/env/lib/python3.6/site-packages/django/db/backends/utils.py", line 75, in _execute_with_wrappers
    return executor(sql, params, many, context)
  File "/home/vid/makereport/DTPreport/env/lib/python3.6/site-packages/django/db/backends/utils.py", line 84, in _execute
    return self.cursor.execute(sql, params)
  File "/home/vid/makereport/DTPreport/env/lib/python3.6/site-packages/django/db/utils.py", line 90, in __exit__
    raise dj_exc_value.with_traceback(traceback) from exc_value
  File "/home/vid/makereport/DTPreport/env/lib/python3.6/site-packages/django/db/backends/utils.py", line 84, in _execute
    return self.cursor.execute(sql, params)
  File "/home/vid/makereport/DTPreport/env/lib/python3.6/site-packages/django/db/backends/sqlite3/base.py", line 413, in execute
    return Database.Cursor.execute(self, query, params)
django.db.utils.OperationalError: attempt to write a readonly database
[2021-02-19 16:23:10 +0000] [59857] [INFO] Worker exiting (pid: 59857)
[2021-02-19 16:23:10 +0000] [59854] [INFO] Handling signal: term
[2021-02-19 16:23:10 +0000] [59854] [INFO] Shutting down: Master
[2021-02-19 16:23:10 +0000] [59879] [INFO] Starting gunicorn 20.0.4
[2021-02-19 16:23:10 +0000] [59879] [INFO] Listening at: http://127.0.0.1:46710 (59879)
[2021-02-19 16:23:10 +0000] [59879] [INFO] Using worker: sync
[2021-02-19 16:23:10 +0000] [59881] [INFO] Booting worker with pid: 59881
[2021-02-19 16:23:10 +0000] [59881] [ERROR] Exception in worker process
Traceback (most recent call last):
  File "/home/vid/makereport/DTPreport/env/lib/python3.6/site-packages/gunicorn/arbiter.py", line 583, in spawn_worker
    worker.init_process()
  File "/home/vid/makereport/DTPreport/env/lib/python3.6/site-packages/gunicorn/workers/base.py", line 119, in init_process
    self.load_wsgi()
  File "/home/vid/makereport/DTPreport/env/lib/python3.6/site-packages/gunicorn/workers/base.py", line 144, in load_wsgi
    self.wsgi = self.app.wsgi()
  File "/home/vid/makereport/DTPreport/env/lib/python3.6/site-packages/gunicorn/app/base.py", line 67, in wsgi
    self.callable = self.load()
  File "/home/vid/makereport/DTPreport/env/lib/python3.6/site-packages/gunicorn/app/wsgiapp.py", line 49, in load
    return self.load_wsgiapp()
  File "/home/vid/makereport/DTPreport/env/lib/python3.6/site-packages/gunicorn/app/wsgiapp.py", line 39, in load_wsgiapp
    return util.import_app(self.app_uri)
  File "/home/vid/makereport/DTPreport/env/lib/python3.6/site-packages/gunicorn/util.py", line 358, in import_app
    mod = importlib.import_module(module)
  File "/usr/lib/python3.6/importlib/__init__.py", line 126, in import_module
    return _bootstrap._gcd_import(name[level:], package, level)
  File "<frozen importlib._bootstrap>", line 994, in _gcd_import
  File "<frozen importlib._bootstrap>", line 971, in _find_and_load
  File "<frozen importlib._bootstrap>", line 955, in _find_and_load_unlocked
  File "<frozen importlib._bootstrap>", line 665, in _load_unlocked
  File "<frozen importlib._bootstrap_external>", line 678, in exec_module
  File "<frozen importlib._bootstrap>", line 219, in _call_with_frames_removed
  File "/home/vid/makereport/DTPreport/DTPreport/wsgi.py", line 16, in <module>
    application = get_wsgi_application()
  File "/home/vid/makereport/DTPreport/env/lib/python3.6/site-packages/django/core/wsgi.py", line 12, in get_wsgi_application
    django.setup(set_prefix=False)
  File "/home/vid/makereport/DTPreport/env/lib/python3.6/site-packages/django/__init__.py", line 19, in setup
    configure_logging(settings.LOGGING_CONFIG, settings.LOGGING)
  File "/home/vid/makereport/DTPreport/env/lib/python3.6/site-packages/django/conf/__init__.py", line 82, in __getattr__
    self._setup(name)
  File "/home/vid/makereport/DTPreport/env/lib/python3.6/site-packages/django/conf/__init__.py", line 69, in _setup
    self._wrapped = Settings(settings_module)
  File "/home/vid/makereport/DTPreport/env/lib/python3.6/site-packages/django/conf/__init__.py", line 170, in __init__
    mod = importlib.import_module(self.SETTINGS_MODULE)
  File "/usr/lib/python3.6/importlib/__init__.py", line 126, in import_module
    return _bootstrap._gcd_import(name[level:], package, level)
  File "<frozen importlib._bootstrap>", line 994, in _gcd_import
  File "<frozen importlib._bootstrap>", line 971, in _find_and_load
  File "<frozen importlib._bootstrap>", line 955, in _find_and_load_unlocked
  File "<frozen importlib._bootstrap>", line 665, in _load_unlocked
  File "<frozen importlib._bootstrap_external>", line 674, in exec_module
  File "<frozen importlib._bootstrap_external>", line 781, in get_code
  File "<frozen importlib._bootstrap_external>", line 741, in source_to_code
  File "<frozen importlib._bootstrap>", line 219, in _call_with_frames_removed
  File "/home/vid/makereport/DTPreport/DTPreport/settings.py", line 108
    DATABASES = {
    ^
IndentationError: unexpected indent
[2021-02-19 16:23:10 +0000] [59881] [INFO] Worker exiting (pid: 59881)
[2021-02-19 16:23:10 +0000] [59879] [INFO] Shutting down: Master
[2021-02-19 16:23:10 +0000] [59879] [INFO] Reason: Worker failed to boot.
[2021-02-19 16:23:12 +0000] [59883] [INFO] Starting gunicorn 20.0.4
[2021-02-19 16:23:12 +0000] [59883] [INFO] Listening at: http://127.0.0.1:46710 (59883)
[2021-02-19 16:23:12 +0000] [59883] [INFO] Using worker: sync
[2021-02-19 16:23:12 +0000] [59885] [INFO] Booting worker with pid: 59885
[2021-02-19 16:23:12 +0000] [59885] [ERROR] Exception in worker process
Traceback (most recent call last):
  File "/home/vid/makereport/DTPreport/env/lib/python3.6/site-packages/gunicorn/arbiter.py", line 583, in spawn_worker
    worker.init_process()
  File "/home/vid/makereport/DTPreport/env/lib/python3.6/site-packages/gunicorn/workers/base.py", line 119, in init_process
    self.load_wsgi()
  File "/home/vid/makereport/DTPreport/env/lib/python3.6/site-packages/gunicorn/workers/base.py", line 144, in load_wsgi
    self.wsgi = self.app.wsgi()
  File "/home/vid/makereport/DTPreport/env/lib/python3.6/site-packages/gunicorn/app/base.py", line 67, in wsgi
    self.callable = self.load()
  File "/home/vid/makereport/DTPreport/env/lib/python3.6/site-packages/gunicorn/app/wsgiapp.py", line 49, in load
    return self.load_wsgiapp()
  File "/home/vid/makereport/DTPreport/env/lib/python3.6/site-packages/gunicorn/app/wsgiapp.py", line 39, in load_wsgiapp
    return util.import_app(self.app_uri)
  File "/home/vid/makereport/DTPreport/env/lib/python3.6/site-packages/gunicorn/util.py", line 358, in import_app
    mod = importlib.import_module(module)
  File "/usr/lib/python3.6/importlib/__init__.py", line 126, in import_module
    return _bootstrap._gcd_import(name[level:], package, level)
  File "<frozen importlib._bootstrap>", line 994, in _gcd_import
  File "<frozen importlib._bootstrap>", line 971, in _find_and_load
  File "<frozen importlib._bootstrap>", line 955, in _find_and_load_unlocked
  File "<frozen importlib._bootstrap>", line 665, in _load_unlocked
  File "<frozen importlib._bootstrap_external>", line 678, in exec_module
  File "<frozen importlib._bootstrap>", line 219, in _call_with_frames_removed
  File "/home/vid/makereport/DTPreport/DTPreport/wsgi.py", line 16, in <module>
    application = get_wsgi_application()
  File "/home/vid/makereport/DTPreport/env/lib/python3.6/site-packages/django/core/wsgi.py", line 12, in get_wsgi_application
    django.setup(set_prefix=False)
  File "/home/vid/makereport/DTPreport/env/lib/python3.6/site-packages/django/__init__.py", line 19, in setup
    configure_logging(settings.LOGGING_CONFIG, settings.LOGGING)
  File "/home/vid/makereport/DTPreport/env/lib/python3.6/site-packages/django/conf/__init__.py", line 82, in __getattr__
    self._setup(name)
  File "/home/vid/makereport/DTPreport/env/lib/python3.6/site-packages/django/conf/__init__.py", line 69, in _setup
    self._wrapped = Settings(settings_module)
  File "/home/vid/makereport/DTPreport/env/lib/python3.6/site-packages/django/conf/__init__.py", line 170, in __init__
    mod = importlib.import_module(self.SETTINGS_MODULE)
  File "/usr/lib/python3.6/importlib/__init__.py", line 126, in import_module
    return _bootstrap._gcd_import(name[level:], package, level)
  File "<frozen importlib._bootstrap>", line 994, in _gcd_import
  File "<frozen importlib._bootstrap>", line 971, in _find_and_load
  File "<frozen importlib._bootstrap>", line 955, in _find_and_load_unlocked
  File "<frozen importlib._bootstrap>", line 665, in _load_unlocked
  File "<frozen importlib._bootstrap_external>", line 674, in exec_module
  File "<frozen importlib._bootstrap_external>", line 781, in get_code
  File "<frozen importlib._bootstrap_external>", line 741, in source_to_code
  File "<frozen importlib._bootstrap>", line 219, in _call_with_frames_removed
  File "/home/vid/makereport/DTPreport/DTPreport/settings.py", line 108
    DATABASES = {
    ^
IndentationError: unexpected indent
[2021-02-19 16:23:12 +0000] [59885] [INFO] Worker exiting (pid: 59885)
[2021-02-19 16:23:12 +0000] [59883] [INFO] Shutting down: Master
[2021-02-19 16:23:12 +0000] [59883] [INFO] Reason: Worker failed to boot.
[2021-02-19 16:23:14 +0000] [59888] [INFO] Starting gunicorn 20.0.4
[2021-02-19 16:23:14 +0000] [59888] [INFO] Listening at: http://127.0.0.1:46710 (59888)
[2021-02-19 16:23:14 +0000] [59888] [INFO] Using worker: sync
[2021-02-19 16:23:14 +0000] [59890] [INFO] Booting worker with pid: 59890
[2021-02-19 16:23:14 +0000] [59890] [ERROR] Exception in worker process
Traceback (most recent call last):
  File "/home/vid/makereport/DTPreport/env/lib/python3.6/site-packages/gunicorn/arbiter.py", line 583, in spawn_worker
    worker.init_process()
  File "/home/vid/makereport/DTPreport/env/lib/python3.6/site-packages/gunicorn/workers/base.py", line 119, in init_process
    self.load_wsgi()
  File "/home/vid/makereport/DTPreport/env/lib/python3.6/site-packages/gunicorn/workers/base.py", line 144, in load_wsgi
    self.wsgi = self.app.wsgi()
  File "/home/vid/makereport/DTPreport/env/lib/python3.6/site-packages/gunicorn/app/base.py", line 67, in wsgi
    self.callable = self.load()
  File "/home/vid/makereport/DTPreport/env/lib/python3.6/site-packages/gunicorn/app/wsgiapp.py", line 49, in load
    return self.load_wsgiapp()
  File "/home/vid/makereport/DTPreport/env/lib/python3.6/site-packages/gunicorn/app/wsgiapp.py", line 39, in load_wsgiapp
    return util.import_app(self.app_uri)
  File "/home/vid/makereport/DTPreport/env/lib/python3.6/site-packages/gunicorn/util.py", line 358, in import_app
    mod = importlib.import_module(module)
  File "/usr/lib/python3.6/importlib/__init__.py", line 126, in import_module
    return _bootstrap._gcd_import(name[level:], package, level)
  File "<frozen importlib._bootstrap>", line 994, in _gcd_import
  File "<frozen importlib._bootstrap>", line 971, in _find_and_load
  File "<frozen importlib._bootstrap>", line 955, in _find_and_load_unlocked
  File "<frozen importlib._bootstrap>", line 665, in _load_unlocked
  File "<frozen importlib._bootstrap_external>", line 678, in exec_module
  File "<frozen importlib._bootstrap>", line 219, in _call_with_frames_removed
  File "/home/vid/makereport/DTPreport/DTPreport/wsgi.py", line 16, in <module>
    application = get_wsgi_application()
  File "/home/vid/makereport/DTPreport/env/lib/python3.6/site-packages/django/core/wsgi.py", line 12, in get_wsgi_application
    django.setup(set_prefix=False)
  File "/home/vid/makereport/DTPreport/env/lib/python3.6/site-packages/django/__init__.py", line 19, in setup
    configure_logging(settings.LOGGING_CONFIG, settings.LOGGING)
  File "/home/vid/makereport/DTPreport/env/lib/python3.6/site-packages/django/conf/__init__.py", line 82, in __getattr__
    self._setup(name)
  File "/home/vid/makereport/DTPreport/env/lib/python3.6/site-packages/django/conf/__init__.py", line 69, in _setup
    self._wrapped = Settings(settings_module)
  File "/home/vid/makereport/DTPreport/env/lib/python3.6/site-packages/django/conf/__init__.py", line 170, in __init__
    mod = importlib.import_module(self.SETTINGS_MODULE)
  File "/usr/lib/python3.6/importlib/__init__.py", line 126, in import_module
    return _bootstrap._gcd_import(name[level:], package, level)
  File "<frozen importlib._bootstrap>", line 994, in _gcd_import
  File "<frozen importlib._bootstrap>", line 971, in _find_and_load
  File "<frozen importlib._bootstrap>", line 955, in _find_and_load_unlocked
  File "<frozen importlib._bootstrap>", line 665, in _load_unlocked
  File "<frozen importlib._bootstrap_external>", line 674, in exec_module
  File "<frozen importlib._bootstrap_external>", line 781, in get_code
  File "<frozen importlib._bootstrap_external>", line 741, in source_to_code
  File "<frozen importlib._bootstrap>", line 219, in _call_with_frames_removed
  File "/home/vid/makereport/DTPreport/DTPreport/settings.py", line 108
    DATABASES = {
    ^
IndentationError: unexpected indent
[2021-02-19 16:23:14 +0000] [59890] [INFO] Worker exiting (pid: 59890)
[2021-02-19 16:23:14 +0000] [59888] [INFO] Shutting down: Master
[2021-02-19 16:23:14 +0000] [59888] [INFO] Reason: Worker failed to boot.
[2021-02-19 16:23:18 +0000] [59893] [INFO] Starting gunicorn 20.0.4
[2021-02-19 16:23:18 +0000] [59893] [INFO] Listening at: http://127.0.0.1:46710 (59893)
[2021-02-19 16:23:18 +0000] [59893] [INFO] Using worker: sync
[2021-02-19 16:23:18 +0000] [59895] [INFO] Booting worker with pid: 59895
[2021-02-19 16:23:18 +0000] [59895] [ERROR] Exception in worker process
Traceback (most recent call last):
  File "/home/vid/makereport/DTPreport/env/lib/python3.6/site-packages/gunicorn/arbiter.py", line 583, in spawn_worker
    worker.init_process()
  File "/home/vid/makereport/DTPreport/env/lib/python3.6/site-packages/gunicorn/workers/base.py", line 119, in init_process
    self.load_wsgi()
  File "/home/vid/makereport/DTPreport/env/lib/python3.6/site-packages/gunicorn/workers/base.py", line 144, in load_wsgi
    self.wsgi = self.app.wsgi()
  File "/home/vid/makereport/DTPreport/env/lib/python3.6/site-packages/gunicorn/app/base.py", line 67, in wsgi
    self.callable = self.load()
  File "/home/vid/makereport/DTPreport/env/lib/python3.6/site-packages/gunicorn/app/wsgiapp.py", line 49, in load
    return self.load_wsgiapp()
  File "/home/vid/makereport/DTPreport/env/lib/python3.6/site-packages/gunicorn/app/wsgiapp.py", line 39, in load_wsgiapp
    return util.import_app(self.app_uri)
  File "/home/vid/makereport/DTPreport/env/lib/python3.6/site-packages/gunicorn/util.py", line 358, in import_app
    mod = importlib.import_module(module)
  File "/usr/lib/python3.6/importlib/__init__.py", line 126, in import_module
    return _bootstrap._gcd_import(name[level:], package, level)
  File "<frozen importlib._bootstrap>", line 994, in _gcd_import
  File "<frozen importlib._bootstrap>", line 971, in _find_and_load
  File "<frozen importlib._bootstrap>", line 955, in _find_and_load_unlocked
  File "<frozen importlib._bootstrap>", line 665, in _load_unlocked
  File "<frozen importlib._bootstrap_external>", line 678, in exec_module
  File "<frozen importlib._bootstrap>", line 219, in _call_with_frames_removed
  File "/home/vid/makereport/DTPreport/DTPreport/wsgi.py", line 16, in <module>
    application = get_wsgi_application()
  File "/home/vid/makereport/DTPreport/env/lib/python3.6/site-packages/django/core/wsgi.py", line 12, in get_wsgi_application
    django.setup(set_prefix=False)
  File "/home/vid/makereport/DTPreport/env/lib/python3.6/site-packages/django/__init__.py", line 19, in setup
    configure_logging(settings.LOGGING_CONFIG, settings.LOGGING)
  File "/home/vid/makereport/DTPreport/env/lib/python3.6/site-packages/django/conf/__init__.py", line 82, in __getattr__
    self._setup(name)
  File "/home/vid/makereport/DTPreport/env/lib/python3.6/site-packages/django/conf/__init__.py", line 69, in _setup
    self._wrapped = Settings(settings_module)
  File "/home/vid/makereport/DTPreport/env/lib/python3.6/site-packages/django/conf/__init__.py", line 170, in __init__
    mod = importlib.import_module(self.SETTINGS_MODULE)
  File "/usr/lib/python3.6/importlib/__init__.py", line 126, in import_module
    return _bootstrap._gcd_import(name[level:], package, level)
  File "<frozen importlib._bootstrap>", line 994, in _gcd_import
  File "<frozen importlib._bootstrap>", line 971, in _find_and_load
  File "<frozen importlib._bootstrap>", line 955, in _find_and_load_unlocked
  File "<frozen importlib._bootstrap>", line 665, in _load_unlocked
  File "<frozen importlib._bootstrap_external>", line 674, in exec_module
  File "<frozen importlib._bootstrap_external>", line 781, in get_code
  File "<frozen importlib._bootstrap_external>", line 741, in source_to_code
  File "<frozen importlib._bootstrap>", line 219, in _call_with_frames_removed
  File "/home/vid/makereport/DTPreport/DTPreport/settings.py", line 108
    DATABASES = {
    ^
IndentationError: unexpected indent
[2021-02-19 16:23:18 +0000] [59895] [INFO] Worker exiting (pid: 59895)
[2021-02-19 16:23:18 +0000] [59893] [INFO] Shutting down: Master
[2021-02-19 16:23:18 +0000] [59893] [INFO] Reason: Worker failed to boot.
[2021-02-19 16:23:36 +0000] [59902] [INFO] Starting gunicorn 20.0.4
[2021-02-19 16:23:36 +0000] [59902] [INFO] Listening at: http://127.0.0.1:46710 (59902)
[2021-02-19 16:23:36 +0000] [59902] [INFO] Using worker: sync
[2021-02-19 16:23:36 +0000] [59904] [INFO] Booting worker with pid: 59904
[2021-02-19 16:23:37 +0000] [59904] [ERROR] Exception in worker process
Traceback (most recent call last):
  File "/home/vid/makereport/DTPreport/env/lib/python3.6/site-packages/gunicorn/arbiter.py", line 583, in spawn_worker
    worker.init_process()
  File "/home/vid/makereport/DTPreport/env/lib/python3.6/site-packages/gunicorn/workers/base.py", line 119, in init_process
    self.load_wsgi()
  File "/home/vid/makereport/DTPreport/env/lib/python3.6/site-packages/gunicorn/workers/base.py", line 144, in load_wsgi
    self.wsgi = self.app.wsgi()
  File "/home/vid/makereport/DTPreport/env/lib/python3.6/site-packages/gunicorn/app/base.py", line 67, in wsgi
    self.callable = self.load()
  File "/home/vid/makereport/DTPreport/env/lib/python3.6/site-packages/gunicorn/app/wsgiapp.py", line 49, in load
    return self.load_wsgiapp()
  File "/home/vid/makereport/DTPreport/env/lib/python3.6/site-packages/gunicorn/app/wsgiapp.py", line 39, in load_wsgiapp
    return util.import_app(self.app_uri)
  File "/home/vid/makereport/DTPreport/env/lib/python3.6/site-packages/gunicorn/util.py", line 358, in import_app
    mod = importlib.import_module(module)
  File "/usr/lib/python3.6/importlib/__init__.py", line 126, in import_module
    return _bootstrap._gcd_import(name[level:], package, level)
  File "<frozen importlib._bootstrap>", line 994, in _gcd_import
  File "<frozen importlib._bootstrap>", line 971, in _find_and_load
  File "<frozen importlib._bootstrap>", line 955, in _find_and_load_unlocked
  File "<frozen importlib._bootstrap>", line 665, in _load_unlocked
  File "<frozen importlib._bootstrap_external>", line 678, in exec_module
  File "<frozen importlib._bootstrap>", line 219, in _call_with_frames_removed
  File "/home/vid/makereport/DTPreport/DTPreport/wsgi.py", line 16, in <module>
    application = get_wsgi_application()
  File "/home/vid/makereport/DTPreport/env/lib/python3.6/site-packages/django/core/wsgi.py", line 12, in get_wsgi_application
    django.setup(set_prefix=False)
  File "/home/vid/makereport/DTPreport/env/lib/python3.6/site-packages/django/__init__.py", line 19, in setup
    configure_logging(settings.LOGGING_CONFIG, settings.LOGGING)
  File "/home/vid/makereport/DTPreport/env/lib/python3.6/site-packages/django/conf/__init__.py", line 82, in __getattr__
    self._setup(name)
  File "/home/vid/makereport/DTPreport/env/lib/python3.6/site-packages/django/conf/__init__.py", line 69, in _setup
    self._wrapped = Settings(settings_module)
  File "/home/vid/makereport/DTPreport/env/lib/python3.6/site-packages/django/conf/__init__.py", line 170, in __init__
    mod = importlib.import_module(self.SETTINGS_MODULE)
  File "/usr/lib/python3.6/importlib/__init__.py", line 126, in import_module
    return _bootstrap._gcd_import(name[level:], package, level)
  File "<frozen importlib._bootstrap>", line 994, in _gcd_import
  File "<frozen importlib._bootstrap>", line 971, in _find_and_load
  File "<frozen importlib._bootstrap>", line 955, in _find_and_load_unlocked
  File "<frozen importlib._bootstrap>", line 665, in _load_unlocked
  File "<frozen importlib._bootstrap_external>", line 674, in exec_module
  File "<frozen importlib._bootstrap_external>", line 781, in get_code
  File "<frozen importlib._bootstrap_external>", line 741, in source_to_code
  File "<frozen importlib._bootstrap>", line 219, in _call_with_frames_removed
  File "/home/vid/makereport/DTPreport/DTPreport/settings.py", line 108
    DATABASES = {
    ^
IndentationError: unexpected indent
[2021-02-19 16:23:37 +0000] [59904] [INFO] Worker exiting (pid: 59904)
[2021-02-19 16:23:37 +0000] [59902] [INFO] Shutting down: Master
[2021-02-19 16:23:37 +0000] [59902] [INFO] Reason: Worker failed to boot.
[2021-02-19 16:23:38 +0000] [59907] [INFO] Starting gunicorn 20.0.4
[2021-02-19 16:23:38 +0000] [59907] [INFO] Listening at: http://127.0.0.1:46710 (59907)
[2021-02-19 16:23:38 +0000] [59907] [INFO] Using worker: sync
[2021-02-19 16:23:38 +0000] [59909] [INFO] Booting worker with pid: 59909
[2021-02-19 16:23:38 +0000] [59909] [ERROR] Exception in worker process
Traceback (most recent call last):
  File "/home/vid/makereport/DTPreport/env/lib/python3.6/site-packages/gunicorn/arbiter.py", line 583, in spawn_worker
    worker.init_process()
  File "/home/vid/makereport/DTPreport/env/lib/python3.6/site-packages/gunicorn/workers/base.py", line 119, in init_process
    self.load_wsgi()
  File "/home/vid/makereport/DTPreport/env/lib/python3.6/site-packages/gunicorn/workers/base.py", line 144, in load_wsgi
    self.wsgi = self.app.wsgi()
  File "/home/vid/makereport/DTPreport/env/lib/python3.6/site-packages/gunicorn/app/base.py", line 67, in wsgi
    self.callable = self.load()
  File "/home/vid/makereport/DTPreport/env/lib/python3.6/site-packages/gunicorn/app/wsgiapp.py", line 49, in load
    return self.load_wsgiapp()
  File "/home/vid/makereport/DTPreport/env/lib/python3.6/site-packages/gunicorn/app/wsgiapp.py", line 39, in load_wsgiapp
    return util.import_app(self.app_uri)
  File "/home/vid/makereport/DTPreport/env/lib/python3.6/site-packages/gunicorn/util.py", line 358, in import_app
    mod = importlib.import_module(module)
  File "/usr/lib/python3.6/importlib/__init__.py", line 126, in import_module
    return _bootstrap._gcd_import(name[level:], package, level)
  File "<frozen importlib._bootstrap>", line 994, in _gcd_import
  File "<frozen importlib._bootstrap>", line 971, in _find_and_load
  File "<frozen importlib._bootstrap>", line 955, in _find_and_load_unlocked
  File "<frozen importlib._bootstrap>", line 665, in _load_unlocked
  File "<frozen importlib._bootstrap_external>", line 678, in exec_module
  File "<frozen importlib._bootstrap>", line 219, in _call_with_frames_removed
  File "/home/vid/makereport/DTPreport/DTPreport/wsgi.py", line 16, in <module>
    application = get_wsgi_application()
  File "/home/vid/makereport/DTPreport/env/lib/python3.6/site-packages/django/core/wsgi.py", line 12, in get_wsgi_application
    django.setup(set_prefix=False)
  File "/home/vid/makereport/DTPreport/env/lib/python3.6/site-packages/django/__init__.py", line 19, in setup
    configure_logging(settings.LOGGING_CONFIG, settings.LOGGING)
  File "/home/vid/makereport/DTPreport/env/lib/python3.6/site-packages/django/conf/__init__.py", line 82, in __getattr__
    self._setup(name)
  File "/home/vid/makereport/DTPreport/env/lib/python3.6/site-packages/django/conf/__init__.py", line 69, in _setup
    self._wrapped = Settings(settings_module)
  File "/home/vid/makereport/DTPreport/env/lib/python3.6/site-packages/django/conf/__init__.py", line 170, in __init__
    mod = importlib.import_module(self.SETTINGS_MODULE)
  File "/usr/lib/python3.6/importlib/__init__.py", line 126, in import_module
    return _bootstrap._gcd_import(name[level:], package, level)
  File "<frozen importlib._bootstrap>", line 994, in _gcd_import
  File "<frozen importlib._bootstrap>", line 971, in _find_and_load
  File "<frozen importlib._bootstrap>", line 955, in _find_and_load_unlocked
  File "<frozen importlib._bootstrap>", line 665, in _load_unlocked
  File "<frozen importlib._bootstrap_external>", line 674, in exec_module
  File "<frozen importlib._bootstrap_external>", line 781, in get_code
  File "<frozen importlib._bootstrap_external>", line 741, in source_to_code
  File "<frozen importlib._bootstrap>", line 219, in _call_with_frames_removed
  File "/home/vid/makereport/DTPreport/DTPreport/settings.py", line 108
    DATABASES = {
    ^
IndentationError: unexpected indent
[2021-02-19 16:23:38 +0000] [59909] [INFO] Worker exiting (pid: 59909)
[2021-02-19 16:23:38 +0000] [59907] [INFO] Shutting down: Master
[2021-02-19 16:23:38 +0000] [59907] [INFO] Reason: Worker failed to boot.
[2021-02-19 16:23:41 +0000] [59911] [INFO] Starting gunicorn 20.0.4
[2021-02-19 16:23:41 +0000] [59911] [INFO] Listening at: http://127.0.0.1:46710 (59911)
[2021-02-19 16:23:41 +0000] [59911] [INFO] Using worker: sync
[2021-02-19 16:23:41 +0000] [59913] [INFO] Booting worker with pid: 59913
[2021-02-19 16:23:41 +0000] [59913] [ERROR] Exception in worker process
Traceback (most recent call last):
  File "/home/vid/makereport/DTPreport/env/lib/python3.6/site-packages/gunicorn/arbiter.py", line 583, in spawn_worker
    worker.init_process()
  File "/home/vid/makereport/DTPreport/env/lib/python3.6/site-packages/gunicorn/workers/base.py", line 119, in init_process
    self.load_wsgi()
  File "/home/vid/makereport/DTPreport/env/lib/python3.6/site-packages/gunicorn/workers/base.py", line 144, in load_wsgi
    self.wsgi = self.app.wsgi()
  File "/home/vid/makereport/DTPreport/env/lib/python3.6/site-packages/gunicorn/app/base.py", line 67, in wsgi
    self.callable = self.load()
  File "/home/vid/makereport/DTPreport/env/lib/python3.6/site-packages/gunicorn/app/wsgiapp.py", line 49, in load
    return self.load_wsgiapp()
  File "/home/vid/makereport/DTPreport/env/lib/python3.6/site-packages/gunicorn/app/wsgiapp.py", line 39, in load_wsgiapp
    return util.import_app(self.app_uri)
  File "/home/vid/makereport/DTPreport/env/lib/python3.6/site-packages/gunicorn/util.py", line 358, in import_app
    mod = importlib.import_module(module)
  File "/usr/lib/python3.6/importlib/__init__.py", line 126, in import_module
    return _bootstrap._gcd_import(name[level:], package, level)
  File "<frozen importlib._bootstrap>", line 994, in _gcd_import
  File "<frozen importlib._bootstrap>", line 971, in _find_and_load
  File "<frozen importlib._bootstrap>", line 955, in _find_and_load_unlocked
  File "<frozen importlib._bootstrap>", line 665, in _load_unlocked
  File "<frozen importlib._bootstrap_external>", line 678, in exec_module
  File "<frozen importlib._bootstrap>", line 219, in _call_with_frames_removed
  File "/home/vid/makereport/DTPreport/DTPreport/wsgi.py", line 16, in <module>
    application = get_wsgi_application()
  File "/home/vid/makereport/DTPreport/env/lib/python3.6/site-packages/django/core/wsgi.py", line 12, in get_wsgi_application
    django.setup(set_prefix=False)
  File "/home/vid/makereport/DTPreport/env/lib/python3.6/site-packages/django/__init__.py", line 19, in setup
    configure_logging(settings.LOGGING_CONFIG, settings.LOGGING)
  File "/home/vid/makereport/DTPreport/env/lib/python3.6/site-packages/django/conf/__init__.py", line 82, in __getattr__
    self._setup(name)
  File "/home/vid/makereport/DTPreport/env/lib/python3.6/site-packages/django/conf/__init__.py", line 69, in _setup
    self._wrapped = Settings(settings_module)
  File "/home/vid/makereport/DTPreport/env/lib/python3.6/site-packages/django/conf/__init__.py", line 170, in __init__
    mod = importlib.import_module(self.SETTINGS_MODULE)
  File "/usr/lib/python3.6/importlib/__init__.py", line 126, in import_module
    return _bootstrap._gcd_import(name[level:], package, level)
  File "<frozen importlib._bootstrap>", line 994, in _gcd_import
  File "<frozen importlib._bootstrap>", line 971, in _find_and_load
  File "<frozen importlib._bootstrap>", line 955, in _find_and_load_unlocked
  File "<frozen importlib._bootstrap>", line 665, in _load_unlocked
  File "<frozen importlib._bootstrap_external>", line 674, in exec_module
  File "<frozen importlib._bootstrap_external>", line 781, in get_code
  File "<frozen importlib._bootstrap_external>", line 741, in source_to_code
  File "<frozen importlib._bootstrap>", line 219, in _call_with_frames_removed
  File "/home/vid/makereport/DTPreport/DTPreport/settings.py", line 108
    DATABASES = {
    ^
IndentationError: unexpected indent
[2021-02-19 16:23:41 +0000] [59913] [INFO] Worker exiting (pid: 59913)
[2021-02-19 16:23:41 +0000] [59911] [INFO] Shutting down: Master
[2021-02-19 16:23:41 +0000] [59911] [INFO] Reason: Worker failed to boot.
[2021-02-19 16:23:44 +0000] [59915] [INFO] Starting gunicorn 20.0.4
[2021-02-19 16:23:44 +0000] [59915] [INFO] Listening at: http://127.0.0.1:46710 (59915)
[2021-02-19 16:23:44 +0000] [59915] [INFO] Using worker: sync
[2021-02-19 16:23:44 +0000] [59917] [INFO] Booting worker with pid: 59917
[2021-02-19 16:23:44 +0000] [59917] [ERROR] Exception in worker process
Traceback (most recent call last):
  File "/home/vid/makereport/DTPreport/env/lib/python3.6/site-packages/gunicorn/arbiter.py", line 583, in spawn_worker
    worker.init_process()
  File "/home/vid/makereport/DTPreport/env/lib/python3.6/site-packages/gunicorn/workers/base.py", line 119, in init_process
    self.load_wsgi()
  File "/home/vid/makereport/DTPreport/env/lib/python3.6/site-packages/gunicorn/workers/base.py", line 144, in load_wsgi
    self.wsgi = self.app.wsgi()
  File "/home/vid/makereport/DTPreport/env/lib/python3.6/site-packages/gunicorn/app/base.py", line 67, in wsgi
    self.callable = self.load()
  File "/home/vid/makereport/DTPreport/env/lib/python3.6/site-packages/gunicorn/app/wsgiapp.py", line 49, in load
    return self.load_wsgiapp()
  File "/home/vid/makereport/DTPreport/env/lib/python3.6/site-packages/gunicorn/app/wsgiapp.py", line 39, in load_wsgiapp
    return util.import_app(self.app_uri)
  File "/home/vid/makereport/DTPreport/env/lib/python3.6/site-packages/gunicorn/util.py", line 358, in import_app
    mod = importlib.import_module(module)
  File "/usr/lib/python3.6/importlib/__init__.py", line 126, in import_module
    return _bootstrap._gcd_import(name[level:], package, level)
  File "<frozen importlib._bootstrap>", line 994, in _gcd_import
  File "<frozen importlib._bootstrap>", line 971, in _find_and_load
  File "<frozen importlib._bootstrap>", line 955, in _find_and_load_unlocked
  File "<frozen importlib._bootstrap>", line 665, in _load_unlocked
  File "<frozen importlib._bootstrap_external>", line 678, in exec_module
  File "<frozen importlib._bootstrap>", line 219, in _call_with_frames_removed
  File "/home/vid/makereport/DTPreport/DTPreport/wsgi.py", line 16, in <module>
    application = get_wsgi_application()
  File "/home/vid/makereport/DTPreport/env/lib/python3.6/site-packages/django/core/wsgi.py", line 12, in get_wsgi_application
    django.setup(set_prefix=False)
  File "/home/vid/makereport/DTPreport/env/lib/python3.6/site-packages/django/__init__.py", line 19, in setup
    configure_logging(settings.LOGGING_CONFIG, settings.LOGGING)
  File "/home/vid/makereport/DTPreport/env/lib/python3.6/site-packages/django/conf/__init__.py", line 82, in __getattr__
    self._setup(name)
  File "/home/vid/makereport/DTPreport/env/lib/python3.6/site-packages/django/conf/__init__.py", line 69, in _setup
    self._wrapped = Settings(settings_module)
  File "/home/vid/makereport/DTPreport/env/lib/python3.6/site-packages/django/conf/__init__.py", line 170, in __init__
    mod = importlib.import_module(self.SETTINGS_MODULE)
  File "/usr/lib/python3.6/importlib/__init__.py", line 126, in import_module
    return _bootstrap._gcd_import(name[level:], package, level)
  File "<frozen importlib._bootstrap>", line 994, in _gcd_import
  File "<frozen importlib._bootstrap>", line 971, in _find_and_load
  File "<frozen importlib._bootstrap>", line 955, in _find_and_load_unlocked
  File "<frozen importlib._bootstrap>", line 665, in _load_unlocked
  File "<frozen importlib._bootstrap_external>", line 674, in exec_module
  File "<frozen importlib._bootstrap_external>", line 781, in get_code
  File "<frozen importlib._bootstrap_external>", line 741, in source_to_code
  File "<frozen importlib._bootstrap>", line 219, in _call_with_frames_removed
  File "/home/vid/makereport/DTPreport/DTPreport/settings.py", line 108
    DATABASES = {
    ^
IndentationError: unexpected indent
[2021-02-19 16:23:44 +0000] [59917] [INFO] Worker exiting (pid: 59917)
[2021-02-19 16:23:45 +0000] [59915] [INFO] Shutting down: Master
[2021-02-19 16:23:45 +0000] [59915] [INFO] Reason: Worker failed to boot.
[2021-02-19 16:28:16 +0000] [60012] [INFO] Starting gunicorn 20.0.4
[2021-02-19 16:28:16 +0000] [60012] [INFO] Listening at: http://127.0.0.1:46710 (60012)
[2021-02-19 16:28:16 +0000] [60012] [INFO] Using worker: sync
[2021-02-19 16:28:16 +0000] [60014] [INFO] Booting worker with pid: 60014
[2021-02-19 16:28:16 +0000] [60014] [ERROR] Exception in worker process
Traceback (most recent call last):
  File "/home/vid/makereport/DTPreport/env/lib/python3.6/site-packages/gunicorn/arbiter.py", line 583, in spawn_worker
    worker.init_process()
  File "/home/vid/makereport/DTPreport/env/lib/python3.6/site-packages/gunicorn/workers/base.py", line 119, in init_process
    self.load_wsgi()
  File "/home/vid/makereport/DTPreport/env/lib/python3.6/site-packages/gunicorn/workers/base.py", line 144, in load_wsgi
    self.wsgi = self.app.wsgi()
  File "/home/vid/makereport/DTPreport/env/lib/python3.6/site-packages/gunicorn/app/base.py", line 67, in wsgi
    self.callable = self.load()
  File "/home/vid/makereport/DTPreport/env/lib/python3.6/site-packages/gunicorn/app/wsgiapp.py", line 49, in load
    return self.load_wsgiapp()
  File "/home/vid/makereport/DTPreport/env/lib/python3.6/site-packages/gunicorn/app/wsgiapp.py", line 39, in load_wsgiapp
    return util.import_app(self.app_uri)
  File "/home/vid/makereport/DTPreport/env/lib/python3.6/site-packages/gunicorn/util.py", line 358, in import_app
    mod = importlib.import_module(module)
  File "/usr/lib/python3.6/importlib/__init__.py", line 126, in import_module
    return _bootstrap._gcd_import(name[level:], package, level)
  File "<frozen importlib._bootstrap>", line 994, in _gcd_import
  File "<frozen importlib._bootstrap>", line 971, in _find_and_load
  File "<frozen importlib._bootstrap>", line 955, in _find_and_load_unlocked
  File "<frozen importlib._bootstrap>", line 665, in _load_unlocked
  File "<frozen importlib._bootstrap_external>", line 678, in exec_module
  File "<frozen importlib._bootstrap>", line 219, in _call_with_frames_removed
  File "/home/vid/makereport/DTPreport/DTPreport/wsgi.py", line 16, in <module>
    application = get_wsgi_application()
  File "/home/vid/makereport/DTPreport/env/lib/python3.6/site-packages/django/core/wsgi.py", line 12, in get_wsgi_application
    django.setup(set_prefix=False)
  File "/home/vid/makereport/DTPreport/env/lib/python3.6/site-packages/django/__init__.py", line 19, in setup
    configure_logging(settings.LOGGING_CONFIG, settings.LOGGING)
  File "/home/vid/makereport/DTPreport/env/lib/python3.6/site-packages/django/conf/__init__.py", line 82, in __getattr__
    self._setup(name)
  File "/home/vid/makereport/DTPreport/env/lib/python3.6/site-packages/django/conf/__init__.py", line 69, in _setup
    self._wrapped = Settings(settings_module)
  File "/home/vid/makereport/DTPreport/env/lib/python3.6/site-packages/django/conf/__init__.py", line 170, in __init__
    mod = importlib.import_module(self.SETTINGS_MODULE)
  File "/usr/lib/python3.6/importlib/__init__.py", line 126, in import_module
    return _bootstrap._gcd_import(name[level:], package, level)
  File "<frozen importlib._bootstrap>", line 994, in _gcd_import
  File "<frozen importlib._bootstrap>", line 971, in _find_and_load
  File "<frozen importlib._bootstrap>", line 955, in _find_and_load_unlocked
  File "<frozen importlib._bootstrap>", line 665, in _load_unlocked
  File "<frozen importlib._bootstrap_external>", line 674, in exec_module
  File "<frozen importlib._bootstrap_external>", line 781, in get_code
  File "<frozen importlib._bootstrap_external>", line 741, in source_to_code
  File "<frozen importlib._bootstrap>", line 219, in _call_with_frames_removed
  File "/home/vid/makereport/DTPreport/DTPreport/settings.py", line 108
    DATABASES = {
    ^
IndentationError: unexpected indent
[2021-02-19 16:28:16 +0000] [60014] [INFO] Worker exiting (pid: 60014)
[2021-02-19 16:28:16 +0000] [60012] [INFO] Shutting down: Master
[2021-02-19 16:28:16 +0000] [60012] [INFO] Reason: Worker failed to boot.
[2021-02-19 16:28:18 +0000] [60016] [INFO] Starting gunicorn 20.0.4
[2021-02-19 16:28:18 +0000] [60016] [INFO] Listening at: http://127.0.0.1:46710 (60016)
[2021-02-19 16:28:18 +0000] [60016] [INFO] Using worker: sync
[2021-02-19 16:28:18 +0000] [60019] [INFO] Booting worker with pid: 60019
[2021-02-19 16:28:18 +0000] [60019] [ERROR] Exception in worker process
Traceback (most recent call last):
  File "/home/vid/makereport/DTPreport/env/lib/python3.6/site-packages/gunicorn/arbiter.py", line 583, in spawn_worker
    worker.init_process()
  File "/home/vid/makereport/DTPreport/env/lib/python3.6/site-packages/gunicorn/workers/base.py", line 119, in init_process
    self.load_wsgi()
  File "/home/vid/makereport/DTPreport/env/lib/python3.6/site-packages/gunicorn/workers/base.py", line 144, in load_wsgi
    self.wsgi = self.app.wsgi()
  File "/home/vid/makereport/DTPreport/env/lib/python3.6/site-packages/gunicorn/app/base.py", line 67, in wsgi
    self.callable = self.load()
  File "/home/vid/makereport/DTPreport/env/lib/python3.6/site-packages/gunicorn/app/wsgiapp.py", line 49, in load
    return self.load_wsgiapp()
  File "/home/vid/makereport/DTPreport/env/lib/python3.6/site-packages/gunicorn/app/wsgiapp.py", line 39, in load_wsgiapp
    return util.import_app(self.app_uri)
  File "/home/vid/makereport/DTPreport/env/lib/python3.6/site-packages/gunicorn/util.py", line 358, in import_app
    mod = importlib.import_module(module)
  File "/usr/lib/python3.6/importlib/__init__.py", line 126, in import_module
    return _bootstrap._gcd_import(name[level:], package, level)
  File "<frozen importlib._bootstrap>", line 994, in _gcd_import
  File "<frozen importlib._bootstrap>", line 971, in _find_and_load
  File "<frozen importlib._bootstrap>", line 955, in _find_and_load_unlocked
  File "<frozen importlib._bootstrap>", line 665, in _load_unlocked
  File "<frozen importlib._bootstrap_external>", line 678, in exec_module
  File "<frozen importlib._bootstrap>", line 219, in _call_with_frames_removed
  File "/home/vid/makereport/DTPreport/DTPreport/wsgi.py", line 16, in <module>
    application = get_wsgi_application()
  File "/home/vid/makereport/DTPreport/env/lib/python3.6/site-packages/django/core/wsgi.py", line 12, in get_wsgi_application
    django.setup(set_prefix=False)
  File "/home/vid/makereport/DTPreport/env/lib/python3.6/site-packages/django/__init__.py", line 19, in setup
    configure_logging(settings.LOGGING_CONFIG, settings.LOGGING)
  File "/home/vid/makereport/DTPreport/env/lib/python3.6/site-packages/django/conf/__init__.py", line 82, in __getattr__
    self._setup(name)
  File "/home/vid/makereport/DTPreport/env/lib/python3.6/site-packages/django/conf/__init__.py", line 69, in _setup
    self._wrapped = Settings(settings_module)
  File "/home/vid/makereport/DTPreport/env/lib/python3.6/site-packages/django/conf/__init__.py", line 170, in __init__
    mod = importlib.import_module(self.SETTINGS_MODULE)
  File "/usr/lib/python3.6/importlib/__init__.py", line 126, in import_module
    return _bootstrap._gcd_import(name[level:], package, level)
  File "<frozen importlib._bootstrap>", line 994, in _gcd_import
  File "<frozen importlib._bootstrap>", line 971, in _find_and_load
  File "<frozen importlib._bootstrap>", line 955, in _find_and_load_unlocked
  File "<frozen importlib._bootstrap>", line 665, in _load_unlocked
  File "<frozen importlib._bootstrap_external>", line 674, in exec_module
  File "<frozen importlib._bootstrap_external>", line 781, in get_code
  File "<frozen importlib._bootstrap_external>", line 741, in source_to_code
  File "<frozen importlib._bootstrap>", line 219, in _call_with_frames_removed
  File "/home/vid/makereport/DTPreport/DTPreport/settings.py", line 108
    DATABASES = {
    ^
IndentationError: unexpected indent
[2021-02-19 16:28:18 +0000] [60019] [INFO] Worker exiting (pid: 60019)
[2021-02-19 16:28:18 +0000] [60016] [INFO] Shutting down: Master
[2021-02-19 16:28:18 +0000] [60016] [INFO] Reason: Worker failed to boot.
[2021-02-19 16:28:21 +0000] [60021] [INFO] Starting gunicorn 20.0.4
[2021-02-19 16:28:21 +0000] [60021] [INFO] Listening at: http://127.0.0.1:46710 (60021)
[2021-02-19 16:28:21 +0000] [60021] [INFO] Using worker: sync
[2021-02-19 16:28:21 +0000] [60023] [INFO] Booting worker with pid: 60023
[2021-02-19 16:28:21 +0000] [60023] [ERROR] Exception in worker process
Traceback (most recent call last):
  File "/home/vid/makereport/DTPreport/env/lib/python3.6/site-packages/gunicorn/arbiter.py", line 583, in spawn_worker
    worker.init_process()
  File "/home/vid/makereport/DTPreport/env/lib/python3.6/site-packages/gunicorn/workers/base.py", line 119, in init_process
    self.load_wsgi()
  File "/home/vid/makereport/DTPreport/env/lib/python3.6/site-packages/gunicorn/workers/base.py", line 144, in load_wsgi
    self.wsgi = self.app.wsgi()
  File "/home/vid/makereport/DTPreport/env/lib/python3.6/site-packages/gunicorn/app/base.py", line 67, in wsgi
    self.callable = self.load()
  File "/home/vid/makereport/DTPreport/env/lib/python3.6/site-packages/gunicorn/app/wsgiapp.py", line 49, in load
    return self.load_wsgiapp()
  File "/home/vid/makereport/DTPreport/env/lib/python3.6/site-packages/gunicorn/app/wsgiapp.py", line 39, in load_wsgiapp
    return util.import_app(self.app_uri)
  File "/home/vid/makereport/DTPreport/env/lib/python3.6/site-packages/gunicorn/util.py", line 358, in import_app
    mod = importlib.import_module(module)
  File "/usr/lib/python3.6/importlib/__init__.py", line 126, in import_module
    return _bootstrap._gcd_import(name[level:], package, level)
  File "<frozen importlib._bootstrap>", line 994, in _gcd_import
  File "<frozen importlib._bootstrap>", line 971, in _find_and_load
  File "<frozen importlib._bootstrap>", line 955, in _find_and_load_unlocked
  File "<frozen importlib._bootstrap>", line 665, in _load_unlocked
  File "<frozen importlib._bootstrap_external>", line 678, in exec_module
  File "<frozen importlib._bootstrap>", line 219, in _call_with_frames_removed
  File "/home/vid/makereport/DTPreport/DTPreport/wsgi.py", line 16, in <module>
    application = get_wsgi_application()
  File "/home/vid/makereport/DTPreport/env/lib/python3.6/site-packages/django/core/wsgi.py", line 12, in get_wsgi_application
    django.setup(set_prefix=False)
  File "/home/vid/makereport/DTPreport/env/lib/python3.6/site-packages/django/__init__.py", line 19, in setup
    configure_logging(settings.LOGGING_CONFIG, settings.LOGGING)
  File "/home/vid/makereport/DTPreport/env/lib/python3.6/site-packages/django/conf/__init__.py", line 82, in __getattr__
    self._setup(name)
  File "/home/vid/makereport/DTPreport/env/lib/python3.6/site-packages/django/conf/__init__.py", line 69, in _setup
    self._wrapped = Settings(settings_module)
  File "/home/vid/makereport/DTPreport/env/lib/python3.6/site-packages/django/conf/__init__.py", line 170, in __init__
    mod = importlib.import_module(self.SETTINGS_MODULE)
  File "/usr/lib/python3.6/importlib/__init__.py", line 126, in import_module
    return _bootstrap._gcd_import(name[level:], package, level)
  File "<frozen importlib._bootstrap>", line 994, in _gcd_import
  File "<frozen importlib._bootstrap>", line 971, in _find_and_load
  File "<frozen importlib._bootstrap>", line 955, in _find_and_load_unlocked
  File "<frozen importlib._bootstrap>", line 665, in _load_unlocked
  File "<frozen importlib._bootstrap_external>", line 674, in exec_module
  File "<frozen importlib._bootstrap_external>", line 781, in get_code
  File "<frozen importlib._bootstrap_external>", line 741, in source_to_code
  File "<frozen importlib._bootstrap>", line 219, in _call_with_frames_removed
  File "/home/vid/makereport/DTPreport/DTPreport/settings.py", line 108
    DATABASES = {
    ^
IndentationError: unexpected indent
[2021-02-19 16:28:21 +0000] [60023] [INFO] Worker exiting (pid: 60023)
[2021-02-19 16:28:21 +0000] [60021] [INFO] Shutting down: Master
[2021-02-19 16:28:21 +0000] [60021] [INFO] Reason: Worker failed to boot.
[2021-02-19 16:28:24 +0000] [60025] [INFO] Starting gunicorn 20.0.4
[2021-02-19 16:28:24 +0000] [60025] [INFO] Listening at: http://127.0.0.1:46710 (60025)
[2021-02-19 16:28:24 +0000] [60025] [INFO] Using worker: sync
[2021-02-19 16:28:24 +0000] [60028] [INFO] Booting worker with pid: 60028
[2021-02-19 16:28:25 +0000] [60028] [ERROR] Exception in worker process
Traceback (most recent call last):
  File "/home/vid/makereport/DTPreport/env/lib/python3.6/site-packages/gunicorn/arbiter.py", line 583, in spawn_worker
    worker.init_process()
  File "/home/vid/makereport/DTPreport/env/lib/python3.6/site-packages/gunicorn/workers/base.py", line 119, in init_process
    self.load_wsgi()
  File "/home/vid/makereport/DTPreport/env/lib/python3.6/site-packages/gunicorn/workers/base.py", line 144, in load_wsgi
    self.wsgi = self.app.wsgi()
  File "/home/vid/makereport/DTPreport/env/lib/python3.6/site-packages/gunicorn/app/base.py", line 67, in wsgi
    self.callable = self.load()
  File "/home/vid/makereport/DTPreport/env/lib/python3.6/site-packages/gunicorn/app/wsgiapp.py", line 49, in load
    return self.load_wsgiapp()
  File "/home/vid/makereport/DTPreport/env/lib/python3.6/site-packages/gunicorn/app/wsgiapp.py", line 39, in load_wsgiapp
    return util.import_app(self.app_uri)
  File "/home/vid/makereport/DTPreport/env/lib/python3.6/site-packages/gunicorn/util.py", line 358, in import_app
    mod = importlib.import_module(module)
  File "/usr/lib/python3.6/importlib/__init__.py", line 126, in import_module
    return _bootstrap._gcd_import(name[level:], package, level)
  File "<frozen importlib._bootstrap>", line 994, in _gcd_import
  File "<frozen importlib._bootstrap>", line 971, in _find_and_load
  File "<frozen importlib._bootstrap>", line 955, in _find_and_load_unlocked
  File "<frozen importlib._bootstrap>", line 665, in _load_unlocked
  File "<frozen importlib._bootstrap_external>", line 678, in exec_module
  File "<frozen importlib._bootstrap>", line 219, in _call_with_frames_removed
  File "/home/vid/makereport/DTPreport/DTPreport/wsgi.py", line 16, in <module>
    application = get_wsgi_application()
  File "/home/vid/makereport/DTPreport/env/lib/python3.6/site-packages/django/core/wsgi.py", line 12, in get_wsgi_application
    django.setup(set_prefix=False)
  File "/home/vid/makereport/DTPreport/env/lib/python3.6/site-packages/django/__init__.py", line 19, in setup
    configure_logging(settings.LOGGING_CONFIG, settings.LOGGING)
  File "/home/vid/makereport/DTPreport/env/lib/python3.6/site-packages/django/conf/__init__.py", line 82, in __getattr__
    self._setup(name)
  File "/home/vid/makereport/DTPreport/env/lib/python3.6/site-packages/django/conf/__init__.py", line 69, in _setup
    self._wrapped = Settings(settings_module)
  File "/home/vid/makereport/DTPreport/env/lib/python3.6/site-packages/django/conf/__init__.py", line 170, in __init__
    mod = importlib.import_module(self.SETTINGS_MODULE)
  File "/usr/lib/python3.6/importlib/__init__.py", line 126, in import_module
    return _bootstrap._gcd_import(name[level:], package, level)
  File "<frozen importlib._bootstrap>", line 994, in _gcd_import
  File "<frozen importlib._bootstrap>", line 971, in _find_and_load
  File "<frozen importlib._bootstrap>", line 955, in _find_and_load_unlocked
  File "<frozen importlib._bootstrap>", line 665, in _load_unlocked
  File "<frozen importlib._bootstrap_external>", line 674, in exec_module
  File "<frozen importlib._bootstrap_external>", line 781, in get_code
  File "<frozen importlib._bootstrap_external>", line 741, in source_to_code
  File "<frozen importlib._bootstrap>", line 219, in _call_with_frames_removed
  File "/home/vid/makereport/DTPreport/DTPreport/settings.py", line 108
    DATABASES = {
    ^
IndentationError: unexpected indent
[2021-02-19 16:28:25 +0000] [60028] [INFO] Worker exiting (pid: 60028)
[2021-02-19 16:28:25 +0000] [60025] [INFO] Shutting down: Master
[2021-02-19 16:28:25 +0000] [60025] [INFO] Reason: Worker failed to boot.
[2021-02-19 16:30:56 +0000] [60230] [INFO] Starting gunicorn 20.0.4
[2021-02-19 16:30:56 +0000] [60230] [INFO] Listening at: http://127.0.0.1:46710 (60230)
[2021-02-19 16:30:56 +0000] [60230] [INFO] Using worker: sync
[2021-02-19 16:30:56 +0000] [60232] [INFO] Booting worker with pid: 60232
[2021-02-19 16:31:47 +0000] [60232] [INFO] Worker exiting (pid: 60232)
[2021-02-19 16:31:47 +0000] [60230] [INFO] Handling signal: term
[2021-02-19 16:31:48 +0000] [60230] [INFO] Shutting down: Master
[2021-02-19 16:31:48 +0000] [60247] [INFO] Starting gunicorn 20.0.4
[2021-02-19 16:31:48 +0000] [60247] [INFO] Listening at: http://127.0.0.1:46710 (60247)
[2021-02-19 16:31:48 +0000] [60247] [INFO] Using worker: sync
[2021-02-19 16:31:48 +0000] [60249] [INFO] Booting worker with pid: 60249
Internal Server Error: /report/create/
Traceback (most recent call last):
  File "/home/vid/makereport/DTPreport/env/lib/python3.6/site-packages/django/core/handlers/exception.py", line 47, in inner
    response = get_response(request)
  File "/home/vid/makereport/DTPreport/env/lib/python3.6/site-packages/django/core/handlers/base.py", line 181, in _get_response
    response = wrapped_callback(request, *callback_args, **callback_kwargs)
  File "/home/vid/makereport/DTPreport/env/lib/python3.6/site-packages/django/views/generic/base.py", line 70, in view
    return self.dispatch(request, *args, **kwargs)
  File "/home/vid/makereport/DTPreport/env/lib/python3.6/site-packages/django/views/generic/base.py", line 98, in dispatch
    return handler(request, *args, **kwargs)
  File "/home/vid/makereport/DTPreport/env/lib/python3.6/site-packages/django/utils/decorators.py", line 43, in _wrapper
    return bound_method(*args, **kwargs)
  File "/home/vid/makereport/DTPreport/env/lib/python3.6/site-packages/django/contrib/auth/decorators.py", line 21, in _wrapped_view
    return view_func(request, *args, **kwargs)
  File "/home/vid/makereport/DTPreport/makereport/views.py", line 105, in get
    'report_rate_price': request.user.myuser.report_rate_price,
  File "/home/vid/makereport/DTPreport/env/lib/python3.6/site-packages/django/utils/functional.py", line 241, in inner
    return func(self._wrapped, *args)
  File "/home/vid/makereport/DTPreport/env/lib/python3.6/site-packages/django/db/models/fields/related_descriptors.py", line 424, in __get__
    self.related.get_accessor_name()
django.contrib.auth.models.User.myuser.RelatedObjectDoesNotExist: User has no myuser.
[2021-02-19 16:34:01 +0000] [60247] [INFO] Handling signal: term
[2021-02-19 16:34:01 +0000] [60249] [INFO] Worker exiting (pid: 60249)
[2021-02-19 16:34:01 +0000] [60247] [INFO] Shutting down: Master
[2021-02-19 16:34:01 +0000] [60393] [INFO] Starting gunicorn 20.0.4
[2021-02-19 16:34:01 +0000] [60393] [INFO] Listening at: http://127.0.0.1:46710 (60393)
[2021-02-19 16:34:01 +0000] [60393] [INFO] Using worker: sync
[2021-02-19 16:34:01 +0000] [60395] [INFO] Booting worker with pid: 60395
[2021-02-19 16:36:27 +0000] [60395] [INFO] Worker exiting (pid: 60395)
[2021-02-19 16:36:27 +0000] [60393] [INFO] Handling signal: term
[2021-02-19 16:36:27 +0000] [60393] [INFO] Shutting down: Master
[2021-02-19 16:36:27 +0000] [60430] [INFO] Starting gunicorn 20.0.4
[2021-02-19 16:36:27 +0000] [60430] [INFO] Listening at: http://127.0.0.1:46710 (60430)
[2021-02-19 16:36:27 +0000] [60430] [INFO] Using worker: sync
[2021-02-19 16:36:27 +0000] [60433] [INFO] Booting worker with pid: 60433
[2021-02-19 16:41:17 +0000] [60433] [INFO] Worker exiting (pid: 60433)
[2021-02-19 16:41:17 +0000] [60430] [INFO] Handling signal: term
[2021-02-19 16:41:17 +0000] [60430] [INFO] Shutting down: Master
[2021-02-19 16:41:17 +0000] [60494] [INFO] Starting gunicorn 20.0.4
[2021-02-19 16:41:17 +0000] [60494] [INFO] Listening at: http://127.0.0.1:46710 (60494)
[2021-02-19 16:41:17 +0000] [60494] [INFO] Using worker: sync
[2021-02-19 16:41:17 +0000] [60496] [INFO] Booting worker with pid: 60496
Internal Server Error: /report/ajax/get_product_cost/
Traceback (most recent call last):
  File "/home/vid/makereport/DTPreport/env/lib/python3.6/site-packages/django/core/handlers/exception.py", line 47, in inner
    response = get_response(request)
  File "/home/vid/makereport/DTPreport/env/lib/python3.6/site-packages/django/core/handlers/base.py", line 181, in _get_response
    response = wrapped_callback(request, *callback_args, **callback_kwargs)
  File "/home/vid/makereport/DTPreport/makereport/utils.py", line 133, in get_product_cost
    total_cost = int(float(quantity) * float(price))
ValueError: could not convert string to float: 
/home/vid/makereport/DTPreport/env/lib/python3.6/site-packages/django/db/models/fields/__init__.py:1312: RuntimeWarning: DateTimeField Report.created_at received a naive datetime (2021-02-19 00:00:00) while time zone support is active.
  RuntimeWarning)
Internal Server Error: /report/create/
Traceback (most recent call last):
  File "/home/vid/makereport/DTPreport/env/lib/python3.6/site-packages/django/core/handlers/exception.py", line 47, in inner
    response = get_response(request)
  File "/home/vid/makereport/DTPreport/env/lib/python3.6/site-packages/django/core/handlers/base.py", line 181, in _get_response
    response = wrapped_callback(request, *callback_args, **callback_kwargs)
  File "/home/vid/makereport/DTPreport/env/lib/python3.6/site-packages/django/views/generic/base.py", line 70, in view
    return self.dispatch(request, *args, **kwargs)
  File "/home/vid/makereport/DTPreport/env/lib/python3.6/site-packages/django/views/generic/base.py", line 98, in dispatch
    return handler(request, *args, **kwargs)
  File "/home/vid/makereport/DTPreport/env/lib/python3.6/site-packages/django/utils/decorators.py", line 43, in _wrapper
    return bound_method(*args, **kwargs)
  File "/home/vid/makereport/DTPreport/env/lib/python3.6/site-packages/django/contrib/auth/decorators.py", line 21, in _wrapped_view
    return view_func(request, *args, **kwargs)
  File "/home/vid/makereport/DTPreport/makereport/views.py", line 157, in post
    Images.objects.create(image=each, report=new_report)
  File "/home/vid/makereport/DTPreport/env/lib/python3.6/site-packages/django/db/models/manager.py", line 85, in manager_method
    return getattr(self.get_queryset(), name)(*args, **kwargs)
  File "/home/vid/makereport/DTPreport/env/lib/python3.6/site-packages/django/db/models/query.py", line 447, in create
    obj.save(force_insert=True, using=self.db)
  File "/home/vid/makereport/DTPreport/env/lib/python3.6/site-packages/django/db/models/base.py", line 754, in save
    force_update=force_update, update_fields=update_fields)
  File "/home/vid/makereport/DTPreport/env/lib/python3.6/site-packages/django/db/models/base.py", line 792, in save_base
    force_update, using, update_fields,
  File "/home/vid/makereport/DTPreport/env/lib/python3.6/site-packages/django/db/models/base.py", line 895, in _save_table
    results = self._do_insert(cls._base_manager, using, fields, returning_fields, raw)
  File "/home/vid/makereport/DTPreport/env/lib/python3.6/site-packages/django/db/models/base.py", line 935, in _do_insert
    using=using, raw=raw,
  File "/home/vid/makereport/DTPreport/env/lib/python3.6/site-packages/django/db/models/manager.py", line 85, in manager_method
    return getattr(self.get_queryset(), name)(*args, **kwargs)
  File "/home/vid/makereport/DTPreport/env/lib/python3.6/site-packages/django/db/models/query.py", line 1254, in _insert
    return query.get_compiler(using=using).execute_sql(returning_fields)
  File "/home/vid/makereport/DTPreport/env/lib/python3.6/site-packages/django/db/models/sql/compiler.py", line 1396, in execute_sql
    for sql, params in self.as_sql():
  File "/home/vid/makereport/DTPreport/env/lib/python3.6/site-packages/django/db/models/sql/compiler.py", line 1341, in as_sql
    for obj in self.query.objs
  File "/home/vid/makereport/DTPreport/env/lib/python3.6/site-packages/django/db/models/sql/compiler.py", line 1341, in <listcomp>
    for obj in self.query.objs
  File "/home/vid/makereport/DTPreport/env/lib/python3.6/site-packages/django/db/models/sql/compiler.py", line 1340, in <listcomp>
    [self.prepare_value(field, self.pre_save_val(field, obj)) for field in fields]
  File "/home/vid/makereport/DTPreport/env/lib/python3.6/site-packages/django/db/models/sql/compiler.py", line 1291, in pre_save_val
    return field.pre_save(obj, add=True)
  File "/home/vid/makereport/DTPreport/env/lib/python3.6/site-packages/django/db/models/fields/files.py", line 307, in pre_save
    file.save(file.name, file.file, save=False)
  File "/home/vid/makereport/DTPreport/env/lib/python3.6/site-packages/django/db/models/fields/files.py", line 87, in save
    self.name = self.storage.save(name, content, max_length=self.field.max_length)
  File "/home/vid/makereport/DTPreport/env/lib/python3.6/site-packages/django/core/files/storage.py", line 52, in save
    return self._save(name, content)
  File "/home/vid/makereport/DTPreport/env/lib/python3.6/site-packages/django/core/files/storage.py", line 248, in _save
    os.makedirs(directory, exist_ok=True)
  File "/usr/lib/python3.6/os.py", line 220, in makedirs
    mkdir(name, mode)
PermissionError: [Errno 13] Permission denied: '/home/vid/makereport/DTPreport/media'
Internal Server Error: /report/create/
Traceback (most recent call last):
  File "/home/vid/makereport/DTPreport/env/lib/python3.6/site-packages/django/core/handlers/exception.py", line 47, in inner
    response = get_response(request)
  File "/home/vid/makereport/DTPreport/env/lib/python3.6/site-packages/django/core/handlers/base.py", line 181, in _get_response
    response = wrapped_callback(request, *callback_args, **callback_kwargs)
  File "/home/vid/makereport/DTPreport/env/lib/python3.6/site-packages/django/views/generic/base.py", line 70, in view
    return self.dispatch(request, *args, **kwargs)
  File "/home/vid/makereport/DTPreport/env/lib/python3.6/site-packages/django/views/generic/base.py", line 98, in dispatch
    return handler(request, *args, **kwargs)
  File "/home/vid/makereport/DTPreport/env/lib/python3.6/site-packages/django/utils/decorators.py", line 43, in _wrapper
    return bound_method(*args, **kwargs)
  File "/home/vid/makereport/DTPreport/env/lib/python3.6/site-packages/django/contrib/auth/decorators.py", line 21, in _wrapped_view
    return view_func(request, *args, **kwargs)
  File "/home/vid/makereport/DTPreport/makereport/views.py", line 157, in post
    Images.objects.create(image=each, report=new_report)
  File "/home/vid/makereport/DTPreport/env/lib/python3.6/site-packages/django/db/models/manager.py", line 85, in manager_method
    return getattr(self.get_queryset(), name)(*args, **kwargs)
  File "/home/vid/makereport/DTPreport/env/lib/python3.6/site-packages/django/db/models/query.py", line 447, in create
    obj.save(force_insert=True, using=self.db)
  File "/home/vid/makereport/DTPreport/env/lib/python3.6/site-packages/django/db/models/base.py", line 754, in save
    force_update=force_update, update_fields=update_fields)
  File "/home/vid/makereport/DTPreport/env/lib/python3.6/site-packages/django/db/models/base.py", line 792, in save_base
    force_update, using, update_fields,
  File "/home/vid/makereport/DTPreport/env/lib/python3.6/site-packages/django/db/models/base.py", line 895, in _save_table
    results = self._do_insert(cls._base_manager, using, fields, returning_fields, raw)
  File "/home/vid/makereport/DTPreport/env/lib/python3.6/site-packages/django/db/models/base.py", line 935, in _do_insert
    using=using, raw=raw,
  File "/home/vid/makereport/DTPreport/env/lib/python3.6/site-packages/django/db/models/manager.py", line 85, in manager_method
    return getattr(self.get_queryset(), name)(*args, **kwargs)
  File "/home/vid/makereport/DTPreport/env/lib/python3.6/site-packages/django/db/models/query.py", line 1254, in _insert
    return query.get_compiler(using=using).execute_sql(returning_fields)
  File "/home/vid/makereport/DTPreport/env/lib/python3.6/site-packages/django/db/models/sql/compiler.py", line 1396, in execute_sql
    for sql, params in self.as_sql():
  File "/home/vid/makereport/DTPreport/env/lib/python3.6/site-packages/django/db/models/sql/compiler.py", line 1341, in as_sql
    for obj in self.query.objs
  File "/home/vid/makereport/DTPreport/env/lib/python3.6/site-packages/django/db/models/sql/compiler.py", line 1341, in <listcomp>
    for obj in self.query.objs
  File "/home/vid/makereport/DTPreport/env/lib/python3.6/site-packages/django/db/models/sql/compiler.py", line 1340, in <listcomp>
    [self.prepare_value(field, self.pre_save_val(field, obj)) for field in fields]
  File "/home/vid/makereport/DTPreport/env/lib/python3.6/site-packages/django/db/models/sql/compiler.py", line 1291, in pre_save_val
    return field.pre_save(obj, add=True)
  File "/home/vid/makereport/DTPreport/env/lib/python3.6/site-packages/django/db/models/fields/files.py", line 307, in pre_save
    file.save(file.name, file.file, save=False)
  File "/home/vid/makereport/DTPreport/env/lib/python3.6/site-packages/django/db/models/fields/files.py", line 87, in save
    self.name = self.storage.save(name, content, max_length=self.field.max_length)
  File "/home/vid/makereport/DTPreport/env/lib/python3.6/site-packages/django/core/files/storage.py", line 52, in save
    return self._save(name, content)
  File "/home/vid/makereport/DTPreport/env/lib/python3.6/site-packages/django/core/files/storage.py", line 267, in _save
    fd = os.open(full_path, self.OS_OPEN_FLAGS, 0o666)
PermissionError: [Errno 13] Permission denied: '/home/vid/makereport/DTPreport/media/123.png'
[2021-02-19 16:49:07 +0000] [60496] [INFO] Worker exiting (pid: 60496)
[2021-02-19 16:49:07 +0000] [60494] [INFO] Handling signal: term
[2021-02-19 16:49:07 +0000] [60494] [INFO] Shutting down: Master
[2021-02-19 16:49:07 +0000] [60615] [INFO] Starting gunicorn 20.0.4
[2021-02-19 16:49:07 +0000] [60615] [INFO] Listening at: http://127.0.0.1:46710 (60615)
[2021-02-19 16:49:07 +0000] [60615] [INFO] Using worker: sync
[2021-02-19 16:49:07 +0000] [60617] [INFO] Booting worker with pid: 60617
/home/vid/makereport/DTPreport/env/lib/python3.6/site-packages/django/db/models/fields/__init__.py:1312: RuntimeWarning: DateTimeField Report.created_at received a naive datetime (2021-02-19 00:00:00) while time zone support is active.
  RuntimeWarning)
Internal Server Error: /report/create/
Traceback (most recent call last):
  File "/home/vid/makereport/DTPreport/env/lib/python3.6/site-packages/django/core/handlers/exception.py", line 47, in inner
    response = get_response(request)
  File "/home/vid/makereport/DTPreport/env/lib/python3.6/site-packages/django/core/handlers/base.py", line 181, in _get_response
    response = wrapped_callback(request, *callback_args, **callback_kwargs)
  File "/home/vid/makereport/DTPreport/env/lib/python3.6/site-packages/django/views/generic/base.py", line 70, in view
    return self.dispatch(request, *args, **kwargs)
  File "/home/vid/makereport/DTPreport/env/lib/python3.6/site-packages/django/views/generic/base.py", line 98, in dispatch
    return handler(request, *args, **kwargs)
  File "/home/vid/makereport/DTPreport/env/lib/python3.6/site-packages/django/utils/decorators.py", line 43, in _wrapper
    return bound_method(*args, **kwargs)
  File "/home/vid/makereport/DTPreport/env/lib/python3.6/site-packages/django/contrib/auth/decorators.py", line 21, in _wrapped_view
    return view_func(request, *args, **kwargs)
  File "/home/vid/makereport/DTPreport/makereport/views.py", line 157, in post
    Images.objects.create(image=each, report=new_report)
  File "/home/vid/makereport/DTPreport/env/lib/python3.6/site-packages/django/db/models/manager.py", line 85, in manager_method
    return getattr(self.get_queryset(), name)(*args, **kwargs)
  File "/home/vid/makereport/DTPreport/env/lib/python3.6/site-packages/django/db/models/query.py", line 447, in create
    obj.save(force_insert=True, using=self.db)
  File "/home/vid/makereport/DTPreport/env/lib/python3.6/site-packages/django/db/models/base.py", line 754, in save
    force_update=force_update, update_fields=update_fields)
  File "/home/vid/makereport/DTPreport/env/lib/python3.6/site-packages/django/db/models/base.py", line 792, in save_base
    force_update, using, update_fields,
  File "/home/vid/makereport/DTPreport/env/lib/python3.6/site-packages/django/db/models/base.py", line 895, in _save_table
    results = self._do_insert(cls._base_manager, using, fields, returning_fields, raw)
  File "/home/vid/makereport/DTPreport/env/lib/python3.6/site-packages/django/db/models/base.py", line 935, in _do_insert
    using=using, raw=raw,
  File "/home/vid/makereport/DTPreport/env/lib/python3.6/site-packages/django/db/models/manager.py", line 85, in manager_method
    return getattr(self.get_queryset(), name)(*args, **kwargs)
  File "/home/vid/makereport/DTPreport/env/lib/python3.6/site-packages/django/db/models/query.py", line 1254, in _insert
    return query.get_compiler(using=using).execute_sql(returning_fields)
  File "/home/vid/makereport/DTPreport/env/lib/python3.6/site-packages/django/db/models/sql/compiler.py", line 1396, in execute_sql
    for sql, params in self.as_sql():
  File "/home/vid/makereport/DTPreport/env/lib/python3.6/site-packages/django/db/models/sql/compiler.py", line 1341, in as_sql
    for obj in self.query.objs
  File "/home/vid/makereport/DTPreport/env/lib/python3.6/site-packages/django/db/models/sql/compiler.py", line 1341, in <listcomp>
    for obj in self.query.objs
  File "/home/vid/makereport/DTPreport/env/lib/python3.6/site-packages/django/db/models/sql/compiler.py", line 1340, in <listcomp>
    [self.prepare_value(field, self.pre_save_val(field, obj)) for field in fields]
  File "/home/vid/makereport/DTPreport/env/lib/python3.6/site-packages/django/db/models/sql/compiler.py", line 1291, in pre_save_val
    return field.pre_save(obj, add=True)
  File "/home/vid/makereport/DTPreport/env/lib/python3.6/site-packages/django/db/models/fields/files.py", line 307, in pre_save
    file.save(file.name, file.file, save=False)
  File "/home/vid/makereport/DTPreport/env/lib/python3.6/site-packages/django/db/models/fields/files.py", line 87, in save
    self.name = self.storage.save(name, content, max_length=self.field.max_length)
  File "/home/vid/makereport/DTPreport/env/lib/python3.6/site-packages/django/core/files/storage.py", line 52, in save
    return self._save(name, content)
  File "/home/vid/makereport/DTPreport/env/lib/python3.6/site-packages/django/core/files/storage.py", line 267, in _save
    fd = os.open(full_path, self.OS_OPEN_FLAGS, 0o666)
PermissionError: [Errno 13] Permission denied: '/home/vid/makereport/DTPreport/media/123.png'
[2021-02-19 16:59:38 +0000] [60615] [INFO] Handling signal: term
[2021-02-19 16:59:38 +0000] [60617] [INFO] Worker exiting (pid: 60617)
[2021-02-19 16:59:38 +0000] [60615] [INFO] Shutting down: Master
[2021-02-19 16:59:40 +0000] [60994] [INFO] Starting gunicorn 20.0.4
[2021-02-19 16:59:40 +0000] [60994] [INFO] Listening at: http://127.0.0.1:46710 (60994)
[2021-02-19 16:59:40 +0000] [60994] [INFO] Using worker: sync
[2021-02-19 16:59:40 +0000] [60996] [INFO] Booting worker with pid: 60996
/home/vid/makereport/DTPreport/env/lib/python3.6/site-packages/django/db/models/fields/__init__.py:1312: RuntimeWarning: DateTimeField Report.created_at received a naive datetime (2021-02-19 00:00:00) while time zone support is active.
  RuntimeWarning)
[2021-02-19 17:04:13 +0000] [60996] [INFO] Worker exiting (pid: 60996)
[2021-02-19 17:04:13 +0000] [60994] [INFO] Handling signal: term
[2021-02-19 17:04:13 +0000] [60994] [INFO] Shutting down: Master
[2021-02-19 17:04:13 +0000] [61043] [INFO] Starting gunicorn 20.0.4
[2021-02-19 17:04:13 +0000] [61043] [INFO] Listening at: http://127.0.0.1:46710 (61043)
[2021-02-19 17:04:13 +0000] [61043] [INFO] Using worker: sync
[2021-02-19 17:04:13 +0000] [61045] [INFO] Booting worker with pid: 61045
[2021-02-19 17:04:51 +0000] [61045] [INFO] Worker exiting (pid: 61045)
[2021-02-19 17:04:51 +0000] [61043] [INFO] Handling signal: term
[2021-02-19 17:04:52 +0000] [61043] [INFO] Shutting down: Master
[2021-02-19 17:04:52 +0000] [61055] [INFO] Starting gunicorn 20.0.4
[2021-02-19 17:04:52 +0000] [61055] [INFO] Listening at: http://127.0.0.1:46710 (61055)
[2021-02-19 17:04:52 +0000] [61055] [INFO] Using worker: sync
[2021-02-19 17:04:52 +0000] [61057] [INFO] Booting worker with pid: 61057
[2021-02-19 17:09:53 +0000] [61055] [INFO] Handling signal: term
[2021-02-19 17:09:53 +0000] [61057] [INFO] Worker exiting (pid: 61057)
[2021-02-19 17:09:54 +0000] [61055] [INFO] Shutting down: Master
[2021-02-19 17:09:54 +0000] [61105] [INFO] Starting gunicorn 20.0.4
[2021-02-19 17:09:54 +0000] [61105] [INFO] Listening at: http://127.0.0.1:46710 (61105)
[2021-02-19 17:09:54 +0000] [61105] [INFO] Using worker: sync
[2021-02-19 17:09:54 +0000] [61107] [INFO] Booting worker with pid: 61107
[2021-02-19 17:11:09 +0000] [61107] [INFO] Worker exiting (pid: 61107)
[2021-02-19 17:11:09 +0000] [61105] [INFO] Handling signal: term
[2021-02-19 17:11:10 +0000] [61105] [INFO] Shutting down: Master
[2021-02-19 17:11:10 +0000] [61121] [INFO] Starting gunicorn 20.0.4
[2021-02-19 17:11:10 +0000] [61121] [INFO] Listening at: http://127.0.0.1:46710 (61121)
[2021-02-19 17:11:10 +0000] [61121] [INFO] Using worker: sync
[2021-02-19 17:11:10 +0000] [61123] [INFO] Booting worker with pid: 61123
[2021-02-19 17:12:00 +0000] [61121] [INFO] Handling signal: term
[2021-02-19 17:12:00 +0000] [61123] [INFO] Worker exiting (pid: 61123)
[2021-02-19 17:12:00 +0000] [61121] [INFO] Shutting down: Master
[2021-02-19 17:12:00 +0000] [61134] [INFO] Starting gunicorn 20.0.4
[2021-02-19 17:12:00 +0000] [61134] [INFO] Listening at: http://127.0.0.1:46710 (61134)
[2021-02-19 17:12:00 +0000] [61134] [INFO] Using worker: sync
[2021-02-19 17:12:00 +0000] [61136] [INFO] Booting worker with pid: 61136
[2021-02-19 17:12:43 +0000] [61136] [INFO] Worker exiting (pid: 61136)
[2021-02-19 17:12:43 +0000] [61134] [INFO] Handling signal: term
[2021-02-19 17:12:43 +0000] [61134] [INFO] Shutting down: Master
[2021-02-19 17:12:43 +0000] [61146] [INFO] Starting gunicorn 20.0.4
[2021-02-19 17:12:43 +0000] [61146] [INFO] Listening at: http://127.0.0.1:46710 (61146)
[2021-02-19 17:12:43 +0000] [61146] [INFO] Using worker: sync
[2021-02-19 17:12:43 +0000] [61148] [INFO] Booting worker with pid: 61148
[2021-02-19 17:13:21 +0000] [61148] [INFO] Worker exiting (pid: 61148)
[2021-02-19 17:13:21 +0000] [61146] [INFO] Handling signal: term
[2021-02-19 17:13:22 +0000] [61146] [INFO] Shutting down: Master
[2021-02-19 17:13:22 +0000] [61158] [INFO] Starting gunicorn 20.0.4
[2021-02-19 17:13:22 +0000] [61158] [INFO] Listening at: http://127.0.0.1:46710 (61158)
[2021-02-19 17:13:22 +0000] [61158] [INFO] Using worker: sync
[2021-02-19 17:13:22 +0000] [61160] [INFO] Booting worker with pid: 61160
[2021-02-19 17:13:52 +0000] [61160] [INFO] Worker exiting (pid: 61160)
[2021-02-19 17:13:52 +0000] [61158] [INFO] Handling signal: term
[2021-02-19 17:13:52 +0000] [61158] [INFO] Shutting down: Master
[2021-02-19 17:13:52 +0000] [61169] [INFO] Starting gunicorn 20.0.4
[2021-02-19 17:13:52 +0000] [61169] [INFO] Listening at: http://127.0.0.1:46710 (61169)
[2021-02-19 17:13:52 +0000] [61169] [INFO] Using worker: sync
[2021-02-19 17:13:52 +0000] [61171] [INFO] Booting worker with pid: 61171
[2021-02-19 17:14:24 +0000] [61171] [INFO] Worker exiting (pid: 61171)
[2021-02-19 17:14:24 +0000] [61169] [INFO] Handling signal: term
[2021-02-19 17:14:25 +0000] [61169] [INFO] Shutting down: Master
[2021-02-19 17:14:25 +0000] [61181] [INFO] Starting gunicorn 20.0.4
[2021-02-19 17:14:25 +0000] [61181] [INFO] Listening at: http://127.0.0.1:46710 (61181)
[2021-02-19 17:14:25 +0000] [61181] [INFO] Using worker: sync
[2021-02-19 17:14:25 +0000] [61183] [INFO] Booting worker with pid: 61183
Internal Server Error: /pdf/1/
Traceback (most recent call last):
  File "/home/vid/makereport/DTPreport/env/lib/python3.6/site-packages/django/core/handlers/exception.py", line 47, in inner
    response = get_response(request)
  File "/home/vid/makereport/DTPreport/env/lib/python3.6/site-packages/django/core/handlers/base.py", line 181, in _get_response
    response = wrapped_callback(request, *callback_args, **callback_kwargs)
  File "/home/vid/makereport/DTPreport/env/lib/python3.6/site-packages/django/views/generic/base.py", line 70, in view
    return self.dispatch(request, *args, **kwargs)
  File "/home/vid/makereport/DTPreport/env/lib/python3.6/site-packages/django/views/generic/base.py", line 98, in dispatch
    return handler(request, *args, **kwargs)
  File "/home/vid/makereport/DTPreport/pdf_report/views.py", line 185, in get
    pdf.generate(context)
  File "/home/vid/makereport/DTPreport/pdf_report/utils.py", line 600, in generate
    self.jinja2(context)
  File "/home/vid/makereport/DTPreport/pdf_report/utils.py", line 573, in jinja2
    self.xml = template.render(**context).encode('utf-8')
  File "/home/vid/makereport/DTPreport/env/lib/python3.6/site-packages/jinja2/environment.py", line 1090, in render
    self.environment.handle_exception()
  File "/home/vid/makereport/DTPreport/env/lib/python3.6/site-packages/jinja2/environment.py", line 832, in handle_exception
    reraise(*rewrite_traceback_stack(source=source))
  File "/home/vid/makereport/DTPreport/env/lib/python3.6/site-packages/jinja2/_compat.py", line 28, in reraise
    raise value.with_traceback(tb)
  File "templates/example.xml", line 884, in top-level template code
    {% for service in report.service_data %}
  File "/home/vid/makereport/DTPreport/env/lib/python3.6/site-packages/jinja2/runtime.py", line 403, in __init__
    self._iterator = self._to_iterator(iterable)
  File "/home/vid/makereport/DTPreport/env/lib/python3.6/site-packages/jinja2/runtime.py", line 411, in _to_iterator
    return iter(iterable)
TypeError: 'NoneType' object is not iterable
[2021-02-19 17:26:38 +0000] [61183] [INFO] Worker exiting (pid: 61183)
[2021-02-19 17:26:38 +0000] [61181] [INFO] Handling signal: term
[2021-02-19 17:26:38 +0000] [61181] [INFO] Shutting down: Master
[2021-02-19 17:26:39 +0000] [61432] [INFO] Starting gunicorn 20.0.4
[2021-02-19 17:26:39 +0000] [61432] [INFO] Listening at: http://127.0.0.1:46710 (61432)
[2021-02-19 17:26:39 +0000] [61432] [INFO] Using worker: sync
[2021-02-19 17:26:39 +0000] [61434] [INFO] Booting worker with pid: 61434
Internal Server Error: /pdf/4/
Traceback (most recent call last):
  File "/home/vid/makereport/DTPreport/env/lib/python3.6/site-packages/django/db/backends/utils.py", line 84, in _execute
    return self.cursor.execute(sql, params)
  File "/home/vid/makereport/DTPreport/env/lib/python3.6/site-packages/django/db/backends/sqlite3/base.py", line 413, in execute
    return Database.Cursor.execute(self, query, params)
sqlite3.OperationalError: no such column: makereport_report.service_cost

The above exception was the direct cause of the following exception:

Traceback (most recent call last):
  File "/home/vid/makereport/DTPreport/env/lib/python3.6/site-packages/django/core/handlers/exception.py", line 47, in inner
    response = get_response(request)
  File "/home/vid/makereport/DTPreport/env/lib/python3.6/site-packages/django/core/handlers/base.py", line 181, in _get_response
    response = wrapped_callback(request, *callback_args, **callback_kwargs)
  File "/home/vid/makereport/DTPreport/env/lib/python3.6/site-packages/django/views/generic/base.py", line 70, in view
    return self.dispatch(request, *args, **kwargs)
  File "/home/vid/makereport/DTPreport/env/lib/python3.6/site-packages/django/views/generic/base.py", line 98, in dispatch
    return handler(request, *args, **kwargs)
  File "/home/vid/makereport/DTPreport/pdf_report/views.py", line 178, in get
    new_report_pdf = Report.objects.get(report_id=id)
  File "/home/vid/makereport/DTPreport/env/lib/python3.6/site-packages/django/db/models/manager.py", line 85, in manager_method
    return getattr(self.get_queryset(), name)(*args, **kwargs)
  File "/home/vid/makereport/DTPreport/env/lib/python3.6/site-packages/django/db/models/query.py", line 425, in get
    num = len(clone)
  File "/home/vid/makereport/DTPreport/env/lib/python3.6/site-packages/django/db/models/query.py", line 269, in __len__
    self._fetch_all()
  File "/home/vid/makereport/DTPreport/env/lib/python3.6/site-packages/django/db/models/query.py", line 1308, in _fetch_all
    self._result_cache = list(self._iterable_class(self))
  File "/home/vid/makereport/DTPreport/env/lib/python3.6/site-packages/django/db/models/query.py", line 53, in __iter__
    results = compiler.execute_sql(chunked_fetch=self.chunked_fetch, chunk_size=self.chunk_size)
  File "/home/vid/makereport/DTPreport/env/lib/python3.6/site-packages/django/db/models/sql/compiler.py", line 1156, in execute_sql
    cursor.execute(sql, params)
  File "/home/vid/makereport/DTPreport/env/lib/python3.6/site-packages/django/db/backends/utils.py", line 98, in execute
    return super().execute(sql, params)
  File "/home/vid/makereport/DTPreport/env/lib/python3.6/site-packages/django/db/backends/utils.py", line 66, in execute
    return self._execute_with_wrappers(sql, params, many=False, executor=self._execute)
  File "/home/vid/makereport/DTPreport/env/lib/python3.6/site-packages/django/db/backends/utils.py", line 75, in _execute_with_wrappers
    return executor(sql, params, many, context)
  File "/home/vid/makereport/DTPreport/env/lib/python3.6/site-packages/django/db/backends/utils.py", line 84, in _execute
    return self.cursor.execute(sql, params)
  File "/home/vid/makereport/DTPreport/env/lib/python3.6/site-packages/django/db/utils.py", line 90, in __exit__
    raise dj_exc_value.with_traceback(traceback) from exc_value
  File "/home/vid/makereport/DTPreport/env/lib/python3.6/site-packages/django/db/backends/utils.py", line 84, in _execute
    return self.cursor.execute(sql, params)
  File "/home/vid/makereport/DTPreport/env/lib/python3.6/site-packages/django/db/backends/sqlite3/base.py", line 413, in execute
    return Database.Cursor.execute(self, query, params)
django.db.utils.OperationalError: no such column: makereport_report.service_cost
Internal Server Error: /pdf/4/
Traceback (most recent call last):
  File "/home/vid/makereport/DTPreport/env/lib/python3.6/site-packages/django/db/backends/utils.py", line 84, in _execute
    return self.cursor.execute(sql, params)
  File "/home/vid/makereport/DTPreport/env/lib/python3.6/site-packages/django/db/backends/sqlite3/base.py", line 413, in execute
    return Database.Cursor.execute(self, query, params)
sqlite3.OperationalError: no such column: makereport_report.key

The above exception was the direct cause of the following exception:

Traceback (most recent call last):
  File "/home/vid/makereport/DTPreport/env/lib/python3.6/site-packages/django/core/handlers/exception.py", line 47, in inner
    response = get_response(request)
  File "/home/vid/makereport/DTPreport/env/lib/python3.6/site-packages/django/core/handlers/base.py", line 181, in _get_response
    response = wrapped_callback(request, *callback_args, **callback_kwargs)
  File "/home/vid/makereport/DTPreport/env/lib/python3.6/site-packages/django/views/generic/base.py", line 70, in view
    return self.dispatch(request, *args, **kwargs)
  File "/home/vid/makereport/DTPreport/env/lib/python3.6/site-packages/django/views/generic/base.py", line 98, in dispatch
    return handler(request, *args, **kwargs)
  File "/home/vid/makereport/DTPreport/pdf_report/views.py", line 178, in get
    new_report_pdf = Report.objects.get(report_id=id)
  File "/home/vid/makereport/DTPreport/env/lib/python3.6/site-packages/django/db/models/manager.py", line 85, in manager_method
    return getattr(self.get_queryset(), name)(*args, **kwargs)
  File "/home/vid/makereport/DTPreport/env/lib/python3.6/site-packages/django/db/models/query.py", line 425, in get
    num = len(clone)
  File "/home/vid/makereport/DTPreport/env/lib/python3.6/site-packages/django/db/models/query.py", line 269, in __len__
    self._fetch_all()
  File "/home/vid/makereport/DTPreport/env/lib/python3.6/site-packages/django/db/models/query.py", line 1308, in _fetch_all
    self._result_cache = list(self._iterable_class(self))
  File "/home/vid/makereport/DTPreport/env/lib/python3.6/site-packages/django/db/models/query.py", line 53, in __iter__
    results = compiler.execute_sql(chunked_fetch=self.chunked_fetch, chunk_size=self.chunk_size)
  File "/home/vid/makereport/DTPreport/env/lib/python3.6/site-packages/django/db/models/sql/compiler.py", line 1156, in execute_sql
    cursor.execute(sql, params)
  File "/home/vid/makereport/DTPreport/env/lib/python3.6/site-packages/django/db/backends/utils.py", line 98, in execute
    return super().execute(sql, params)
  File "/home/vid/makereport/DTPreport/env/lib/python3.6/site-packages/django/db/backends/utils.py", line 66, in execute
    return self._execute_with_wrappers(sql, params, many=False, executor=self._execute)
  File "/home/vid/makereport/DTPreport/env/lib/python3.6/site-packages/django/db/backends/utils.py", line 75, in _execute_with_wrappers
    return executor(sql, params, many, context)
  File "/home/vid/makereport/DTPreport/env/lib/python3.6/site-packages/django/db/backends/utils.py", line 84, in _execute
    return self.cursor.execute(sql, params)
  File "/home/vid/makereport/DTPreport/env/lib/python3.6/site-packages/django/db/utils.py", line 90, in __exit__
    raise dj_exc_value.with_traceback(traceback) from exc_value
  File "/home/vid/makereport/DTPreport/env/lib/python3.6/site-packages/django/db/backends/utils.py", line 84, in _execute
    return self.cursor.execute(sql, params)
  File "/home/vid/makereport/DTPreport/env/lib/python3.6/site-packages/django/db/backends/sqlite3/base.py", line 413, in execute
    return Database.Cursor.execute(self, query, params)
django.db.utils.OperationalError: no such column: makereport_report.key
[2021-02-19 17:29:11 +0000] [61432] [INFO] Handling signal: term
[2021-02-19 17:29:11 +0000] [61434] [INFO] Worker exiting (pid: 61434)
[2021-02-19 17:29:12 +0000] [61432] [INFO] Shutting down: Master
[2021-02-19 17:29:12 +0000] [61486] [INFO] Starting gunicorn 20.0.4
[2021-02-19 17:29:12 +0000] [61486] [INFO] Listening at: http://127.0.0.1:46710 (61486)
[2021-02-19 17:29:12 +0000] [61486] [INFO] Using worker: sync
[2021-02-19 17:29:12 +0000] [61488] [INFO] Booting worker with pid: 61488
Internal Server Error: /pdf/4/
Traceback (most recent call last):
  File "/home/vid/makereport/DTPreport/env/lib/python3.6/site-packages/django/db/backends/utils.py", line 84, in _execute
    return self.cursor.execute(sql, params)
  File "/home/vid/makereport/DTPreport/env/lib/python3.6/site-packages/django/db/backends/sqlite3/base.py", line 413, in execute
    return Database.Cursor.execute(self, query, params)
sqlite3.OperationalError: no such column: makereport_report.key

The above exception was the direct cause of the following exception:

Traceback (most recent call last):
  File "/home/vid/makereport/DTPreport/env/lib/python3.6/site-packages/django/core/handlers/exception.py", line 47, in inner
    response = get_response(request)
  File "/home/vid/makereport/DTPreport/env/lib/python3.6/site-packages/django/core/handlers/base.py", line 181, in _get_response
    response = wrapped_callback(request, *callback_args, **callback_kwargs)
  File "/home/vid/makereport/DTPreport/env/lib/python3.6/site-packages/django/views/generic/base.py", line 70, in view
    return self.dispatch(request, *args, **kwargs)
  File "/home/vid/makereport/DTPreport/env/lib/python3.6/site-packages/django/views/generic/base.py", line 98, in dispatch
    return handler(request, *args, **kwargs)
  File "/home/vid/makereport/DTPreport/pdf_report/views.py", line 178, in get
    new_report_pdf = Report.objects.get(report_id=id)
  File "/home/vid/makereport/DTPreport/env/lib/python3.6/site-packages/django/db/models/manager.py", line 85, in manager_method
    return getattr(self.get_queryset(), name)(*args, **kwargs)
  File "/home/vid/makereport/DTPreport/env/lib/python3.6/site-packages/django/db/models/query.py", line 425, in get
    num = len(clone)
  File "/home/vid/makereport/DTPreport/env/lib/python3.6/site-packages/django/db/models/query.py", line 269, in __len__
    self._fetch_all()
  File "/home/vid/makereport/DTPreport/env/lib/python3.6/site-packages/django/db/models/query.py", line 1308, in _fetch_all
    self._result_cache = list(self._iterable_class(self))
  File "/home/vid/makereport/DTPreport/env/lib/python3.6/site-packages/django/db/models/query.py", line 53, in __iter__
    results = compiler.execute_sql(chunked_fetch=self.chunked_fetch, chunk_size=self.chunk_size)
  File "/home/vid/makereport/DTPreport/env/lib/python3.6/site-packages/django/db/models/sql/compiler.py", line 1156, in execute_sql
    cursor.execute(sql, params)
  File "/home/vid/makereport/DTPreport/env/lib/python3.6/site-packages/django/db/backends/utils.py", line 98, in execute
    return super().execute(sql, params)
  File "/home/vid/makereport/DTPreport/env/lib/python3.6/site-packages/django/db/backends/utils.py", line 66, in execute
    return self._execute_with_wrappers(sql, params, many=False, executor=self._execute)
  File "/home/vid/makereport/DTPreport/env/lib/python3.6/site-packages/django/db/backends/utils.py", line 75, in _execute_with_wrappers
    return executor(sql, params, many, context)
  File "/home/vid/makereport/DTPreport/env/lib/python3.6/site-packages/django/db/backends/utils.py", line 84, in _execute
    return self.cursor.execute(sql, params)
  File "/home/vid/makereport/DTPreport/env/lib/python3.6/site-packages/django/db/utils.py", line 90, in __exit__
    raise dj_exc_value.with_traceback(traceback) from exc_value
  File "/home/vid/makereport/DTPreport/env/lib/python3.6/site-packages/django/db/backends/utils.py", line 84, in _execute
    return self.cursor.execute(sql, params)
  File "/home/vid/makereport/DTPreport/env/lib/python3.6/site-packages/django/db/backends/sqlite3/base.py", line 413, in execute
    return Database.Cursor.execute(self, query, params)
django.db.utils.OperationalError: no such column: makereport_report.key
[2021-02-19 17:30:08 +0000] [61488] [INFO] Worker exiting (pid: 61488)
[2021-02-19 17:30:08 +0000] [61486] [INFO] Handling signal: term
[2021-02-19 17:30:08 +0000] [61486] [INFO] Shutting down: Master
[2021-02-19 17:30:08 +0000] [61500] [INFO] Starting gunicorn 20.0.4
[2021-02-19 17:30:08 +0000] [61500] [INFO] Listening at: http://127.0.0.1:46710 (61500)
[2021-02-19 17:30:08 +0000] [61500] [INFO] Using worker: sync
[2021-02-19 17:30:08 +0000] [61502] [INFO] Booting worker with pid: 61502
[2021-02-19 17:32:13 +0000] [61502] [INFO] Worker exiting (pid: 61502)
[2021-02-19 17:32:13 +0000] [61500] [INFO] Handling signal: term
[2021-02-19 17:32:13 +0000] [61500] [INFO] Shutting down: Master
[2021-02-19 17:32:13 +0000] [61534] [INFO] Starting gunicorn 20.0.4
[2021-02-19 17:32:13 +0000] [61534] [INFO] Listening at: http://127.0.0.1:46710 (61534)
[2021-02-19 17:32:13 +0000] [61534] [INFO] Using worker: sync
[2021-02-19 17:32:13 +0000] [61536] [INFO] Booting worker with pid: 61536
[2021-02-19 17:34:10 +0000] [61536] [INFO] Worker exiting (pid: 61536)
[2021-02-19 17:34:10 +0000] [61534] [INFO] Handling signal: term
[2021-02-19 17:34:11 +0000] [61534] [INFO] Shutting down: Master
[2021-02-19 17:34:11 +0000] [61569] [INFO] Starting gunicorn 20.0.4
[2021-02-19 17:34:11 +0000] [61569] [INFO] Listening at: http://127.0.0.1:46710 (61569)
[2021-02-19 17:34:11 +0000] [61569] [INFO] Using worker: sync
[2021-02-19 17:34:11 +0000] [61571] [INFO] Booting worker with pid: 61571
Invalid HTTP_HOST header: '185.196.214.176'. You may need to add '185.196.214.176' to ALLOWED_HOSTS.
Bad Request: /
Invalid HTTP_HOST header: '185.196.214.176'. You may need to add '185.196.214.176' to ALLOWED_HOSTS.
Bad Request: /
Invalid HTTP_HOST header: '185.196.214.176'. You may need to add '185.196.214.176' to ALLOWED_HOSTS.
Bad Request: /
Not Found: /robots.txt
Internal Server Error: /pdf/1/
Traceback (most recent call last):
  File "/home/vid/makereport/DTPreport/env/lib/python3.6/site-packages/django/core/handlers/exception.py", line 47, in inner
    response = get_response(request)
  File "/home/vid/makereport/DTPreport/env/lib/python3.6/site-packages/django/core/handlers/base.py", line 181, in _get_response
    response = wrapped_callback(request, *callback_args, **callback_kwargs)
  File "/home/vid/makereport/DTPreport/env/lib/python3.6/site-packages/django/views/generic/base.py", line 70, in view
    return self.dispatch(request, *args, **kwargs)
  File "/home/vid/makereport/DTPreport/env/lib/python3.6/site-packages/django/views/generic/base.py", line 98, in dispatch
    return handler(request, *args, **kwargs)
  File "/home/vid/makereport/DTPreport/pdf_report/views.py", line 185, in get
    pdf.generate(context)
  File "/home/vid/makereport/DTPreport/pdf_report/utils.py", line 600, in generate
    self.jinja2(context)
  File "/home/vid/makereport/DTPreport/pdf_report/utils.py", line 573, in jinja2
    self.xml = template.render(**context).encode('utf-8')
  File "/home/vid/makereport/DTPreport/env/lib/python3.6/site-packages/jinja2/environment.py", line 1090, in render
    self.environment.handle_exception()
  File "/home/vid/makereport/DTPreport/env/lib/python3.6/site-packages/jinja2/environment.py", line 832, in handle_exception
    reraise(*rewrite_traceback_stack(source=source))
  File "/home/vid/makereport/DTPreport/env/lib/python3.6/site-packages/jinja2/_compat.py", line 28, in reraise
    raise value.with_traceback(tb)
  File "templates/example.xml", line 690, in top-level template code
    Ки,физ =(0,208 - 0,003 * {{ report.wear_data.__getitem__('point') }}) * {{ report.wear_data.__getitem__('weight') }} ^ 0.7 = {{ report.wear_data.__getitem__('wear') }}%
jinja2.exceptions.UndefinedError: 'None' has no attribute '__getitem__'
Not Found: /accounts/login/
Internal Server Error: /pdf/1/
Traceback (most recent call last):
  File "/home/vid/makereport/DTPreport/env/lib/python3.6/site-packages/django/core/handlers/exception.py", line 47, in inner
    response = get_response(request)
  File "/home/vid/makereport/DTPreport/env/lib/python3.6/site-packages/django/core/handlers/base.py", line 181, in _get_response
    response = wrapped_callback(request, *callback_args, **callback_kwargs)
  File "/home/vid/makereport/DTPreport/env/lib/python3.6/site-packages/django/views/generic/base.py", line 70, in view
    return self.dispatch(request, *args, **kwargs)
  File "/home/vid/makereport/DTPreport/env/lib/python3.6/site-packages/django/views/generic/base.py", line 98, in dispatch
    return handler(request, *args, **kwargs)
  File "/home/vid/makereport/DTPreport/pdf_report/views.py", line 185, in get
    pdf.generate(context)
  File "/home/vid/makereport/DTPreport/pdf_report/utils.py", line 600, in generate
    self.jinja2(context)
  File "/home/vid/makereport/DTPreport/pdf_report/utils.py", line 573, in jinja2
    self.xml = template.render(**context).encode('utf-8')
  File "/home/vid/makereport/DTPreport/env/lib/python3.6/site-packages/jinja2/environment.py", line 1090, in render
    self.environment.handle_exception()
  File "/home/vid/makereport/DTPreport/env/lib/python3.6/site-packages/jinja2/environment.py", line 832, in handle_exception
    reraise(*rewrite_traceback_stack(source=source))
  File "/home/vid/makereport/DTPreport/env/lib/python3.6/site-packages/jinja2/_compat.py", line 28, in reraise
    raise value.with_traceback(tb)
  File "templates/example.xml", line 690, in top-level template code
    Ки,физ =(0,208 - 0,003 * {{ report.wear_data.__getitem__('point') }}) * {{ report.wear_data.__getitem__('weight') }} ^ 0.7 = {{ report.wear_data.__getitem__('wear') }}%
jinja2.exceptions.UndefinedError: 'None' has no attribute '__getitem__'
Invalid HTTP_HOST header: '185.196.214.176'. You may need to add '185.196.214.176' to ALLOWED_HOSTS.
Bad Request: /
Invalid HTTP_HOST header: '185.196.214.176'. You may need to add '185.196.214.176' to ALLOWED_HOSTS.
Bad Request: /
Invalid HTTP_HOST header: '185.196.214.176'. You may need to add '185.196.214.176' to ALLOWED_HOSTS.
Bad Request: /admin//config.php
Invalid HTTP_HOST header: '185.196.214.176'. You may need to add '185.196.214.176' to ALLOWED_HOSTS.
Bad Request: /tmui/login.jsp/..;/tmui/locallb/workspace/fileRead.jsp
Not Found: /favicon.ico
Invalid HTTP_HOST header: '185.196.214.176'. You may need to add '185.196.214.176' to ALLOWED_HOSTS.
Bad Request: /
Invalid HTTP_HOST header: '185.196.214.176'. You may need to add '185.196.214.176' to ALLOWED_HOSTS.
Bad Request: /
Not Found: /favicon.ico
Not Found: /favicon.ico
Not Found: /favicon.ico
Not Found: /favicon.ico
Not Found: /favicon.ico
Not Found: /robots.txt
Invalid HTTP_HOST header: '185.196.214.176'. You may need to add '185.196.214.176' to ALLOWED_HOSTS.
Bad Request: /
[2021-02-20 09:41:42 +0000] [61571] [INFO] Worker exiting (pid: 61571)
[2021-02-20 09:41:42 +0000] [61569] [INFO] Handling signal: term
[2021-02-20 09:41:43 +0000] [61569] [INFO] Shutting down: Master
[2021-02-20 09:41:43 +0000] [71736] [INFO] Starting gunicorn 20.0.4
[2021-02-20 09:41:43 +0000] [71736] [INFO] Listening at: http://127.0.0.1:46710 (71736)
[2021-02-20 09:41:43 +0000] [71736] [INFO] Using worker: sync
[2021-02-20 09:41:43 +0000] [71738] [INFO] Booting worker with pid: 71738
/home/vid/makereport/DTPreport/env/lib/python3.6/site-packages/django/db/models/fields/__init__.py:1312: RuntimeWarning: DateTimeField Report.created_at received a naive datetime (2021-02-19 00:00:00) while time zone support is active.
  RuntimeWarning)
Internal Server Error: /pdf/1/
Traceback (most recent call last):
  File "/home/vid/makereport/DTPreport/env/lib/python3.6/site-packages/django/core/handlers/exception.py", line 47, in inner
    response = get_response(request)
  File "/home/vid/makereport/DTPreport/env/lib/python3.6/site-packages/django/core/handlers/base.py", line 181, in _get_response
    response = wrapped_callback(request, *callback_args, **callback_kwargs)
  File "/home/vid/makereport/DTPreport/env/lib/python3.6/site-packages/django/views/generic/base.py", line 70, in view
    return self.dispatch(request, *args, **kwargs)
  File "/home/vid/makereport/DTPreport/env/lib/python3.6/site-packages/django/views/generic/base.py", line 98, in dispatch
    return handler(request, *args, **kwargs)
  File "/home/vid/makereport/DTPreport/pdf_report/views.py", line 185, in get
    pdf.generate(context)
  File "/home/vid/makereport/DTPreport/pdf_report/utils.py", line 600, in generate
    self.jinja2(context)
  File "/home/vid/makereport/DTPreport/pdf_report/utils.py", line 573, in jinja2
    self.xml = template.render(**context).encode('utf-8')
  File "/home/vid/makereport/DTPreport/env/lib/python3.6/site-packages/jinja2/environment.py", line 1090, in render
    self.environment.handle_exception()
  File "/home/vid/makereport/DTPreport/env/lib/python3.6/site-packages/jinja2/environment.py", line 832, in handle_exception
    reraise(*rewrite_traceback_stack(source=source))
  File "/home/vid/makereport/DTPreport/env/lib/python3.6/site-packages/jinja2/_compat.py", line 28, in reraise
    raise value.with_traceback(tb)
  File "templates/example.xml", line 690, in top-level template code
    Ки,физ =(0,208 - 0,003 * {{ report.wear_data.__getitem__('point') }}) * {{ report.wear_data.__getitem__('weight') }} ^ 0.7 = {{ report.wear_data.__getitem__('wear') }}%
jinja2.exceptions.UndefinedError: 'None' has no attribute '__getitem__'
Internal Server Error: /pdf/3/
Traceback (most recent call last):
  File "/home/vid/makereport/DTPreport/env/lib/python3.6/site-packages/django/core/handlers/exception.py", line 47, in inner
    response = get_response(request)
  File "/home/vid/makereport/DTPreport/env/lib/python3.6/site-packages/django/core/handlers/base.py", line 181, in _get_response
    response = wrapped_callback(request, *callback_args, **callback_kwargs)
  File "/home/vid/makereport/DTPreport/env/lib/python3.6/site-packages/django/views/generic/base.py", line 70, in view
    return self.dispatch(request, *args, **kwargs)
  File "/home/vid/makereport/DTPreport/env/lib/python3.6/site-packages/django/views/generic/base.py", line 98, in dispatch
    return handler(request, *args, **kwargs)
  File "/home/vid/makereport/DTPreport/pdf_report/views.py", line 185, in get
    pdf.generate(context)
  File "/home/vid/makereport/DTPreport/pdf_report/utils.py", line 600, in generate
    self.jinja2(context)
  File "/home/vid/makereport/DTPreport/pdf_report/utils.py", line 573, in jinja2
    self.xml = template.render(**context).encode('utf-8')
  File "/home/vid/makereport/DTPreport/env/lib/python3.6/site-packages/jinja2/environment.py", line 1090, in render
    self.environment.handle_exception()
  File "/home/vid/makereport/DTPreport/env/lib/python3.6/site-packages/jinja2/environment.py", line 832, in handle_exception
    reraise(*rewrite_traceback_stack(source=source))
  File "/home/vid/makereport/DTPreport/env/lib/python3.6/site-packages/jinja2/_compat.py", line 28, in reraise
    raise value.with_traceback(tb)
  File "templates/example.xml", line 690, in top-level template code
    Ки,физ =(0,208 - 0,003 * {{ report.wear_data.__getitem__('point') }}) * {{ report.wear_data.__getitem__('weight') }} ^ 0.7 = {{ report.wear_data.__getitem__('wear') }}%
jinja2.exceptions.UndefinedError: 'None' has no attribute '__getitem__'
Not Found: /robots.txt
Not Found: /accounts/login/
Not Found: /favicon.ico
Not Found: /report/create/generic.html
Internal Server Error: /pdf/1/
Traceback (most recent call last):
  File "/home/vid/makereport/DTPreport/env/lib/python3.6/site-packages/django/core/handlers/exception.py", line 47, in inner
    response = get_response(request)
  File "/home/vid/makereport/DTPreport/env/lib/python3.6/site-packages/django/core/handlers/base.py", line 181, in _get_response
    response = wrapped_callback(request, *callback_args, **callback_kwargs)
  File "/home/vid/makereport/DTPreport/env/lib/python3.6/site-packages/django/views/generic/base.py", line 70, in view
    return self.dispatch(request, *args, **kwargs)
  File "/home/vid/makereport/DTPreport/env/lib/python3.6/site-packages/django/views/generic/base.py", line 98, in dispatch
    return handler(request, *args, **kwargs)
  File "/home/vid/makereport/DTPreport/pdf_report/views.py", line 185, in get
    pdf.generate(context)
  File "/home/vid/makereport/DTPreport/pdf_report/utils.py", line 600, in generate
    self.jinja2(context)
  File "/home/vid/makereport/DTPreport/pdf_report/utils.py", line 573, in jinja2
    self.xml = template.render(**context).encode('utf-8')
  File "/home/vid/makereport/DTPreport/env/lib/python3.6/site-packages/jinja2/environment.py", line 1090, in render
    self.environment.handle_exception()
  File "/home/vid/makereport/DTPreport/env/lib/python3.6/site-packages/jinja2/environment.py", line 832, in handle_exception
    reraise(*rewrite_traceback_stack(source=source))
  File "/home/vid/makereport/DTPreport/env/lib/python3.6/site-packages/jinja2/_compat.py", line 28, in reraise
    raise value.with_traceback(tb)
  File "templates/example.xml", line 690, in top-level template code
    Ки,физ =(0,208 - 0,003 * {{ report.wear_data.__getitem__('point') }}) * {{ report.wear_data.__getitem__('weight') }} ^ 0.7 = {{ report.wear_data.__getitem__('wear') }}%
jinja2.exceptions.UndefinedError: 'None' has no attribute '__getitem__'
Internal Server Error: /pdf/1/
Traceback (most recent call last):
  File "/home/vid/makereport/DTPreport/env/lib/python3.6/site-packages/django/core/handlers/exception.py", line 47, in inner
    response = get_response(request)
  File "/home/vid/makereport/DTPreport/env/lib/python3.6/site-packages/django/core/handlers/base.py", line 181, in _get_response
    response = wrapped_callback(request, *callback_args, **callback_kwargs)
  File "/home/vid/makereport/DTPreport/env/lib/python3.6/site-packages/django/views/generic/base.py", line 70, in view
    return self.dispatch(request, *args, **kwargs)
  File "/home/vid/makereport/DTPreport/env/lib/python3.6/site-packages/django/views/generic/base.py", line 98, in dispatch
    return handler(request, *args, **kwargs)
  File "/home/vid/makereport/DTPreport/pdf_report/views.py", line 185, in get
    pdf.generate(context)
  File "/home/vid/makereport/DTPreport/pdf_report/utils.py", line 600, in generate
    self.jinja2(context)
  File "/home/vid/makereport/DTPreport/pdf_report/utils.py", line 573, in jinja2
    self.xml = template.render(**context).encode('utf-8')
  File "/home/vid/makereport/DTPreport/env/lib/python3.6/site-packages/jinja2/environment.py", line 1090, in render
    self.environment.handle_exception()
  File "/home/vid/makereport/DTPreport/env/lib/python3.6/site-packages/jinja2/environment.py", line 832, in handle_exception
    reraise(*rewrite_traceback_stack(source=source))
  File "/home/vid/makereport/DTPreport/env/lib/python3.6/site-packages/jinja2/_compat.py", line 28, in reraise
    raise value.with_traceback(tb)
  File "templates/example.xml", line 690, in top-level template code
    Ки,физ =(0,208 - 0,003 * {{ report.wear_data.__getitem__('point') }}) * {{ report.wear_data.__getitem__('weight') }} ^ 0.7 = {{ report.wear_data.__getitem__('wear') }}%
jinja2.exceptions.UndefinedError: 'None' has no attribute '__getitem__'
Not Found: /accounts/login/
Invalid HTTP_HOST header: '185.196.214.176'. You may need to add '185.196.214.176' to ALLOWED_HOSTS.
Bad Request: /
Invalid HTTP_HOST header: '185.196.214.176'. You may need to add '185.196.214.176' to ALLOWED_HOSTS.
Bad Request: /
Internal Server Error: /pdf/2/
Traceback (most recent call last):
  File "/home/vid/makereport/DTPreport/env/lib/python3.6/site-packages/django/core/handlers/exception.py", line 47, in inner
    response = get_response(request)
  File "/home/vid/makereport/DTPreport/env/lib/python3.6/site-packages/django/core/handlers/base.py", line 181, in _get_response
    response = wrapped_callback(request, *callback_args, **callback_kwargs)
  File "/home/vid/makereport/DTPreport/env/lib/python3.6/site-packages/django/views/generic/base.py", line 70, in view
    return self.dispatch(request, *args, **kwargs)
  File "/home/vid/makereport/DTPreport/env/lib/python3.6/site-packages/django/views/generic/base.py", line 98, in dispatch
    return handler(request, *args, **kwargs)
  File "/home/vid/makereport/DTPreport/pdf_report/views.py", line 185, in get
    pdf.generate(context)
  File "/home/vid/makereport/DTPreport/pdf_report/utils.py", line 600, in generate
    self.jinja2(context)
  File "/home/vid/makereport/DTPreport/pdf_report/utils.py", line 573, in jinja2
    self.xml = template.render(**context).encode('utf-8')
  File "/home/vid/makereport/DTPreport/env/lib/python3.6/site-packages/jinja2/environment.py", line 1090, in render
    self.environment.handle_exception()
  File "/home/vid/makereport/DTPreport/env/lib/python3.6/site-packages/jinja2/environment.py", line 832, in handle_exception
    reraise(*rewrite_traceback_stack(source=source))
  File "/home/vid/makereport/DTPreport/env/lib/python3.6/site-packages/jinja2/_compat.py", line 28, in reraise
    raise value.with_traceback(tb)
  File "templates/example.xml", line 690, in top-level template code
    Ки,физ =(0,208 - 0,003 * {{ report.wear_data.__getitem__('point') }}) * {{ report.wear_data.__getitem__('weight') }} ^ 0.7 = {{ report.wear_data.__getitem__('wear') }}%
jinja2.exceptions.UndefinedError: 'None' has no attribute '__getitem__'
Not Found: /robots.txt
Internal Server Error: /pdf/1/
Traceback (most recent call last):
  File "/home/vid/makereport/DTPreport/env/lib/python3.6/site-packages/django/core/handlers/exception.py", line 47, in inner
    response = get_response(request)
  File "/home/vid/makereport/DTPreport/env/lib/python3.6/site-packages/django/core/handlers/base.py", line 181, in _get_response
    response = wrapped_callback(request, *callback_args, **callback_kwargs)
  File "/home/vid/makereport/DTPreport/env/lib/python3.6/site-packages/django/views/generic/base.py", line 70, in view
    return self.dispatch(request, *args, **kwargs)
  File "/home/vid/makereport/DTPreport/env/lib/python3.6/site-packages/django/views/generic/base.py", line 98, in dispatch
    return handler(request, *args, **kwargs)
  File "/home/vid/makereport/DTPreport/pdf_report/views.py", line 185, in get
    pdf.generate(context)
  File "/home/vid/makereport/DTPreport/pdf_report/utils.py", line 600, in generate
    self.jinja2(context)
  File "/home/vid/makereport/DTPreport/pdf_report/utils.py", line 573, in jinja2
    self.xml = template.render(**context).encode('utf-8')
  File "/home/vid/makereport/DTPreport/env/lib/python3.6/site-packages/jinja2/environment.py", line 1090, in render
    self.environment.handle_exception()
  File "/home/vid/makereport/DTPreport/env/lib/python3.6/site-packages/jinja2/environment.py", line 832, in handle_exception
    reraise(*rewrite_traceback_stack(source=source))
  File "/home/vid/makereport/DTPreport/env/lib/python3.6/site-packages/jinja2/_compat.py", line 28, in reraise
    raise value.with_traceback(tb)
  File "templates/example.xml", line 690, in top-level template code
    Ки,физ =(0,208 - 0,003 * {{ report.wear_data.__getitem__('point') }}) * {{ report.wear_data.__getitem__('weight') }} ^ 0.7 = {{ report.wear_data.__getitem__('wear') }}%
jinja2.exceptions.UndefinedError: 'None' has no attribute '__getitem__'
Internal Server Error: /pdf/2/
Traceback (most recent call last):
  File "/home/vid/makereport/DTPreport/env/lib/python3.6/site-packages/django/core/handlers/exception.py", line 47, in inner
    response = get_response(request)
  File "/home/vid/makereport/DTPreport/env/lib/python3.6/site-packages/django/core/handlers/base.py", line 181, in _get_response
    response = wrapped_callback(request, *callback_args, **callback_kwargs)
  File "/home/vid/makereport/DTPreport/env/lib/python3.6/site-packages/django/views/generic/base.py", line 70, in view
    return self.dispatch(request, *args, **kwargs)
  File "/home/vid/makereport/DTPreport/env/lib/python3.6/site-packages/django/views/generic/base.py", line 98, in dispatch
    return handler(request, *args, **kwargs)
  File "/home/vid/makereport/DTPreport/pdf_report/views.py", line 185, in get
    pdf.generate(context)
  File "/home/vid/makereport/DTPreport/pdf_report/utils.py", line 600, in generate
    self.jinja2(context)
  File "/home/vid/makereport/DTPreport/pdf_report/utils.py", line 573, in jinja2
    self.xml = template.render(**context).encode('utf-8')
  File "/home/vid/makereport/DTPreport/env/lib/python3.6/site-packages/jinja2/environment.py", line 1090, in render
    self.environment.handle_exception()
  File "/home/vid/makereport/DTPreport/env/lib/python3.6/site-packages/jinja2/environment.py", line 832, in handle_exception
    reraise(*rewrite_traceback_stack(source=source))
  File "/home/vid/makereport/DTPreport/env/lib/python3.6/site-packages/jinja2/_compat.py", line 28, in reraise
    raise value.with_traceback(tb)
  File "templates/example.xml", line 690, in top-level template code
    Ки,физ =(0,208 - 0,003 * {{ report.wear_data.__getitem__('point') }}) * {{ report.wear_data.__getitem__('weight') }} ^ 0.7 = {{ report.wear_data.__getitem__('wear') }}%
jinja2.exceptions.UndefinedError: 'None' has no attribute '__getitem__'
Internal Server Error: /pdf/1/
Traceback (most recent call last):
  File "/home/vid/makereport/DTPreport/env/lib/python3.6/site-packages/django/core/handlers/exception.py", line 47, in inner
    response = get_response(request)
  File "/home/vid/makereport/DTPreport/env/lib/python3.6/site-packages/django/core/handlers/base.py", line 181, in _get_response
    response = wrapped_callback(request, *callback_args, **callback_kwargs)
  File "/home/vid/makereport/DTPreport/env/lib/python3.6/site-packages/django/views/generic/base.py", line 70, in view
    return self.dispatch(request, *args, **kwargs)
  File "/home/vid/makereport/DTPreport/env/lib/python3.6/site-packages/django/views/generic/base.py", line 98, in dispatch
    return handler(request, *args, **kwargs)
  File "/home/vid/makereport/DTPreport/pdf_report/views.py", line 185, in get
    pdf.generate(context)
  File "/home/vid/makereport/DTPreport/pdf_report/utils.py", line 600, in generate
    self.jinja2(context)
  File "/home/vid/makereport/DTPreport/pdf_report/utils.py", line 573, in jinja2
    self.xml = template.render(**context).encode('utf-8')
  File "/home/vid/makereport/DTPreport/env/lib/python3.6/site-packages/jinja2/environment.py", line 1090, in render
    self.environment.handle_exception()
  File "/home/vid/makereport/DTPreport/env/lib/python3.6/site-packages/jinja2/environment.py", line 832, in handle_exception
    reraise(*rewrite_traceback_stack(source=source))
  File "/home/vid/makereport/DTPreport/env/lib/python3.6/site-packages/jinja2/_compat.py", line 28, in reraise
    raise value.with_traceback(tb)
  File "templates/example.xml", line 690, in top-level template code
    Ки,физ =(0,208 - 0,003 * {{ report.wear_data.__getitem__('point') }}) * {{ report.wear_data.__getitem__('weight') }} ^ 0.7 = {{ report.wear_data.__getitem__('wear') }}%
jinja2.exceptions.UndefinedError: 'None' has no attribute '__getitem__'
Internal Server Error: /pdf/2/
Traceback (most recent call last):
  File "/home/vid/makereport/DTPreport/env/lib/python3.6/site-packages/django/core/handlers/exception.py", line 47, in inner
    response = get_response(request)
  File "/home/vid/makereport/DTPreport/env/lib/python3.6/site-packages/django/core/handlers/base.py", line 181, in _get_response
    response = wrapped_callback(request, *callback_args, **callback_kwargs)
  File "/home/vid/makereport/DTPreport/env/lib/python3.6/site-packages/django/views/generic/base.py", line 70, in view
    return self.dispatch(request, *args, **kwargs)
  File "/home/vid/makereport/DTPreport/env/lib/python3.6/site-packages/django/views/generic/base.py", line 98, in dispatch
    return handler(request, *args, **kwargs)
  File "/home/vid/makereport/DTPreport/pdf_report/views.py", line 185, in get
    pdf.generate(context)
  File "/home/vid/makereport/DTPreport/pdf_report/utils.py", line 600, in generate
    self.jinja2(context)
  File "/home/vid/makereport/DTPreport/pdf_report/utils.py", line 573, in jinja2
    self.xml = template.render(**context).encode('utf-8')
  File "/home/vid/makereport/DTPreport/env/lib/python3.6/site-packages/jinja2/environment.py", line 1090, in render
    self.environment.handle_exception()
  File "/home/vid/makereport/DTPreport/env/lib/python3.6/site-packages/jinja2/environment.py", line 832, in handle_exception
    reraise(*rewrite_traceback_stack(source=source))
  File "/home/vid/makereport/DTPreport/env/lib/python3.6/site-packages/jinja2/_compat.py", line 28, in reraise
    raise value.with_traceback(tb)
  File "templates/example.xml", line 690, in top-level template code
    Ки,физ =(0,208 - 0,003 * {{ report.wear_data.__getitem__('point') }}) * {{ report.wear_data.__getitem__('weight') }} ^ 0.7 = {{ report.wear_data.__getitem__('wear') }}%
jinja2.exceptions.UndefinedError: 'None' has no attribute '__getitem__'
Not Found: /robots.txt
Not Found: /accounts/login/
Not Found: /robots.txt
Internal Server Error: /pdf/1/
Traceback (most recent call last):
  File "/home/vid/makereport/DTPreport/env/lib/python3.6/site-packages/django/core/handlers/exception.py", line 47, in inner
    response = get_response(request)
  File "/home/vid/makereport/DTPreport/env/lib/python3.6/site-packages/django/core/handlers/base.py", line 181, in _get_response
    response = wrapped_callback(request, *callback_args, **callback_kwargs)
  File "/home/vid/makereport/DTPreport/env/lib/python3.6/site-packages/django/views/generic/base.py", line 70, in view
    return self.dispatch(request, *args, **kwargs)
  File "/home/vid/makereport/DTPreport/env/lib/python3.6/site-packages/django/views/generic/base.py", line 98, in dispatch
    return handler(request, *args, **kwargs)
  File "/home/vid/makereport/DTPreport/pdf_report/views.py", line 185, in get
    pdf.generate(context)
  File "/home/vid/makereport/DTPreport/pdf_report/utils.py", line 600, in generate
    self.jinja2(context)
  File "/home/vid/makereport/DTPreport/pdf_report/utils.py", line 573, in jinja2
    self.xml = template.render(**context).encode('utf-8')
  File "/home/vid/makereport/DTPreport/env/lib/python3.6/site-packages/jinja2/environment.py", line 1090, in render
    self.environment.handle_exception()
  File "/home/vid/makereport/DTPreport/env/lib/python3.6/site-packages/jinja2/environment.py", line 832, in handle_exception
    reraise(*rewrite_traceback_stack(source=source))
  File "/home/vid/makereport/DTPreport/env/lib/python3.6/site-packages/jinja2/_compat.py", line 28, in reraise
    raise value.with_traceback(tb)
  File "templates/example.xml", line 690, in top-level template code
    Ки,физ =(0,208 - 0,003 * {{ report.wear_data.__getitem__('point') }}) * {{ report.wear_data.__getitem__('weight') }} ^ 0.7 = {{ report.wear_data.__getitem__('wear') }}%
jinja2.exceptions.UndefinedError: 'None' has no attribute '__getitem__'
Internal Server Error: /pdf/2/
Traceback (most recent call last):
  File "/home/vid/makereport/DTPreport/env/lib/python3.6/site-packages/django/core/handlers/exception.py", line 47, in inner
    response = get_response(request)
  File "/home/vid/makereport/DTPreport/env/lib/python3.6/site-packages/django/core/handlers/base.py", line 181, in _get_response
    response = wrapped_callback(request, *callback_args, **callback_kwargs)
  File "/home/vid/makereport/DTPreport/env/lib/python3.6/site-packages/django/views/generic/base.py", line 70, in view
    return self.dispatch(request, *args, **kwargs)
  File "/home/vid/makereport/DTPreport/env/lib/python3.6/site-packages/django/views/generic/base.py", line 98, in dispatch
    return handler(request, *args, **kwargs)
  File "/home/vid/makereport/DTPreport/pdf_report/views.py", line 185, in get
    pdf.generate(context)
  File "/home/vid/makereport/DTPreport/pdf_report/utils.py", line 600, in generate
    self.jinja2(context)
  File "/home/vid/makereport/DTPreport/pdf_report/utils.py", line 573, in jinja2
    self.xml = template.render(**context).encode('utf-8')
  File "/home/vid/makereport/DTPreport/env/lib/python3.6/site-packages/jinja2/environment.py", line 1090, in render
    self.environment.handle_exception()
  File "/home/vid/makereport/DTPreport/env/lib/python3.6/site-packages/jinja2/environment.py", line 832, in handle_exception
    reraise(*rewrite_traceback_stack(source=source))
  File "/home/vid/makereport/DTPreport/env/lib/python3.6/site-packages/jinja2/_compat.py", line 28, in reraise
    raise value.with_traceback(tb)
  File "templates/example.xml", line 690, in top-level template code
    Ки,физ =(0,208 - 0,003 * {{ report.wear_data.__getitem__('point') }}) * {{ report.wear_data.__getitem__('weight') }} ^ 0.7 = {{ report.wear_data.__getitem__('wear') }}%
jinja2.exceptions.UndefinedError: 'None' has no attribute '__getitem__'
Invalid HTTP_HOST header: '185.196.214.176'. You may need to add '185.196.214.176' to ALLOWED_HOSTS.
Bad Request: /bag2
Invalid HTTP_HOST header: '185.196.214.176'. You may need to add '185.196.214.176' to ALLOWED_HOSTS.
Bad Request: /
Invalid HTTP_HOST header: '185.196.214.176'. You may need to add '185.196.214.176' to ALLOWED_HOSTS.
Bad Request: /admin//config.php
Invalid HTTP_HOST header: '185.196.214.176'. You may need to add '185.196.214.176' to ALLOWED_HOSTS.
Bad Request: /
Invalid HTTP_HOST header: '185.196.214.176'. You may need to add '185.196.214.176' to ALLOWED_HOSTS.
Bad Request: /
Invalid HTTP_HOST header: '185.196.214.176'. You may need to add '185.196.214.176' to ALLOWED_HOSTS.
Bad Request: /robots.txt
Invalid HTTP_HOST header: '185.196.214.176'. You may need to add '185.196.214.176' to ALLOWED_HOSTS.
Bad Request: /sitemap.xml
Invalid HTTP_HOST header: '185.196.214.176'. You may need to add '185.196.214.176' to ALLOWED_HOSTS.
Bad Request: /.well-known/security.txt
Invalid HTTP_HOST header: '185.196.214.176'. You may need to add '185.196.214.176' to ALLOWED_HOSTS.
Bad Request: /favicon.ico
Invalid HTTP_HOST header: '185.196.214.176'. You may need to add '185.196.214.176' to ALLOWED_HOSTS.
Bad Request: /
Invalid HTTP_HOST header: 'www.e-otsenka.uz'. You may need to add 'www.e-otsenka.uz' to ALLOWED_HOSTS.
Bad Request: /
Not Found: /robots.txt
Not Found: /accounts/login/
Internal Server Error: /pdf/1/
Traceback (most recent call last):
  File "/home/vid/makereport/DTPreport/env/lib/python3.6/site-packages/django/core/handlers/exception.py", line 47, in inner
    response = get_response(request)
  File "/home/vid/makereport/DTPreport/env/lib/python3.6/site-packages/django/core/handlers/base.py", line 181, in _get_response
    response = wrapped_callback(request, *callback_args, **callback_kwargs)
  File "/home/vid/makereport/DTPreport/env/lib/python3.6/site-packages/django/views/generic/base.py", line 70, in view
    return self.dispatch(request, *args, **kwargs)
  File "/home/vid/makereport/DTPreport/env/lib/python3.6/site-packages/django/views/generic/base.py", line 98, in dispatch
    return handler(request, *args, **kwargs)
  File "/home/vid/makereport/DTPreport/pdf_report/views.py", line 185, in get
    pdf.generate(context)
  File "/home/vid/makereport/DTPreport/pdf_report/utils.py", line 600, in generate
    self.jinja2(context)
  File "/home/vid/makereport/DTPreport/pdf_report/utils.py", line 573, in jinja2
    self.xml = template.render(**context).encode('utf-8')
  File "/home/vid/makereport/DTPreport/env/lib/python3.6/site-packages/jinja2/environment.py", line 1090, in render
    self.environment.handle_exception()
  File "/home/vid/makereport/DTPreport/env/lib/python3.6/site-packages/jinja2/environment.py", line 832, in handle_exception
    reraise(*rewrite_traceback_stack(source=source))
  File "/home/vid/makereport/DTPreport/env/lib/python3.6/site-packages/jinja2/_compat.py", line 28, in reraise
    raise value.with_traceback(tb)
  File "templates/example.xml", line 690, in top-level template code
    Ки,физ =(0,208 - 0,003 * {{ report.wear_data.__getitem__('point') }}) * {{ report.wear_data.__getitem__('weight') }} ^ 0.7 = {{ report.wear_data.__getitem__('wear') }}%
jinja2.exceptions.UndefinedError: 'None' has no attribute '__getitem__'
Internal Server Error: /pdf/2/
Traceback (most recent call last):
  File "/home/vid/makereport/DTPreport/env/lib/python3.6/site-packages/django/core/handlers/exception.py", line 47, in inner
    response = get_response(request)
  File "/home/vid/makereport/DTPreport/env/lib/python3.6/site-packages/django/core/handlers/base.py", line 181, in _get_response
    response = wrapped_callback(request, *callback_args, **callback_kwargs)
  File "/home/vid/makereport/DTPreport/env/lib/python3.6/site-packages/django/views/generic/base.py", line 70, in view
    return self.dispatch(request, *args, **kwargs)
  File "/home/vid/makereport/DTPreport/env/lib/python3.6/site-packages/django/views/generic/base.py", line 98, in dispatch
    return handler(request, *args, **kwargs)
  File "/home/vid/makereport/DTPreport/pdf_report/views.py", line 185, in get
    pdf.generate(context)
  File "/home/vid/makereport/DTPreport/pdf_report/utils.py", line 600, in generate
    self.jinja2(context)
  File "/home/vid/makereport/DTPreport/pdf_report/utils.py", line 573, in jinja2
    self.xml = template.render(**context).encode('utf-8')
  File "/home/vid/makereport/DTPreport/env/lib/python3.6/site-packages/jinja2/environment.py", line 1090, in render
    self.environment.handle_exception()
  File "/home/vid/makereport/DTPreport/env/lib/python3.6/site-packages/jinja2/environment.py", line 832, in handle_exception
    reraise(*rewrite_traceback_stack(source=source))
  File "/home/vid/makereport/DTPreport/env/lib/python3.6/site-packages/jinja2/_compat.py", line 28, in reraise
    raise value.with_traceback(tb)
  File "templates/example.xml", line 690, in top-level template code
    Ки,физ =(0,208 - 0,003 * {{ report.wear_data.__getitem__('point') }}) * {{ report.wear_data.__getitem__('weight') }} ^ 0.7 = {{ report.wear_data.__getitem__('wear') }}%
jinja2.exceptions.UndefinedError: 'None' has no attribute '__getitem__'
Not Found: /accounts/login/
Not Found: /robots.txt
Not Found: /favicon.ico
Not Found: /robots.txt
Internal Server Error: /pdf/1/
Traceback (most recent call last):
  File "/home/vid/makereport/DTPreport/env/lib/python3.6/site-packages/django/core/handlers/exception.py", line 47, in inner
    response = get_response(request)
  File "/home/vid/makereport/DTPreport/env/lib/python3.6/site-packages/django/core/handlers/base.py", line 181, in _get_response
    response = wrapped_callback(request, *callback_args, **callback_kwargs)
  File "/home/vid/makereport/DTPreport/env/lib/python3.6/site-packages/django/views/generic/base.py", line 70, in view
    return self.dispatch(request, *args, **kwargs)
  File "/home/vid/makereport/DTPreport/env/lib/python3.6/site-packages/django/views/generic/base.py", line 98, in dispatch
    return handler(request, *args, **kwargs)
  File "/home/vid/makereport/DTPreport/pdf_report/views.py", line 185, in get
    pdf.generate(context)
  File "/home/vid/makereport/DTPreport/pdf_report/utils.py", line 600, in generate
    self.jinja2(context)
  File "/home/vid/makereport/DTPreport/pdf_report/utils.py", line 573, in jinja2
    self.xml = template.render(**context).encode('utf-8')
  File "/home/vid/makereport/DTPreport/env/lib/python3.6/site-packages/jinja2/environment.py", line 1090, in render
    self.environment.handle_exception()
  File "/home/vid/makereport/DTPreport/env/lib/python3.6/site-packages/jinja2/environment.py", line 832, in handle_exception
    reraise(*rewrite_traceback_stack(source=source))
  File "/home/vid/makereport/DTPreport/env/lib/python3.6/site-packages/jinja2/_compat.py", line 28, in reraise
    raise value.with_traceback(tb)
  File "templates/example.xml", line 690, in top-level template code
    Ки,физ =(0,208 - 0,003 * {{ report.wear_data.__getitem__('point') }}) * {{ report.wear_data.__getitem__('weight') }} ^ 0.7 = {{ report.wear_data.__getitem__('wear') }}%
jinja2.exceptions.UndefinedError: 'None' has no attribute '__getitem__'
Internal Server Error: /pdf/2/
Traceback (most recent call last):
  File "/home/vid/makereport/DTPreport/env/lib/python3.6/site-packages/django/core/handlers/exception.py", line 47, in inner
    response = get_response(request)
  File "/home/vid/makereport/DTPreport/env/lib/python3.6/site-packages/django/core/handlers/base.py", line 181, in _get_response
    response = wrapped_callback(request, *callback_args, **callback_kwargs)
  File "/home/vid/makereport/DTPreport/env/lib/python3.6/site-packages/django/views/generic/base.py", line 70, in view
    return self.dispatch(request, *args, **kwargs)
  File "/home/vid/makereport/DTPreport/env/lib/python3.6/site-packages/django/views/generic/base.py", line 98, in dispatch
    return handler(request, *args, **kwargs)
  File "/home/vid/makereport/DTPreport/pdf_report/views.py", line 185, in get
    pdf.generate(context)
  File "/home/vid/makereport/DTPreport/pdf_report/utils.py", line 600, in generate
    self.jinja2(context)
  File "/home/vid/makereport/DTPreport/pdf_report/utils.py", line 573, in jinja2
    self.xml = template.render(**context).encode('utf-8')
  File "/home/vid/makereport/DTPreport/env/lib/python3.6/site-packages/jinja2/environment.py", line 1090, in render
    self.environment.handle_exception()
  File "/home/vid/makereport/DTPreport/env/lib/python3.6/site-packages/jinja2/environment.py", line 832, in handle_exception
    reraise(*rewrite_traceback_stack(source=source))
  File "/home/vid/makereport/DTPreport/env/lib/python3.6/site-packages/jinja2/_compat.py", line 28, in reraise
    raise value.with_traceback(tb)
  File "templates/example.xml", line 690, in top-level template code
    Ки,физ =(0,208 - 0,003 * {{ report.wear_data.__getitem__('point') }}) * {{ report.wear_data.__getitem__('weight') }} ^ 0.7 = {{ report.wear_data.__getitem__('wear') }}%
jinja2.exceptions.UndefinedError: 'None' has no attribute '__getitem__'
Invalid HTTP_HOST header: '185.196.214.176'. You may need to add '185.196.214.176' to ALLOWED_HOSTS.
Bad Request: /cgi-bin/kerbynet
Internal Server Error: /pdf/1/
Traceback (most recent call last):
  File "/home/vid/makereport/DTPreport/env/lib/python3.6/site-packages/django/core/handlers/exception.py", line 47, in inner
    response = get_response(request)
  File "/home/vid/makereport/DTPreport/env/lib/python3.6/site-packages/django/core/handlers/base.py", line 181, in _get_response
    response = wrapped_callback(request, *callback_args, **callback_kwargs)
  File "/home/vid/makereport/DTPreport/env/lib/python3.6/site-packages/django/views/generic/base.py", line 70, in view
    return self.dispatch(request, *args, **kwargs)
  File "/home/vid/makereport/DTPreport/env/lib/python3.6/site-packages/django/views/generic/base.py", line 98, in dispatch
    return handler(request, *args, **kwargs)
  File "/home/vid/makereport/DTPreport/pdf_report/views.py", line 185, in get
    pdf.generate(context)
  File "/home/vid/makereport/DTPreport/pdf_report/utils.py", line 600, in generate
    self.jinja2(context)
  File "/home/vid/makereport/DTPreport/pdf_report/utils.py", line 573, in jinja2
    self.xml = template.render(**context).encode('utf-8')
  File "/home/vid/makereport/DTPreport/env/lib/python3.6/site-packages/jinja2/environment.py", line 1090, in render
    self.environment.handle_exception()
  File "/home/vid/makereport/DTPreport/env/lib/python3.6/site-packages/jinja2/environment.py", line 832, in handle_exception
    reraise(*rewrite_traceback_stack(source=source))
  File "/home/vid/makereport/DTPreport/env/lib/python3.6/site-packages/jinja2/_compat.py", line 28, in reraise
    raise value.with_traceback(tb)
  File "templates/example.xml", line 690, in top-level template code
    Ки,физ =(0,208 - 0,003 * {{ report.wear_data.__getitem__('point') }}) * {{ report.wear_data.__getitem__('weight') }} ^ 0.7 = {{ report.wear_data.__getitem__('wear') }}%
jinja2.exceptions.UndefinedError: 'None' has no attribute '__getitem__'
Internal Server Error: /pdf/2/
Traceback (most recent call last):
  File "/home/vid/makereport/DTPreport/env/lib/python3.6/site-packages/django/core/handlers/exception.py", line 47, in inner
    response = get_response(request)
  File "/home/vid/makereport/DTPreport/env/lib/python3.6/site-packages/django/core/handlers/base.py", line 181, in _get_response
    response = wrapped_callback(request, *callback_args, **callback_kwargs)
  File "/home/vid/makereport/DTPreport/env/lib/python3.6/site-packages/django/views/generic/base.py", line 70, in view
    return self.dispatch(request, *args, **kwargs)
  File "/home/vid/makereport/DTPreport/env/lib/python3.6/site-packages/django/views/generic/base.py", line 98, in dispatch
    return handler(request, *args, **kwargs)
  File "/home/vid/makereport/DTPreport/pdf_report/views.py", line 185, in get
    pdf.generate(context)
  File "/home/vid/makereport/DTPreport/pdf_report/utils.py", line 600, in generate
    self.jinja2(context)
  File "/home/vid/makereport/DTPreport/pdf_report/utils.py", line 573, in jinja2
    self.xml = template.render(**context).encode('utf-8')
  File "/home/vid/makereport/DTPreport/env/lib/python3.6/site-packages/jinja2/environment.py", line 1090, in render
    self.environment.handle_exception()
  File "/home/vid/makereport/DTPreport/env/lib/python3.6/site-packages/jinja2/environment.py", line 832, in handle_exception
    reraise(*rewrite_traceback_stack(source=source))
  File "/home/vid/makereport/DTPreport/env/lib/python3.6/site-packages/jinja2/_compat.py", line 28, in reraise
    raise value.with_traceback(tb)
  File "templates/example.xml", line 690, in top-level template code
    Ки,физ =(0,208 - 0,003 * {{ report.wear_data.__getitem__('point') }}) * {{ report.wear_data.__getitem__('weight') }} ^ 0.7 = {{ report.wear_data.__getitem__('wear') }}%
jinja2.exceptions.UndefinedError: 'None' has no attribute '__getitem__'
Invalid HTTP_HOST header: '185.196.214.176'. You may need to add '185.196.214.176' to ALLOWED_HOSTS.
Bad Request: /admin//config.php
Not Found: /robots.txt
Internal Server Error: /pdf/1/
Traceback (most recent call last):
  File "/home/vid/makereport/DTPreport/env/lib/python3.6/site-packages/django/core/handlers/exception.py", line 47, in inner
    response = get_response(request)
  File "/home/vid/makereport/DTPreport/env/lib/python3.6/site-packages/django/core/handlers/base.py", line 181, in _get_response
    response = wrapped_callback(request, *callback_args, **callback_kwargs)
  File "/home/vid/makereport/DTPreport/env/lib/python3.6/site-packages/django/views/generic/base.py", line 70, in view
    return self.dispatch(request, *args, **kwargs)
  File "/home/vid/makereport/DTPreport/env/lib/python3.6/site-packages/django/views/generic/base.py", line 98, in dispatch
    return handler(request, *args, **kwargs)
  File "/home/vid/makereport/DTPreport/pdf_report/views.py", line 185, in get
    pdf.generate(context)
  File "/home/vid/makereport/DTPreport/pdf_report/utils.py", line 600, in generate
    self.jinja2(context)
  File "/home/vid/makereport/DTPreport/pdf_report/utils.py", line 573, in jinja2
    self.xml = template.render(**context).encode('utf-8')
  File "/home/vid/makereport/DTPreport/env/lib/python3.6/site-packages/jinja2/environment.py", line 1090, in render
    self.environment.handle_exception()
  File "/home/vid/makereport/DTPreport/env/lib/python3.6/site-packages/jinja2/environment.py", line 832, in handle_exception
    reraise(*rewrite_traceback_stack(source=source))
  File "/home/vid/makereport/DTPreport/env/lib/python3.6/site-packages/jinja2/_compat.py", line 28, in reraise
    raise value.with_traceback(tb)
  File "templates/example.xml", line 690, in top-level template code
    Ки,физ =(0,208 - 0,003 * {{ report.wear_data.__getitem__('point') }}) * {{ report.wear_data.__getitem__('weight') }} ^ 0.7 = {{ report.wear_data.__getitem__('wear') }}%
jinja2.exceptions.UndefinedError: 'None' has no attribute '__getitem__'
Internal Server Error: /pdf/2/
Traceback (most recent call last):
  File "/home/vid/makereport/DTPreport/env/lib/python3.6/site-packages/django/core/handlers/exception.py", line 47, in inner
    response = get_response(request)
  File "/home/vid/makereport/DTPreport/env/lib/python3.6/site-packages/django/core/handlers/base.py", line 181, in _get_response
    response = wrapped_callback(request, *callback_args, **callback_kwargs)
  File "/home/vid/makereport/DTPreport/env/lib/python3.6/site-packages/django/views/generic/base.py", line 70, in view
    return self.dispatch(request, *args, **kwargs)
  File "/home/vid/makereport/DTPreport/env/lib/python3.6/site-packages/django/views/generic/base.py", line 98, in dispatch
    return handler(request, *args, **kwargs)
  File "/home/vid/makereport/DTPreport/pdf_report/views.py", line 185, in get
    pdf.generate(context)
  File "/home/vid/makereport/DTPreport/pdf_report/utils.py", line 600, in generate
    self.jinja2(context)
  File "/home/vid/makereport/DTPreport/pdf_report/utils.py", line 573, in jinja2
    self.xml = template.render(**context).encode('utf-8')
  File "/home/vid/makereport/DTPreport/env/lib/python3.6/site-packages/jinja2/environment.py", line 1090, in render
    self.environment.handle_exception()
  File "/home/vid/makereport/DTPreport/env/lib/python3.6/site-packages/jinja2/environment.py", line 832, in handle_exception
    reraise(*rewrite_traceback_stack(source=source))
  File "/home/vid/makereport/DTPreport/env/lib/python3.6/site-packages/jinja2/_compat.py", line 28, in reraise
    raise value.with_traceback(tb)
  File "templates/example.xml", line 690, in top-level template code
    Ки,физ =(0,208 - 0,003 * {{ report.wear_data.__getitem__('point') }}) * {{ report.wear_data.__getitem__('weight') }} ^ 0.7 = {{ report.wear_data.__getitem__('wear') }}%
jinja2.exceptions.UndefinedError: 'None' has no attribute '__getitem__'
Not Found: /favicon.ico
Not Found: /favicon.ico
Invalid HTTP_HOST header: '185.196.214.176'. You may need to add '185.196.214.176' to ALLOWED_HOSTS.
Bad Request: /
Invalid HTTP_HOST header: '185.196.214.176'. You may need to add '185.196.214.176' to ALLOWED_HOSTS.
Bad Request: /
Invalid HTTP_HOST header: '185.196.214.176'. You may need to add '185.196.214.176' to ALLOWED_HOSTS.
Bad Request: /
Invalid HTTP_HOST header: '185.196.214.176'. You may need to add '185.196.214.176' to ALLOWED_HOSTS.
Bad Request: /
Not Found: /favicon.ico
Not Found: /accounts/login/
Not Found: /accounts/login/
Not Found: /robots.txt
Not Found: /robots.txt
Not Found: /favicon.ico
Not Found: /accounts/login/
Not Found: /accounts/login/
Not Found: /accounts/login/
Not Found: /accounts/login/
Not Found: /favicon.ico
Not Found: /report
Not Found: /report/
Invalid HTTP_HOST header: '185.196.214.176'. You may need to add '185.196.214.176' to ALLOWED_HOSTS.
Bad Request: /
Not Found: /favicon.ico
Not Found: /reports_list
Not Found: /accounts/login/
Not Found: /favicon.ico
Forbidden (CSRF token missing or incorrect.): /
Not Found: /favicon.ico
Invalid HTTP_HOST header: '185.196.214.176'. You may need to add '185.196.214.176' to ALLOWED_HOSTS.
Bad Request: /admin//config.php
Not Found: /robots.txt
Invalid HTTP_HOST header: '185.196.214.176'. You may need to add '185.196.214.176' to ALLOWED_HOSTS.
Bad Request: /
Invalid HTTP_HOST header: '185.196.214.176'. You may need to add '185.196.214.176' to ALLOWED_HOSTS.
Bad Request: /
Invalid HTTP_HOST header: '185.196.214.176'. You may need to add '185.196.214.176' to ALLOWED_HOSTS.
Bad Request: /
Not Found: /favicon.ico
Not Found: /favicon.ico
Not Found: /favicon.ico
Invalid HTTP_HOST header: '185.196.214.176'. You may need to add '185.196.214.176' to ALLOWED_HOSTS.
Bad Request: /
Invalid HTTP_HOST header: '185.196.214.176'. You may need to add '185.196.214.176' to ALLOWED_HOSTS.
Bad Request: /
Not Found: /favicon.ico
Invalid HTTP_HOST header: '185.196.214.176'. You may need to add '185.196.214.176' to ALLOWED_HOSTS.
Bad Request: /admin//config.php
Not Found: /favicon.ico
Invalid HTTP_HOST header: '185.196.214.176'. You may need to add '185.196.214.176' to ALLOWED_HOSTS.
Bad Request: /
Invalid HTTP_HOST header: '185.196.214.176'. You may need to add '185.196.214.176' to ALLOWED_HOSTS.
Bad Request: /
Invalid HTTP_HOST header: '185.196.214.176'. You may need to add '185.196.214.176' to ALLOWED_HOSTS.
Bad Request: /
Invalid HTTP_HOST header: '185.196.214.176'. You may need to add '185.196.214.176' to ALLOWED_HOSTS.
Bad Request: /
Not Found: /accounts/login/
Not Found: /favicon.ico
Not Found: /accounts/login/
Not Found: /favicon.ico
Not Found: /favicon.ico
Invalid HTTP_HOST header: 'www.e-otsenka.uz'. You may need to add 'www.e-otsenka.uz' to ALLOWED_HOSTS.
Bad Request: /
Invalid HTTP_HOST header: '185.196.214.176'. You may need to add '185.196.214.176' to ALLOWED_HOSTS.
Bad Request: /
Invalid HTTP_HOST header: '185.196.214.176'. You may need to add '185.196.214.176' to ALLOWED_HOSTS.
Bad Request: /
Not Found: /favicon.ico
Invalid HTTP_HOST header: '185.196.214.176'. You may need to add '185.196.214.176' to ALLOWED_HOSTS.
Bad Request: /
Invalid HTTP_HOST header: '185.196.214.176'. You may need to add '185.196.214.176' to ALLOWED_HOSTS.
Bad Request: /admin//config.php
Invalid HTTP_HOST header: '185.196.214.176'. You may need to add '185.196.214.176' to ALLOWED_HOSTS.
Bad Request: /
Invalid HTTP_HOST header: '185.196.214.176'. You may need to add '185.196.214.176' to ALLOWED_HOSTS.
Bad Request: /
Not Found: /favicon.ico
Invalid HTTP_HOST header: '185.196.214.176'. You may need to add '185.196.214.176' to ALLOWED_HOSTS.
Bad Request: /system_api.php
Invalid HTTP_HOST header: '185.196.214.176'. You may need to add '185.196.214.176' to ALLOWED_HOSTS.
Bad Request: /c/version.js
Invalid HTTP_HOST header: '185.196.214.176'. You may need to add '185.196.214.176' to ALLOWED_HOSTS.
Bad Request: /streaming/clients_live.php
Invalid HTTP_HOST header: '185.196.214.176'. You may need to add '185.196.214.176' to ALLOWED_HOSTS.
Bad Request: /stalker_portal/c/version.js
Invalid HTTP_HOST header: '185.196.214.176'. You may need to add '185.196.214.176' to ALLOWED_HOSTS.
Bad Request: /client_area/
Invalid HTTP_HOST header: '185.196.214.176'. You may need to add '185.196.214.176' to ALLOWED_HOSTS.
Bad Request: /stalker_portal/c/
Invalid HTTP_HOST header: '185.196.214.176'. You may need to add '185.196.214.176' to ALLOWED_HOSTS.
Bad Request: /
Not Found: /favicon.ico
Invalid HTTP_HOST header: '185.196.214.176'. You may need to add '185.196.214.176' to ALLOWED_HOSTS.
Bad Request: /dns-query
Invalid HTTP_HOST header: '185.196.214.176'. You may need to add '185.196.214.176' to ALLOWED_HOSTS.
Bad Request: /
Invalid HTTP_HOST header: '185.196.214.176'. You may need to add '185.196.214.176' to ALLOWED_HOSTS.
Bad Request: /
Invalid HTTP_HOST header: '185.196.214.176'. You may need to add '185.196.214.176' to ALLOWED_HOSTS.
Bad Request: /robots.txt
Invalid HTTP_HOST header: '185.196.214.176'. You may need to add '185.196.214.176' to ALLOWED_HOSTS.
Bad Request: /sitemap.xml
Invalid HTTP_HOST header: '185.196.214.176'. You may need to add '185.196.214.176' to ALLOWED_HOSTS.
Bad Request: /.well-known/security.txt
Invalid HTTP_HOST header: '185.196.214.176'. You may need to add '185.196.214.176' to ALLOWED_HOSTS.
Bad Request: /favicon.ico
Invalid HTTP_HOST header: '185.196.214.176'. You may need to add '185.196.214.176' to ALLOWED_HOSTS.
Bad Request: /
Invalid HTTP_HOST header: '185.196.214.176'. You may need to add '185.196.214.176' to ALLOWED_HOSTS.
Bad Request: /
Not Found: /favicon.ico
Invalid HTTP_HOST header: '185.196.214.176'. You may need to add '185.196.214.176' to ALLOWED_HOSTS.
Bad Request: /
Invalid HTTP_HOST header: '185.196.214.176'. You may need to add '185.196.214.176' to ALLOWED_HOSTS.
Bad Request: /
Invalid HTTP_HOST header: '185.196.214.176'. You may need to add '185.196.214.176' to ALLOWED_HOSTS.
Bad Request: /
Invalid HTTP_HOST header: '185.196.214.176'. You may need to add '185.196.214.176' to ALLOWED_HOSTS.
Bad Request: /
Invalid HTTP_HOST header: '185.196.214.176'. You may need to add '185.196.214.176' to ALLOWED_HOSTS.
Bad Request: /
[2021-02-25 08:57:02 +0000] [71738] [INFO] Worker exiting (pid: 71738)
[2021-02-25 08:57:02 +0000] [71736] [INFO] Handling signal: term
[2021-02-25 08:57:03 +0000] [71736] [INFO] Shutting down: Master
[2021-02-25 08:57:03 +0000] [4640] [INFO] Starting gunicorn 20.0.4
[2021-02-25 08:57:03 +0000] [4640] [INFO] Listening at: http://127.0.0.1:46710 (4640)
[2021-02-25 08:57:03 +0000] [4640] [INFO] Using worker: sync
[2021-02-25 08:57:03 +0000] [4642] [INFO] Booting worker with pid: 4642
Not Found: /assets/js/bootstrap.min.js
Not Found: /assets/js/script.js
Not Found: /assets/js/script.js
Not Found: /favicon.ico
Not Found: /assets/js/script.js
Not Found: /assets/js/bootstrap.min.js
Not Found: /assets/js/script.js
Not Found: /assets/js/bootstrap.min.js
Not Found: /assets/js/script.js
Not Found: /assets/js/script.js
[2021-02-25 08:58:00 +0000] [4642] [INFO] Worker exiting (pid: 4642)
[2021-02-25 08:58:00 +0000] [4640] [INFO] Handling signal: term
[2021-02-25 08:58:00 +0000] [4640] [INFO] Shutting down: Master
[2021-02-25 08:58:01 +0000] [4655] [INFO] Starting gunicorn 20.0.4
[2021-02-25 08:58:01 +0000] [4655] [INFO] Listening at: http://127.0.0.1:46710 (4655)
[2021-02-25 08:58:01 +0000] [4655] [INFO] Using worker: sync
[2021-02-25 08:58:01 +0000] [4657] [INFO] Booting worker with pid: 4657
Not Found: /assets/js/bootstrap.min.js
Not Found: /assets/js/script.js
[2021-02-25 08:58:44 +0000] [4657] [INFO] Worker exiting (pid: 4657)
[2021-02-25 08:58:44 +0000] [4655] [INFO] Handling signal: term
[2021-02-25 08:58:44 +0000] [4655] [INFO] Shutting down: Master
[2021-02-25 08:58:45 +0000] [4678] [INFO] Starting gunicorn 20.0.4
[2021-02-25 08:58:45 +0000] [4678] [INFO] Listening at: http://127.0.0.1:46710 (4678)
[2021-02-25 08:58:45 +0000] [4678] [INFO] Using worker: sync
[2021-02-25 08:58:45 +0000] [4680] [INFO] Booting worker with pid: 4680
Not Found: /assets/js/bootstrap.min.js
Not Found: /assets/js/script.js
Not Found: /assets/js/bootstrap.min.js
Not Found: /assets/js/script.js
Not Found: /assets/js/bootstrap.min.js
Not Found: /assets/js/script.js
Not Found: /assets/js/bootstrap.min.js
Not Found: /assets/js/script.js
Not Found: /assets/js/script.js
Not Found: /login/assets/js/bootstrap.min.js
Not Found: /login/assets/js/script.js
Not Found: /login/assets/js/bootstrap.min.js
Not Found: /login/assets/js/script.js
Internal Server Error: /report/list
Traceback (most recent call last):
  File "/home/vid/makereport/DTPreport/env/lib/python3.6/site-packages/django/db/backends/utils.py", line 84, in _execute
    return self.cursor.execute(sql, params)
psycopg2.errors.UndefinedColumn: column makereport_report.total_report_cost_txt does not exist
LINE 1: ..."."key", "makereport_report"."total_report_cost", "makerepor...
                                                             ^


The above exception was the direct cause of the following exception:

Traceback (most recent call last):
  File "/home/vid/makereport/DTPreport/env/lib/python3.6/site-packages/django/core/handlers/exception.py", line 47, in inner
    response = get_response(request)
  File "/home/vid/makereport/DTPreport/env/lib/python3.6/site-packages/django/core/handlers/base.py", line 181, in _get_response
    response = wrapped_callback(request, *callback_args, **callback_kwargs)
  File "/home/vid/makereport/DTPreport/env/lib/python3.6/site-packages/django/contrib/auth/decorators.py", line 21, in _wrapped_view
    return view_func(request, *args, **kwargs)
  File "/home/vid/makereport/DTPreport/makereport/views.py", line 339, in reports_list
    return render(request, 'makereport/index.html', context={'reports': reports})
  File "/home/vid/makereport/DTPreport/env/lib/python3.6/site-packages/django/shortcuts.py", line 19, in render
    content = loader.render_to_string(template_name, context, request, using=using)
  File "/home/vid/makereport/DTPreport/env/lib/python3.6/site-packages/django/template/loader.py", line 62, in render_to_string
    return template.render(context, request)
  File "/home/vid/makereport/DTPreport/env/lib/python3.6/site-packages/django/template/backends/django.py", line 61, in render
    return self.template.render(context)
  File "/home/vid/makereport/DTPreport/env/lib/python3.6/site-packages/django/template/base.py", line 170, in render
    return self._render(context)
  File "/home/vid/makereport/DTPreport/env/lib/python3.6/site-packages/django/template/base.py", line 162, in _render
    return self.nodelist.render(context)
  File "/home/vid/makereport/DTPreport/env/lib/python3.6/site-packages/django/template/base.py", line 938, in render
    bit = node.render_annotated(context)
  File "/home/vid/makereport/DTPreport/env/lib/python3.6/site-packages/django/template/base.py", line 905, in render_annotated
    return self.render(context)
  File "/home/vid/makereport/DTPreport/env/lib/python3.6/site-packages/django/template/defaulttags.py", line 168, in render
    len_values = len(values)
  File "/home/vid/makereport/DTPreport/env/lib/python3.6/site-packages/django/db/models/query.py", line 269, in __len__
    self._fetch_all()
  File "/home/vid/makereport/DTPreport/env/lib/python3.6/site-packages/django/db/models/query.py", line 1308, in _fetch_all
    self._result_cache = list(self._iterable_class(self))
  File "/home/vid/makereport/DTPreport/env/lib/python3.6/site-packages/django/db/models/query.py", line 53, in __iter__
    results = compiler.execute_sql(chunked_fetch=self.chunked_fetch, chunk_size=self.chunk_size)
  File "/home/vid/makereport/DTPreport/env/lib/python3.6/site-packages/django/db/models/sql/compiler.py", line 1156, in execute_sql
    cursor.execute(sql, params)
  File "/home/vid/makereport/DTPreport/env/lib/python3.6/site-packages/django/db/backends/utils.py", line 98, in execute
    return super().execute(sql, params)
  File "/home/vid/makereport/DTPreport/env/lib/python3.6/site-packages/django/db/backends/utils.py", line 66, in execute
    return self._execute_with_wrappers(sql, params, many=False, executor=self._execute)
  File "/home/vid/makereport/DTPreport/env/lib/python3.6/site-packages/django/db/backends/utils.py", line 75, in _execute_with_wrappers
    return executor(sql, params, many, context)
  File "/home/vid/makereport/DTPreport/env/lib/python3.6/site-packages/django/db/backends/utils.py", line 84, in _execute
    return self.cursor.execute(sql, params)
  File "/home/vid/makereport/DTPreport/env/lib/python3.6/site-packages/django/db/utils.py", line 90, in __exit__
    raise dj_exc_value.with_traceback(traceback) from exc_value
  File "/home/vid/makereport/DTPreport/env/lib/python3.6/site-packages/django/db/backends/utils.py", line 84, in _execute
    return self.cursor.execute(sql, params)
django.db.utils.ProgrammingError: column makereport_report.total_report_cost_txt does not exist
LINE 1: ..."."key", "makereport_report"."total_report_cost", "makerepor...
                                                             ^

[2021-02-25 08:59:41 +0000] [4678] [INFO] Handling signal: term
[2021-02-25 08:59:41 +0000] [4680] [INFO] Worker exiting (pid: 4680)
[2021-02-25 08:59:42 +0000] [4678] [INFO] Shutting down: Master
[2021-02-25 08:59:42 +0000] [4700] [INFO] Starting gunicorn 20.0.4
[2021-02-25 08:59:42 +0000] [4700] [INFO] Listening at: http://127.0.0.1:46710 (4700)
[2021-02-25 08:59:42 +0000] [4700] [INFO] Using worker: sync
[2021-02-25 08:59:42 +0000] [4702] [INFO] Booting worker with pid: 4702
Internal Server Error: /pdf/3/
Traceback (most recent call last):
  File "/home/vid/makereport/DTPreport/env/lib/python3.6/site-packages/django/core/handlers/exception.py", line 47, in inner
    response = get_response(request)
  File "/home/vid/makereport/DTPreport/env/lib/python3.6/site-packages/django/core/handlers/base.py", line 181, in _get_response
    response = wrapped_callback(request, *callback_args, **callback_kwargs)
  File "/home/vid/makereport/DTPreport/env/lib/python3.6/site-packages/django/views/generic/base.py", line 70, in view
    return self.dispatch(request, *args, **kwargs)
  File "/home/vid/makereport/DTPreport/env/lib/python3.6/site-packages/django/views/generic/base.py", line 98, in dispatch
    return handler(request, *args, **kwargs)
  File "/home/vid/makereport/DTPreport/pdf_report/views.py", line 26, in get
    pdf.generate(context)
  File "/home/vid/makereport/DTPreport/pdf_report/utils.py", line 600, in generate
    self.jinja2(context)
  File "/home/vid/makereport/DTPreport/pdf_report/utils.py", line 573, in jinja2
    self.xml = template.render(**context).encode('utf-8')
  File "/home/vid/makereport/DTPreport/env/lib/python3.6/site-packages/jinja2/environment.py", line 1090, in render
    self.environment.handle_exception()
  File "/home/vid/makereport/DTPreport/env/lib/python3.6/site-packages/jinja2/environment.py", line 832, in handle_exception
    reraise(*rewrite_traceback_stack(source=source))
  File "/home/vid/makereport/DTPreport/env/lib/python3.6/site-packages/jinja2/_compat.py", line 28, in reraise
    raise value.with_traceback(tb)
  File "templates/example.xml", line 935, in top-level template code
    Ки,физ =(0,208 - 0,003 * {{ report.wear_data.__getitem__('point') }}) * {{ report.wear_data.__getitem__('weight') }} ^ 0.7 = {{ report.wear_data.__getitem__('wear') }}%
jinja2.exceptions.UndefinedError: 'None' has no attribute '__getitem__'
Internal Server Error: /pdf/4/
Traceback (most recent call last):
  File "/home/vid/makereport/DTPreport/env/lib/python3.6/site-packages/reportlab/lib/utils.py", line 677, in open_for_read
    return open_for_read_by_name(name,mode)
  File "/home/vid/makereport/DTPreport/env/lib/python3.6/site-packages/reportlab/lib/utils.py", line 612, in open_for_read_by_name
    return open(name,mode)
FileNotFoundError: [Errno 2] No such file or directory: 'media/AAB.png'

During handling of the above exception, another exception occurred:

Traceback (most recent call last):
  File "/home/vid/makereport/DTPreport/env/lib/python3.6/site-packages/reportlab/lib/utils.py", line 684, in open_for_read
    return getBytesIO(datareader(name) if name[:5].lower()=='data:' else urlopen(name).read())
  File "/usr/lib/python3.6/urllib/request.py", line 223, in urlopen
    return opener.open(url, data, timeout)
  File "/usr/lib/python3.6/urllib/request.py", line 511, in open
    req = Request(fullurl, data)
  File "/usr/lib/python3.6/urllib/request.py", line 329, in __init__
    self.full_url = url
  File "/usr/lib/python3.6/urllib/request.py", line 355, in full_url
    self._parse()
  File "/usr/lib/python3.6/urllib/request.py", line 384, in _parse
    raise ValueError("unknown url type: %r" % self.full_url)
ValueError: unknown url type: 'media/AAB.png'

During handling of the above exception, another exception occurred:

Traceback (most recent call last):
  File "/home/vid/makereport/DTPreport/env/lib/python3.6/site-packages/django/core/handlers/exception.py", line 47, in inner
    response = get_response(request)
  File "/home/vid/makereport/DTPreport/env/lib/python3.6/site-packages/django/core/handlers/base.py", line 181, in _get_response
    response = wrapped_callback(request, *callback_args, **callback_kwargs)
  File "/home/vid/makereport/DTPreport/env/lib/python3.6/site-packages/django/views/generic/base.py", line 70, in view
    return self.dispatch(request, *args, **kwargs)
  File "/home/vid/makereport/DTPreport/env/lib/python3.6/site-packages/django/views/generic/base.py", line 98, in dispatch
    return handler(request, *args, **kwargs)
  File "/home/vid/makereport/DTPreport/pdf_report/views.py", line 26, in get
    pdf.generate(context)
  File "/home/vid/makereport/DTPreport/pdf_report/utils.py", line 602, in generate
    self.parse()
  File "/home/vid/makereport/DTPreport/pdf_report/utils.py", line 576, in parse
    self.parser.Parse(self.xml)
  File "../Modules/pyexpat.c", line 419, in StartElement
  File "/home/vid/makereport/DTPreport/pdf_report/utils.py", line 523, in handler
    method(**attrs)
  File "/home/vid/makereport/DTPreport/pdf_report/utils.py", line 662, in image_start
    self.canvas.drawImage(src, **args)
  File "/home/vid/makereport/DTPreport/env/lib/python3.6/site-packages/reportlab/pdfgen/canvas.py", line 985, in drawImage
    imgObj = pdfdoc.PDFImageXObject(name, image, mask=mask)
  File "/home/vid/makereport/DTPreport/env/lib/python3.6/site-packages/reportlab/pdfbase/pdfdoc.py", line 2090, in __init__
    src = open_for_read(source)
  File "/home/vid/makereport/DTPreport/env/lib/python3.6/site-packages/reportlab/lib/utils.py", line 688, in open_for_read
    return open_for_read(name,mode)
  File "/home/vid/makereport/DTPreport/env/lib/python3.6/site-packages/reportlab/lib/utils.py", line 686, in open_for_read
    raise IOError('Cannot open resource "%s"' % name)
OSError: Cannot open resource "media/AAB.png"
[2021-02-25 09:49:05 +0000] [4702] [INFO] Worker exiting (pid: 4702)
[2021-02-25 09:49:05 +0000] [4700] [INFO] Handling signal: term
[2021-02-25 09:49:05 +0000] [4700] [INFO] Shutting down: Master
[2021-02-25 09:49:05 +0000] [5469] [INFO] Starting gunicorn 20.0.4
[2021-02-25 09:49:05 +0000] [5469] [INFO] Listening at: http://127.0.0.1:46710 (5469)
[2021-02-25 09:49:05 +0000] [5469] [INFO] Using worker: sync
[2021-02-25 09:49:05 +0000] [5471] [INFO] Booting worker with pid: 5471
Internal Server Error: /pdf/4/
Traceback (most recent call last):
  File "/home/vid/makereport/DTPreport/env/lib/python3.6/site-packages/reportlab/lib/utils.py", line 677, in open_for_read
    return open_for_read_by_name(name,mode)
  File "/home/vid/makereport/DTPreport/env/lib/python3.6/site-packages/reportlab/lib/utils.py", line 612, in open_for_read_by_name
    return open(name,mode)
FileNotFoundError: [Errno 2] No such file or directory: 'media/Cit.png'

During handling of the above exception, another exception occurred:

Traceback (most recent call last):
  File "/home/vid/makereport/DTPreport/env/lib/python3.6/site-packages/reportlab/lib/utils.py", line 684, in open_for_read
    return getBytesIO(datareader(name) if name[:5].lower()=='data:' else urlopen(name).read())
  File "/usr/lib/python3.6/urllib/request.py", line 223, in urlopen
    return opener.open(url, data, timeout)
  File "/usr/lib/python3.6/urllib/request.py", line 511, in open
    req = Request(fullurl, data)
  File "/usr/lib/python3.6/urllib/request.py", line 329, in __init__
    self.full_url = url
  File "/usr/lib/python3.6/urllib/request.py", line 355, in full_url
    self._parse()
  File "/usr/lib/python3.6/urllib/request.py", line 384, in _parse
    raise ValueError("unknown url type: %r" % self.full_url)
ValueError: unknown url type: 'media/Cit.png'

During handling of the above exception, another exception occurred:

Traceback (most recent call last):
  File "/home/vid/makereport/DTPreport/env/lib/python3.6/site-packages/django/core/handlers/exception.py", line 47, in inner
    response = get_response(request)
  File "/home/vid/makereport/DTPreport/env/lib/python3.6/site-packages/django/core/handlers/base.py", line 181, in _get_response
    response = wrapped_callback(request, *callback_args, **callback_kwargs)
  File "/home/vid/makereport/DTPreport/env/lib/python3.6/site-packages/django/views/generic/base.py", line 70, in view
    return self.dispatch(request, *args, **kwargs)
  File "/home/vid/makereport/DTPreport/env/lib/python3.6/site-packages/django/views/generic/base.py", line 98, in dispatch
    return handler(request, *args, **kwargs)
  File "/home/vid/makereport/DTPreport/pdf_report/views.py", line 26, in get
    pdf.generate(context)
  File "/home/vid/makereport/DTPreport/pdf_report/utils.py", line 602, in generate
    self.parse()
  File "/home/vid/makereport/DTPreport/pdf_report/utils.py", line 576, in parse
    self.parser.Parse(self.xml)
  File "../Modules/pyexpat.c", line 419, in StartElement
  File "/home/vid/makereport/DTPreport/pdf_report/utils.py", line 523, in handler
    method(**attrs)
  File "/home/vid/makereport/DTPreport/pdf_report/utils.py", line 662, in image_start
    self.canvas.drawImage(src, **args)
  File "/home/vid/makereport/DTPreport/env/lib/python3.6/site-packages/reportlab/pdfgen/canvas.py", line 985, in drawImage
    imgObj = pdfdoc.PDFImageXObject(name, image, mask=mask)
  File "/home/vid/makereport/DTPreport/env/lib/python3.6/site-packages/reportlab/pdfbase/pdfdoc.py", line 2090, in __init__
    src = open_for_read(source)
  File "/home/vid/makereport/DTPreport/env/lib/python3.6/site-packages/reportlab/lib/utils.py", line 688, in open_for_read
    return open_for_read(name,mode)
  File "/home/vid/makereport/DTPreport/env/lib/python3.6/site-packages/reportlab/lib/utils.py", line 686, in open_for_read
    raise IOError('Cannot open resource "%s"' % name)
OSError: Cannot open resource "media/Cit.png"
Not Found: /assets/js/bootstrap.min.js
Not Found: /assets/js/script.js
Not Found: /assets/js/script.js
Not Found: /assets/js/bootstrap.min.js
Not Found: /assets/js/script.js
Not Found: /assets/js/script.js
Not Found: /report/create/generic.html
Invalid HTTP_HOST header: '185.196.214.176'. You may need to add '185.196.214.176' to ALLOWED_HOSTS.
Bad Request: //a2billing/customer/templates/default/footer.tpl
Not Found: /assets/js/bootstrap.min.js
Not Found: /assets/js/script.js
Not Found: /assets/js/script.js
Not Found: /favicon.ico
Not Found: /favicon.ico
Invalid HTTP_HOST header: '185.196.214.176'. You may need to add '185.196.214.176' to ALLOWED_HOSTS.
Bad Request: /
Not Found: /robots.txt
Not Found: /accounts/login/
Invalid HTTP_HOST header: '185.196.214.176'. You may need to add '185.196.214.176' to ALLOWED_HOSTS.
Bad Request: /
Not Found: /accounts/login/
Invalid HTTP_HOST header: '185.196.214.176'. You may need to add '185.196.214.176' to ALLOWED_HOSTS.
Bad Request: /
Invalid HTTP_HOST header: '185.196.214.176'. You may need to add '185.196.214.176' to ALLOWED_HOSTS.
Bad Request: /admin//config.php
Invalid HTTP_HOST header: '185.196.214.176'. You may need to add '185.196.214.176' to ALLOWED_HOSTS.
Bad Request: /admin//config.php
Not Found: /robots.txt
Not Found: /accounts/login/
Not Found: /accounts/login/
Invalid HTTP_HOST header: '185.196.214.176'. You may need to add '185.196.214.176' to ALLOWED_HOSTS.
Bad Request: /
Invalid HTTP_HOST header: '185.196.214.176'. You may need to add '185.196.214.176' to ALLOWED_HOSTS.
Bad Request: /admin//config.php
Invalid HTTP_HOST header: '185.196.214.176'. You may need to add '185.196.214.176' to ALLOWED_HOSTS.
Bad Request: /
Not Found: /favicon.ico
Not Found: /favicon.ico
Invalid HTTP_HOST header: '185.196.214.176'. You may need to add '185.196.214.176' to ALLOWED_HOSTS.
Bad Request: /ews
Invalid HTTP_HOST header: '185.196.214.176'. You may need to add '185.196.214.176' to ALLOWED_HOSTS.
Bad Request: /
Not Found: /assets/js/bootstrap.min.js
Not Found: /assets/js/script.js
Not Found: /assets/js/script.js
Not Found: /favicon.ico
Not Found: /login/assets/js/bootstrap.min.js
Not Found: /login/assets/js/script.js
Not Found: /login/assets/js/bootstrap.min.js
Not Found: /login/assets/js/script.js
Not Found: /assets/js/bootstrap.min.js
Not Found: /assets/js/script.js
Not Found: /assets/js/bootstrap.min.js
Not Found: /assets/js/script.js
Not Found: /assets/js/script.js
Not Found: /favicon.ico
Not Found: /login/assets/js/bootstrap.min.js
Not Found: /login/assets/js/script.js
Not Found: /login/assets/js/bootstrap.min.js
Not Found: /login/assets/js/script.js
Not Found: /robots.txt
Not Found: /favicon.ico
Not Found: /report/create/generic.html
Not Found: /report/create/generic.html
Not Found: /assets/js/script.js
Not Found: /assets/js/bootstrap.min.js
Not Found: /assets/js/script.js
Not Found: /favicon.ico
Not Found: /assets/js/bootstrap.min.js
Not Found: /assets/js/script.js
Not Found: /assets/js/script.js
Not Found: /favicon.ico
Not Found: /login/assets/js/bootstrap.min.js
Not Found: /login/assets/js/script.js
Not Found: /assets/js/script.js
Not Found: /assets/js/bootstrap.min.js
Not Found: /assets/js/script.js
Not Found: /assets/js/bootstrap.min.js
Not Found: /assets/js/script.js
Not Found: /login/assets/js/bootstrap.min.js
Not Found: /login/assets/js/script.js
Not Found: /login/assets/js/bootstrap.min.js
Not Found: /login/assets/js/script.js
Not Found: /assets/js/bootstrap.min.js
Not Found: /assets/js/script.js
Not Found: /login/assets/js/bootstrap.min.js
Not Found: /login/assets/js/script.js
Not Found: /assets/js/bootstrap.min.js
Not Found: /assets/js/script.js
Not Found: /login/assets/js/bootstrap.min.js
Not Found: /login/assets/js/script.js
Not Found: /assets/js/bootstrap.min.js
Not Found: /assets/js/script.js
Not Found: /login/assets/js/bootstrap.min.js
Not Found: /login/assets/js/script.js
Not Found: /login/assets/js/bootstrap.min.js
Not Found: /login/assets/js/script.js
Not Found: /assets/js/bootstrap.min.js
Not Found: /assets/js/script.js
Not Found: /login/assets/js/bootstrap.min.js
Not Found: /login/assets/js/script.js
Not Found: /login/assets/js/bootstrap.min.js
Not Found: /login/assets/js/script.js
Not Found: /login/assets/js/bootstrap.min.js
Not Found: /login/assets/js/script.js
Not Found: /assets/js/bootstrap.min.js
Not Found: /assets/js/script.js
Not Found: /login/assets/js/bootstrap.min.js
Not Found: /login/assets/js/script.js
Not Found: /login/assets/js/bootstrap.min.js
Not Found: /login/assets/js/script.js
Invalid HTTP_HOST header: '185.196.214.176'. You may need to add '185.196.214.176' to ALLOWED_HOSTS.
Bad Request: /
Invalid HTTP_HOST header: '185.196.214.176'. You may need to add '185.196.214.176' to ALLOWED_HOSTS.
Bad Request: /
Not Found: /assets/js/bootstrap.min.js
Not Found: /assets/js/script.js
Not Found: /assets/js/bootstrap.min.js
Not Found: /assets/js/script.js
Not Found: /assets/js/bootstrap.min.js
Not Found: /assets/js/script.js
Invalid HTTP_HOST header: '185.196.214.176'. You may need to add '185.196.214.176' to ALLOWED_HOSTS.
Bad Request: /
Not Found: /aad7
Not Found: /aaa9
Invalid HTTP_HOST header: '185.196.214.176'. You may need to add '185.196.214.176' to ALLOWED_HOSTS.
Bad Request: /
Invalid HTTP_HOST header: '185.196.214.176'. You may need to add '185.196.214.176' to ALLOWED_HOSTS.
Bad Request: /
Invalid HTTP_HOST header: '185.196.214.176'. You may need to add '185.196.214.176' to ALLOWED_HOSTS.
Bad Request: /admin//config.php
Invalid HTTP_HOST header: '185.196.214.176'. You may need to add '185.196.214.176' to ALLOWED_HOSTS.
Bad Request: /
Not Found: /favicon.ico
Invalid HTTP_HOST header: '185.196.214.176'. You may need to add '185.196.214.176' to ALLOWED_HOSTS.
Bad Request: /
Invalid HTTP_HOST header: '185.196.214.176'. You may need to add '185.196.214.176' to ALLOWED_HOSTS.
Bad Request: /
Invalid HTTP_HOST header: '185.196.214.176'. You may need to add '185.196.214.176' to ALLOWED_HOSTS.
Bad Request: /
Invalid HTTP_HOST header: '185.196.214.176'. You may need to add '185.196.214.176' to ALLOWED_HOSTS.
Bad Request: /
Not Found: /assets/js/bootstrap.min.js
Not Found: /assets/js/script.js
Invalid HTTP_HOST header: '185.196.214.176'. You may need to add '185.196.214.176' to ALLOWED_HOSTS.
Bad Request: /se4Q
Not Found: /assets/js/bootstrap.min.js
Not Found: /assets/js/script.js
Not Found: /assets/js/script.js
Not Found: /favicon.ico
Not Found: /login/assets/js/bootstrap.min.js
Not Found: /login/assets/js/script.js
Not Found: /login/assets/js/script.js
Not Found: /login/assets/js/bootstrap.min.js
Not Found: /login/assets/js/script.js
Not Found: /login/assets/js/bootstrap.min.js
Not Found: /login/assets/js/script.js
Not Found: /report/create/generic.html
Not Found: /report/create/generic.html
Not Found: /report/create/generic.html
Internal Server Error: /report/ajax/get_service_ajax/
Traceback (most recent call last):
  File "/home/vid/makereport/DTPreport/env/lib/python3.6/site-packages/django/core/handlers/exception.py", line 47, in inner
    response = get_response(request)
  File "/home/vid/makereport/DTPreport/env/lib/python3.6/site-packages/django/core/handlers/base.py", line 181, in _get_response
    response = wrapped_callback(request, *callback_args, **callback_kwargs)
  File "/home/vid/makereport/DTPreport/makereport/utils.py", line 49, in get_service_ajax
    print(get_brand_nph(request))
  File "/home/vid/makereport/DTPreport/makereport/utils.py", line 114, in get_brand_nph
    norm_per_hour = service.BRANDS.get(brand).value_from_object(service)
AttributeError: 'NoneType' object has no attribute 'value_from_object'
Internal Server Error: /report/ajax/get_service_ajax/
Traceback (most recent call last):
  File "/home/vid/makereport/DTPreport/env/lib/python3.6/site-packages/django/core/handlers/exception.py", line 47, in inner
    response = get_response(request)
  File "/home/vid/makereport/DTPreport/env/lib/python3.6/site-packages/django/core/handlers/base.py", line 181, in _get_response
    response = wrapped_callback(request, *callback_args, **callback_kwargs)
  File "/home/vid/makereport/DTPreport/makereport/utils.py", line 49, in get_service_ajax
    print(get_brand_nph(request))
  File "/home/vid/makereport/DTPreport/makereport/utils.py", line 114, in get_brand_nph
    norm_per_hour = service.BRANDS.get(brand).value_from_object(service)
AttributeError: 'NoneType' object has no attribute 'value_from_object'
Not Found: /assets/js/bootstrap.min.js
Not Found: /assets/js/script.js
Not Found: /assets/js/script.js
Not Found: /favicon.ico
Not Found: /assets/js/bootstrap.min.js
Not Found: /assets/js/script.js
Not Found: /assets/js/script.js
Not Found: /favicon.ico
Not Found: /report/create/generic.html
Invalid HTTP_HOST header: '185.196.214.176'. You may need to add '185.196.214.176' to ALLOWED_HOSTS.
Bad Request: /admin//config.php
Not Found: /favicon.ico
Not Found: /assets/js/script.js
Not Found: /assets/js/bootstrap.min.js
Not Found: /assets/js/script.js
Not Found: /favicon.ico
Not Found: /robots.txt
Internal Server Error: /pdf/2/
Traceback (most recent call last):
  File "/home/vid/makereport/DTPreport/env/lib/python3.6/site-packages/django/core/handlers/exception.py", line 47, in inner
    response = get_response(request)
  File "/home/vid/makereport/DTPreport/env/lib/python3.6/site-packages/django/core/handlers/base.py", line 181, in _get_response
    response = wrapped_callback(request, *callback_args, **callback_kwargs)
  File "/home/vid/makereport/DTPreport/env/lib/python3.6/site-packages/django/views/generic/base.py", line 70, in view
    return self.dispatch(request, *args, **kwargs)
  File "/home/vid/makereport/DTPreport/env/lib/python3.6/site-packages/django/views/generic/base.py", line 98, in dispatch
    return handler(request, *args, **kwargs)
  File "/home/vid/makereport/DTPreport/pdf_report/views.py", line 17, in get
    new_report_pdf = Report.objects.get(report_id=id)
  File "/home/vid/makereport/DTPreport/env/lib/python3.6/site-packages/django/db/models/manager.py", line 85, in manager_method
    return getattr(self.get_queryset(), name)(*args, **kwargs)
  File "/home/vid/makereport/DTPreport/env/lib/python3.6/site-packages/django/db/models/query.py", line 431, in get
    self.model._meta.object_name
makereport.models.Report.DoesNotExist: Report matching query does not exist.
Not Found: /accounts/login/
Not Found: /robots.txt
Internal Server Error: /pdf/2/
Traceback (most recent call last):
  File "/home/vid/makereport/DTPreport/env/lib/python3.6/site-packages/django/core/handlers/exception.py", line 47, in inner
    response = get_response(request)
  File "/home/vid/makereport/DTPreport/env/lib/python3.6/site-packages/django/core/handlers/base.py", line 181, in _get_response
    response = wrapped_callback(request, *callback_args, **callback_kwargs)
  File "/home/vid/makereport/DTPreport/env/lib/python3.6/site-packages/django/views/generic/base.py", line 70, in view
    return self.dispatch(request, *args, **kwargs)
  File "/home/vid/makereport/DTPreport/env/lib/python3.6/site-packages/django/views/generic/base.py", line 98, in dispatch
    return handler(request, *args, **kwargs)
  File "/home/vid/makereport/DTPreport/pdf_report/views.py", line 17, in get
    new_report_pdf = Report.objects.get(report_id=id)
  File "/home/vid/makereport/DTPreport/env/lib/python3.6/site-packages/django/db/models/manager.py", line 85, in manager_method
    return getattr(self.get_queryset(), name)(*args, **kwargs)
  File "/home/vid/makereport/DTPreport/env/lib/python3.6/site-packages/django/db/models/query.py", line 431, in get
    self.model._meta.object_name
makereport.models.Report.DoesNotExist: Report matching query does not exist.
Internal Server Error: /pdf/2/
Traceback (most recent call last):
  File "/home/vid/makereport/DTPreport/env/lib/python3.6/site-packages/django/core/handlers/exception.py", line 47, in inner
    response = get_response(request)
  File "/home/vid/makereport/DTPreport/env/lib/python3.6/site-packages/django/core/handlers/base.py", line 181, in _get_response
    response = wrapped_callback(request, *callback_args, **callback_kwargs)
  File "/home/vid/makereport/DTPreport/env/lib/python3.6/site-packages/django/views/generic/base.py", line 70, in view
    return self.dispatch(request, *args, **kwargs)
  File "/home/vid/makereport/DTPreport/env/lib/python3.6/site-packages/django/views/generic/base.py", line 98, in dispatch
    return handler(request, *args, **kwargs)
  File "/home/vid/makereport/DTPreport/pdf_report/views.py", line 17, in get
    new_report_pdf = Report.objects.get(report_id=id)
  File "/home/vid/makereport/DTPreport/env/lib/python3.6/site-packages/django/db/models/manager.py", line 85, in manager_method
    return getattr(self.get_queryset(), name)(*args, **kwargs)
  File "/home/vid/makereport/DTPreport/env/lib/python3.6/site-packages/django/db/models/query.py", line 431, in get
    self.model._meta.object_name
makereport.models.Report.DoesNotExist: Report matching query does not exist.
Internal Server Error: /pdf/2/
Traceback (most recent call last):
  File "/home/vid/makereport/DTPreport/env/lib/python3.6/site-packages/django/core/handlers/exception.py", line 47, in inner
    response = get_response(request)
  File "/home/vid/makereport/DTPreport/env/lib/python3.6/site-packages/django/core/handlers/base.py", line 181, in _get_response
    response = wrapped_callback(request, *callback_args, **callback_kwargs)
  File "/home/vid/makereport/DTPreport/env/lib/python3.6/site-packages/django/views/generic/base.py", line 70, in view
    return self.dispatch(request, *args, **kwargs)
  File "/home/vid/makereport/DTPreport/env/lib/python3.6/site-packages/django/views/generic/base.py", line 98, in dispatch
    return handler(request, *args, **kwargs)
  File "/home/vid/makereport/DTPreport/pdf_report/views.py", line 17, in get
    new_report_pdf = Report.objects.get(report_id=id)
  File "/home/vid/makereport/DTPreport/env/lib/python3.6/site-packages/django/db/models/manager.py", line 85, in manager_method
    return getattr(self.get_queryset(), name)(*args, **kwargs)
  File "/home/vid/makereport/DTPreport/env/lib/python3.6/site-packages/django/db/models/query.py", line 431, in get
    self.model._meta.object_name
makereport.models.Report.DoesNotExist: Report matching query does not exist.
Invalid HTTP_HOST header: '185.196.214.176'. You may need to add '185.196.214.176' to ALLOWED_HOSTS.
Bad Request: /
Invalid HTTP_HOST header: '185.196.214.176'. You may need to add '185.196.214.176' to ALLOWED_HOSTS.
Bad Request: /admin//config.php
Invalid HTTP_HOST header: '185.196.214.176'. You may need to add '185.196.214.176' to ALLOWED_HOSTS.
Bad Request: /
Invalid HTTP_HOST header: '185.196.214.176'. You may need to add '185.196.214.176' to ALLOWED_HOSTS.
Bad Request: /dns-query
Invalid HTTP_HOST header: '185.196.214.176'. You may need to add '185.196.214.176' to ALLOWED_HOSTS.
Bad Request: /dns-query
Not Found: /robots.txt
Not Found: /favicon.ico
Invalid HTTP_HOST header: '185.196.214.176'. You may need to add '185.196.214.176' to ALLOWED_HOSTS.
Bad Request: /
Invalid HTTP_HOST header: '185.196.214.176'. You may need to add '185.196.214.176' to ALLOWED_HOSTS.
Bad Request: /
Invalid HTTP_HOST header: '185.196.214.176'. You may need to add '185.196.214.176' to ALLOWED_HOSTS.
Bad Request: /
Invalid HTTP_HOST header: '185.196.214.176'. You may need to add '185.196.214.176' to ALLOWED_HOSTS.
Bad Request: /
Invalid HTTP_HOST header: '185.196.214.176'. You may need to add '185.196.214.176' to ALLOWED_HOSTS.
Bad Request: /
Invalid HTTP_HOST header: '185.196.214.176'. You may need to add '185.196.214.176' to ALLOWED_HOSTS.
Bad Request: /
Invalid HTTP_HOST header: '185.196.214.176'. You may need to add '185.196.214.176' to ALLOWED_HOSTS.
Bad Request: /admin//config.php
Invalid HTTP_HOST header: '185.196.214.176'. You may need to add '185.196.214.176' to ALLOWED_HOSTS.
Bad Request: /
[2021-02-28 15:43:45 +0000] [5469] [INFO] Handling signal: term
[2021-02-28 15:43:45 +0000] [5471] [INFO] Worker exiting (pid: 5471)
[2021-02-28 15:43:45 +0000] [5469] [INFO] Shutting down: Master
[2021-02-28 15:43:46 +0000] [63122] [INFO] Starting gunicorn 20.0.4
[2021-02-28 15:43:46 +0000] [63122] [INFO] Listening at: http://127.0.0.1:46710 (63122)
[2021-02-28 15:43:46 +0000] [63122] [INFO] Using worker: sync
[2021-02-28 15:43:46 +0000] [63124] [INFO] Booting worker with pid: 63124
Internal Server Error: /robots.txt
Traceback (most recent call last):
  File "/home/vid/makereport/DTPreport/env/lib/python3.6/site-packages/django/core/handlers/exception.py", line 47, in inner
    response = get_response(request)
  File "/home/vid/makereport/DTPreport/env/lib/python3.6/site-packages/django/utils/deprecation.py", line 113, in __call__
    response = self.process_request(request)
  File "/home/vid/makereport/DTPreport/env/lib/python3.6/site-packages/django/middleware/common.py", line 53, in process_request
    if self.should_redirect_with_slash(request):
  File "/home/vid/makereport/DTPreport/env/lib/python3.6/site-packages/django/middleware/common.py", line 71, in should_redirect_with_slash
    not is_valid_path(request.path_info, urlconf) and
  File "/home/vid/makereport/DTPreport/env/lib/python3.6/site-packages/django/urls/base.py", line 154, in is_valid_path
    resolve(path, urlconf)
  File "/home/vid/makereport/DTPreport/env/lib/python3.6/site-packages/django/urls/base.py", line 25, in resolve
    return get_resolver(urlconf).resolve(path)
  File "/home/vid/makereport/DTPreport/env/lib/python3.6/site-packages/django/urls/resolvers.py", line 545, in resolve
    for pattern in self.url_patterns:
  File "/home/vid/makereport/DTPreport/env/lib/python3.6/site-packages/django/utils/functional.py", line 48, in __get__
    res = instance.__dict__[self.name] = self.func(instance)
  File "/home/vid/makereport/DTPreport/env/lib/python3.6/site-packages/django/urls/resolvers.py", line 589, in url_patterns
    patterns = getattr(self.urlconf_module, "urlpatterns", self.urlconf_module)
  File "/home/vid/makereport/DTPreport/env/lib/python3.6/site-packages/django/utils/functional.py", line 48, in __get__
    res = instance.__dict__[self.name] = self.func(instance)
  File "/home/vid/makereport/DTPreport/env/lib/python3.6/site-packages/django/urls/resolvers.py", line 582, in urlconf_module
    return import_module(self.urlconf_name)
  File "/usr/lib/python3.6/importlib/__init__.py", line 126, in import_module
    return _bootstrap._gcd_import(name[level:], package, level)
  File "<frozen importlib._bootstrap>", line 994, in _gcd_import
  File "<frozen importlib._bootstrap>", line 971, in _find_and_load
  File "<frozen importlib._bootstrap>", line 955, in _find_and_load_unlocked
  File "<frozen importlib._bootstrap>", line 665, in _load_unlocked
  File "<frozen importlib._bootstrap_external>", line 678, in exec_module
  File "<frozen importlib._bootstrap>", line 219, in _call_with_frames_removed
  File "/home/vid/makereport/DTPreport/DTPreport/urls.py", line 21, in <module>
    from makereport.views import user_login, user_logout, users_list, search
  File "/home/vid/makereport/DTPreport/makereport/views.py", line 14, in <module>
    from .utils import *
  File "/home/vid/makereport/DTPreport/makereport/utils.py", line 3, in <module>
    import requests
ModuleNotFoundError: No module named 'requests'
Internal Server Error: /pdf/2/
Traceback (most recent call last):
  File "/home/vid/makereport/DTPreport/env/lib/python3.6/site-packages/django/core/handlers/exception.py", line 47, in inner
    response = get_response(request)
  File "/home/vid/makereport/DTPreport/env/lib/python3.6/site-packages/django/core/handlers/base.py", line 167, in _get_response
    callback, callback_args, callback_kwargs = self.resolve_request(request)
  File "/home/vid/makereport/DTPreport/env/lib/python3.6/site-packages/django/core/handlers/base.py", line 290, in resolve_request
    resolver_match = resolver.resolve(request.path_info)
  File "/home/vid/makereport/DTPreport/env/lib/python3.6/site-packages/django/urls/resolvers.py", line 545, in resolve
    for pattern in self.url_patterns:
  File "/home/vid/makereport/DTPreport/env/lib/python3.6/site-packages/django/utils/functional.py", line 48, in __get__
    res = instance.__dict__[self.name] = self.func(instance)
  File "/home/vid/makereport/DTPreport/env/lib/python3.6/site-packages/django/urls/resolvers.py", line 589, in url_patterns
    patterns = getattr(self.urlconf_module, "urlpatterns", self.urlconf_module)
  File "/home/vid/makereport/DTPreport/env/lib/python3.6/site-packages/django/utils/functional.py", line 48, in __get__
    res = instance.__dict__[self.name] = self.func(instance)
  File "/home/vid/makereport/DTPreport/env/lib/python3.6/site-packages/django/urls/resolvers.py", line 582, in urlconf_module
    return import_module(self.urlconf_name)
  File "/usr/lib/python3.6/importlib/__init__.py", line 126, in import_module
    return _bootstrap._gcd_import(name[level:], package, level)
  File "<frozen importlib._bootstrap>", line 994, in _gcd_import
  File "<frozen importlib._bootstrap>", line 971, in _find_and_load
  File "<frozen importlib._bootstrap>", line 955, in _find_and_load_unlocked
  File "<frozen importlib._bootstrap>", line 665, in _load_unlocked
  File "<frozen importlib._bootstrap_external>", line 678, in exec_module
  File "<frozen importlib._bootstrap>", line 219, in _call_with_frames_removed
  File "/home/vid/makereport/DTPreport/DTPreport/urls.py", line 21, in <module>
    from makereport.views import user_login, user_logout, users_list, search
  File "/home/vid/makereport/DTPreport/makereport/views.py", line 14, in <module>
    from .utils import *
  File "/home/vid/makereport/DTPreport/makereport/utils.py", line 3, in <module>
    import requests
ModuleNotFoundError: No module named 'requests'
[2021-02-28 15:45:04 +0000] [63124] [INFO] Worker exiting (pid: 63124)
[2021-02-28 15:45:04 +0000] [63122] [INFO] Handling signal: term
[2021-02-28 15:45:04 +0000] [63122] [INFO] Shutting down: Master
[2021-02-28 15:45:05 +0000] [63159] [INFO] Starting gunicorn 20.0.4
[2021-02-28 15:45:05 +0000] [63159] [INFO] Listening at: http://127.0.0.1:46710 (63159)
[2021-02-28 15:45:05 +0000] [63159] [INFO] Using worker: sync
[2021-02-28 15:45:05 +0000] [63161] [INFO] Booting worker with pid: 63161
Not Found: /assets/js/bootstrap.min.js
Not Found: /assets/js/script.js
Not Found: /assets/js/script.js
Not Found: /favicon.ico
Not Found: /assets/js/bootstrap.min.js
Not Found: /assets/js/script.js
Not Found: /assets/js/bootstrap.min.js
Not Found: /assets/js/script.js
Not Found: /assets/js/script.js
[2021-02-28 15:55:35 +0000] [63159] [INFO] Handling signal: term
[2021-02-28 15:55:35 +0000] [63161] [INFO] Worker exiting (pid: 63161)
[2021-02-28 15:55:35 +0000] [63159] [INFO] Shutting down: Master
[2021-02-28 15:55:36 +0000] [63559] [INFO] Starting gunicorn 20.0.4
[2021-02-28 15:55:36 +0000] [63559] [INFO] Listening at: http://127.0.0.1:46710 (63559)
[2021-02-28 15:55:36 +0000] [63559] [INFO] Using worker: sync
[2021-02-28 15:55:36 +0000] [63561] [INFO] Booting worker with pid: 63561
[2021-02-28 15:56:37 +0000] [63561] [INFO] Worker exiting (pid: 63561)
[2021-02-28 15:56:37 +0000] [63559] [INFO] Handling signal: term
[2021-02-28 15:56:37 +0000] [63559] [INFO] Shutting down: Master
[2021-02-28 15:56:37 +0000] [63583] [INFO] Starting gunicorn 20.0.4
[2021-02-28 15:56:37 +0000] [63583] [INFO] Listening at: http://127.0.0.1:46710 (63583)
[2021-02-28 15:56:37 +0000] [63583] [INFO] Using worker: sync
[2021-02-28 15:56:37 +0000] [63585] [INFO] Booting worker with pid: 63585
[2021-02-28 16:03:31 +0000] [63585] [INFO] Worker exiting (pid: 63585)
[2021-02-28 16:03:31 +0000] [63583] [INFO] Handling signal: term
[2021-02-28 16:03:31 +0000] [63583] [INFO] Shutting down: Master
[2021-02-28 16:03:32 +0000] [63662] [INFO] Starting gunicorn 20.0.4
[2021-02-28 16:03:32 +0000] [63662] [INFO] Listening at: http://127.0.0.1:46710 (63662)
[2021-02-28 16:03:32 +0000] [63662] [INFO] Using worker: sync
[2021-02-28 16:03:32 +0000] [63664] [INFO] Booting worker with pid: 63664
Internal Server Error: /report/ajax/verifyPkcs7/
Traceback (most recent call last):
  File "/home/vid/makereport/DTPreport/env/lib/python3.6/site-packages/django/core/handlers/exception.py", line 47, in inner
    response = get_response(request)
  File "/home/vid/makereport/DTPreport/env/lib/python3.6/site-packages/django/core/handlers/base.py", line 181, in _get_response
    response = wrapped_callback(request, *callback_args, **callback_kwargs)
  File "/home/vid/makereport/DTPreport/makereport/utils.py", line 39, in verifyPkcs7
    get_verifyPkcs7(report_id)
TypeError: get_verifyPkcs7() missing 1 required positional argument: 'report_id'
Internal Server Error: /report/ajax/verifyPkcs7/
Traceback (most recent call last):
  File "/home/vid/makereport/DTPreport/env/lib/python3.6/site-packages/django/core/handlers/exception.py", line 47, in inner
    response = get_response(request)
  File "/home/vid/makereport/DTPreport/env/lib/python3.6/site-packages/django/core/handlers/base.py", line 181, in _get_response
    response = wrapped_callback(request, *callback_args, **callback_kwargs)
  File "/home/vid/makereport/DTPreport/makereport/utils.py", line 39, in verifyPkcs7
    get_verifyPkcs7(report_id)
TypeError: get_verifyPkcs7() missing 1 required positional argument: 'report_id'
Internal Server Error: /report/ajax/verifyPkcs7/
Traceback (most recent call last):
  File "/home/vid/makereport/DTPreport/env/lib/python3.6/site-packages/django/core/handlers/exception.py", line 47, in inner
    response = get_response(request)
  File "/home/vid/makereport/DTPreport/env/lib/python3.6/site-packages/django/core/handlers/base.py", line 181, in _get_response
    response = wrapped_callback(request, *callback_args, **callback_kwargs)
  File "/home/vid/makereport/DTPreport/makereport/utils.py", line 39, in verifyPkcs7
    get_verifyPkcs7(report_id)
TypeError: get_verifyPkcs7() missing 1 required positional argument: 'report_id'
Internal Server Error: /report/ajax/verifyPkcs7/
Traceback (most recent call last):
  File "/home/vid/makereport/DTPreport/env/lib/python3.6/site-packages/django/core/handlers/exception.py", line 47, in inner
    response = get_response(request)
  File "/home/vid/makereport/DTPreport/env/lib/python3.6/site-packages/django/core/handlers/base.py", line 181, in _get_response
    response = wrapped_callback(request, *callback_args, **callback_kwargs)
  File "/home/vid/makereport/DTPreport/makereport/utils.py", line 39, in verifyPkcs7
    get_verifyPkcs7(report_id)
TypeError: get_verifyPkcs7() missing 1 required positional argument: 'report_id'
Internal Server Error: /report/ajax/verifyPkcs7/
Traceback (most recent call last):
  File "/home/vid/makereport/DTPreport/env/lib/python3.6/site-packages/django/core/handlers/exception.py", line 47, in inner
    response = get_response(request)
  File "/home/vid/makereport/DTPreport/env/lib/python3.6/site-packages/django/core/handlers/base.py", line 181, in _get_response
    response = wrapped_callback(request, *callback_args, **callback_kwargs)
  File "/home/vid/makereport/DTPreport/makereport/utils.py", line 39, in verifyPkcs7
    get_verifyPkcs7(report_id)
TypeError: get_verifyPkcs7() missing 1 required positional argument: 'report_id'
Internal Server Error: /report/ajax/verifyPkcs7/
Traceback (most recent call last):
  File "/home/vid/makereport/DTPreport/env/lib/python3.6/site-packages/django/core/handlers/exception.py", line 47, in inner
    response = get_response(request)
  File "/home/vid/makereport/DTPreport/env/lib/python3.6/site-packages/django/core/handlers/base.py", line 181, in _get_response
    response = wrapped_callback(request, *callback_args, **callback_kwargs)
  File "/home/vid/makereport/DTPreport/makereport/utils.py", line 39, in verifyPkcs7
    get_verifyPkcs7(report_id)
TypeError: get_verifyPkcs7() missing 1 required positional argument: 'report_id'
Internal Server Error: /report/ajax/verifyPkcs7/
Traceback (most recent call last):
  File "/home/vid/makereport/DTPreport/env/lib/python3.6/site-packages/django/core/handlers/exception.py", line 47, in inner
    response = get_response(request)
  File "/home/vid/makereport/DTPreport/env/lib/python3.6/site-packages/django/core/handlers/base.py", line 181, in _get_response
    response = wrapped_callback(request, *callback_args, **callback_kwargs)
  File "/home/vid/makereport/DTPreport/makereport/utils.py", line 39, in verifyPkcs7
    get_verifyPkcs7(report_id)
TypeError: get_verifyPkcs7() missing 1 required positional argument: 'report_id'
[2021-02-28 16:05:11 +0000] [63662] [INFO] Handling signal: term
[2021-02-28 16:05:11 +0000] [63664] [INFO] Worker exiting (pid: 63664)
[2021-02-28 16:05:11 +0000] [63662] [INFO] Shutting down: Master
[2021-02-28 16:05:12 +0000] [63704] [INFO] Starting gunicorn 20.0.4
[2021-02-28 16:05:12 +0000] [63704] [INFO] Listening at: http://127.0.0.1:46710 (63704)
[2021-02-28 16:05:12 +0000] [63704] [INFO] Using worker: sync
[2021-02-28 16:05:12 +0000] [63706] [INFO] Booting worker with pid: 63706
Internal Server Error: /report/ajax/verifyPkcs7/
Traceback (most recent call last):
  File "/home/vid/makereport/DTPreport/env/lib/python3.6/site-packages/django/core/handlers/exception.py", line 47, in inner
    response = get_response(request)
  File "/home/vid/makereport/DTPreport/env/lib/python3.6/site-packages/django/core/handlers/base.py", line 181, in _get_response
    response = wrapped_callback(request, *callback_args, **callback_kwargs)
  File "/home/vid/makereport/DTPreport/makereport/utils.py", line 41, in verifyPkcs7
    get_verifyPkcs7(report_id)
TypeError: get_verifyPkcs7() missing 1 required positional argument: 'report_id'
[2021-02-28 16:08:16 +0000] [63706] [INFO] Worker exiting (pid: 63706)
[2021-02-28 16:08:16 +0000] [63704] [INFO] Handling signal: term
[2021-02-28 16:08:16 +0000] [63704] [INFO] Shutting down: Master
[2021-02-28 16:08:17 +0000] [63751] [INFO] Starting gunicorn 20.0.4
[2021-02-28 16:08:17 +0000] [63751] [INFO] Listening at: http://127.0.0.1:46710 (63751)
[2021-02-28 16:08:17 +0000] [63751] [INFO] Using worker: sync
[2021-02-28 16:08:17 +0000] [63753] [INFO] Booting worker with pid: 63753
Internal Server Error: /report/ajax/verifyPkcs7/
Traceback (most recent call last):
  File "/home/vid/makereport/DTPreport/env/lib/python3.6/site-packages/django/core/handlers/exception.py", line 47, in inner
    response = get_response(request)
  File "/home/vid/makereport/DTPreport/env/lib/python3.6/site-packages/django/core/handlers/base.py", line 181, in _get_response
    response = wrapped_callback(request, *callback_args, **callback_kwargs)
  File "/home/vid/makereport/DTPreport/makereport/utils.py", line 41, in verifyPkcs7
    get_verifyPkcs7(report_id)
  File "/home/vid/makereport/DTPreport/makereport/utils.py", line 10, in get_verifyPkcs7
    pkcs7 = report.pdf_report_pkcs
AttributeError: 'Report' object has no attribute 'pdf_report_pkcs'
[2021-02-28 16:10:02 +0000] [63753] [INFO] Worker exiting (pid: 63753)
[2021-02-28 16:10:02 +0000] [63751] [INFO] Handling signal: term
[2021-02-28 16:10:02 +0000] [63751] [INFO] Shutting down: Master
[2021-02-28 16:10:03 +0000] [63786] [INFO] Starting gunicorn 20.0.4
[2021-02-28 16:10:03 +0000] [63786] [INFO] Listening at: http://127.0.0.1:46710 (63786)
[2021-02-28 16:10:03 +0000] [63786] [INFO] Using worker: sync
[2021-02-28 16:10:03 +0000] [63788] [INFO] Booting worker with pid: 63788
[2021-02-28 16:14:50 +0000] [63788] [INFO] Worker exiting (pid: 63788)
[2021-02-28 16:14:50 +0000] [63786] [INFO] Handling signal: term
[2021-02-28 16:14:50 +0000] [63786] [INFO] Shutting down: Master
[2021-02-28 16:14:51 +0000] [63843] [INFO] Starting gunicorn 20.0.4
[2021-02-28 16:14:51 +0000] [63843] [INFO] Listening at: http://127.0.0.1:46710 (63843)
[2021-02-28 16:14:51 +0000] [63843] [INFO] Using worker: sync
[2021-02-28 16:14:51 +0000] [63845] [INFO] Booting worker with pid: 63845
Internal Server Error: /report/ajax/verifyPkcs7/
Traceback (most recent call last):
  File "/home/vid/makereport/DTPreport/env/lib/python3.6/site-packages/django/core/handlers/exception.py", line 47, in inner
    response = get_response(request)
  File "/home/vid/makereport/DTPreport/env/lib/python3.6/site-packages/django/core/handlers/base.py", line 181, in _get_response
    response = wrapped_callback(request, *callback_args, **callback_kwargs)
  File "/home/vid/makereport/DTPreport/makereport/utils.py", line 38, in verifyPkcs7
    get_verifyPkcs7(report_id)
  File "/home/vid/makereport/DTPreport/makereport/utils.py", line 26, in get_verifyPkcs7
    json.dump(response, f)
  File "/usr/lib/python3.6/json/__init__.py", line 179, in dump
    for chunk in iterable:
  File "/usr/lib/python3.6/json/encoder.py", line 437, in _iterencode
    o = _default(o)
  File "/usr/lib/python3.6/json/encoder.py", line 180, in default
    o.__class__.__name__)
TypeError: Object of type 'Response' is not JSON serializable
[2021-02-28 16:16:36 +0000] [63845] [INFO] Worker exiting (pid: 63845)
[2021-02-28 16:16:36 +0000] [63843] [INFO] Handling signal: term
[2021-02-28 16:16:36 +0000] [63843] [INFO] Shutting down: Master
[2021-02-28 16:16:36 +0000] [63889] [INFO] Starting gunicorn 20.0.4
[2021-02-28 16:16:36 +0000] [63889] [INFO] Listening at: http://127.0.0.1:46710 (63889)
[2021-02-28 16:16:36 +0000] [63889] [INFO] Using worker: sync
[2021-02-28 16:16:36 +0000] [63891] [INFO] Booting worker with pid: 63891
Internal Server Error: /report/ajax/verifyPkcs7/
Traceback (most recent call last):
  File "/home/vid/makereport/DTPreport/env/lib/python3.6/site-packages/django/core/handlers/exception.py", line 47, in inner
    response = get_response(request)
  File "/home/vid/makereport/DTPreport/env/lib/python3.6/site-packages/django/core/handlers/base.py", line 181, in _get_response
    response = wrapped_callback(request, *callback_args, **callback_kwargs)
  File "/home/vid/makereport/DTPreport/makereport/utils.py", line 38, in verifyPkcs7
    get_verifyPkcs7(report_id)
  File "/home/vid/makereport/DTPreport/makereport/utils.py", line 26, in get_verifyPkcs7
    json.dump(response.content, f)
  File "/usr/lib/python3.6/json/__init__.py", line 179, in dump
    for chunk in iterable:
  File "/usr/lib/python3.6/json/encoder.py", line 437, in _iterencode
    o = _default(o)
  File "/usr/lib/python3.6/json/encoder.py", line 180, in default
    o.__class__.__name__)
TypeError: Object of type 'bytes' is not JSON serializable
[2021-02-28 16:17:50 +0000] [63891] [INFO] Worker exiting (pid: 63891)
[2021-02-28 16:17:50 +0000] [63889] [INFO] Handling signal: term
[2021-02-28 16:17:50 +0000] [63889] [INFO] Shutting down: Master
[2021-02-28 16:17:51 +0000] [63929] [INFO] Starting gunicorn 20.0.4
[2021-02-28 16:17:51 +0000] [63929] [INFO] Listening at: http://127.0.0.1:46710 (63929)
[2021-02-28 16:17:51 +0000] [63929] [INFO] Using worker: sync
z[2021-02-28 16:17:51 +0000] [63931] [INFO] Booting worker with pid: 63931
[2021-02-28 16:22:08 +0000] [63929] [INFO] Handling signal: term
[2021-02-28 16:22:08 +0000] [63931] [INFO] Worker exiting (pid: 63931)
[2021-02-28 16:22:08 +0000] [63929] [INFO] Shutting down: Master
[2021-02-28 16:22:08 +0000] [63989] [INFO] Starting gunicorn 20.0.4
[2021-02-28 16:22:08 +0000] [63989] [INFO] Listening at: http://127.0.0.1:46710 (63989)
[2021-02-28 16:22:08 +0000] [63989] [INFO] Using worker: sync
[2021-02-28 16:22:08 +0000] [63991] [INFO] Booting worker with pid: 63991
[2021-02-28 16:22:54 +0000] [63989] [CRITICAL] WORKER TIMEOUT (pid:63991)
[2021-02-28 16:22:55 +0000] [63991] [INFO] Worker exiting (pid: 63991)
[2021-02-28 16:22:55 +0000] [64005] [INFO] Booting worker with pid: 64005
