[2021-03-11 11:57:49 +0000] [69871] [INFO] Starting gunicorn 20.0.4
[2021-03-11 11:57:49 +0000] [69871] [INFO] Listening at: http://127.0.0.1:46710 (69871)
[2021-03-11 11:57:49 +0000] [69871] [INFO] Using worker: sync
[2021-03-11 11:57:49 +0000] [69874] [INFO] Booting worker with pid: 69874
[2021-03-11 11:57:59 +0000] [69874] [INFO] Worker exiting (pid: 69874)
[2021-03-11 11:57:59 +0000] [69871] [INFO] Handling signal: term
[2021-03-11 11:57:59 +0000] [69871] [INFO] Shutting down: Master
[2021-03-11 11:58:01 +0000] [69879] [INFO] Starting gunicorn 20.0.4
[2021-03-11 11:58:01 +0000] [69879] [INFO] Listening at: http://127.0.0.1:46710 (69879)
[2021-03-11 11:58:01 +0000] [69879] [INFO] Using worker: sync
[2021-03-11 11:58:01 +0000] [69882] [INFO] Booting worker with pid: 69882
Internal Server Error: /report/ajax/verifyPkcs7/
Traceback (most recent call last):
  File "/home/vid/makereport/DTPreport/env/lib/python3.6/site-packages/django/core/handlers/exception.py", line 47, in inner
    response = get_response(request)
  File "/home/vid/makereport/DTPreport/env/lib/python3.6/site-packages/django/core/handlers/base.py", line 181, in _get_response
    response = wrapped_callback(request, *callback_args, **callback_kwargs)
  File "/home/vid/makereport/DTPreport/makereport/utils.py", line 102, in verifyPkcs7
    get_verifyPkcs7(report_id)
  File "/home/vid/makereport/DTPreport/makereport/utils.py", line 68, in get_verifyPkcs7
    signers = get_json["pkcs7Info"]["signers"][0]
KeyError: 'pkcs7Info'
Not Found: /robots.txt
[2021-03-11 12:16:12 +0000] [69882] [INFO] Worker exiting (pid: 69882)
[2021-03-11 12:16:12 +0000] [69879] [INFO] Handling signal: term
[2021-03-11 12:16:13 +0000] [69879] [INFO] Shutting down: Master
[2021-03-11 12:16:13 +0000] [70182] [INFO] Starting gunicorn 20.0.4
[2021-03-11 12:16:13 +0000] [70182] [INFO] Listening at: http://127.0.0.1:46710 (70182)
[2021-03-11 12:16:13 +0000] [70182] [INFO] Using worker: sync
[2021-03-11 12:16:13 +0000] [70185] [INFO] Booting worker with pid: 70185
Internal Server Error: /report/ajax/verifyPkcs7/
Traceback (most recent call last):
  File "/home/vid/makereport/DTPreport/env/lib/python3.6/site-packages/django/core/handlers/exception.py", line 47, in inner
    response = get_response(request)
  File "/home/vid/makereport/DTPreport/env/lib/python3.6/site-packages/django/core/handlers/base.py", line 181, in _get_response
    response = wrapped_callback(request, *callback_args, **callback_kwargs)
  File "/home/vid/makereport/DTPreport/makereport/utils.py", line 101, in verifyPkcs7
    get_verifyPkcs7(report_id)
  File "/home/vid/makereport/DTPreport/makereport/utils.py", line 67, in get_verifyPkcs7
    signers = get_json["pkcs7Info"]["signers"][0]
KeyError: 'pkcs7Info'
Internal Server Error: /report/ajax/verifyPkcs7/
Traceback (most recent call last):
  File "/home/vid/makereport/DTPreport/env/lib/python3.6/site-packages/django/core/handlers/exception.py", line 47, in inner
    response = get_response(request)
  File "/home/vid/makereport/DTPreport/env/lib/python3.6/site-packages/django/core/handlers/base.py", line 181, in _get_response
    response = wrapped_callback(request, *callback_args, **callback_kwargs)
  File "/home/vid/makereport/DTPreport/makereport/utils.py", line 101, in verifyPkcs7
    get_verifyPkcs7(report_id)
  File "/home/vid/makereport/DTPreport/makereport/utils.py", line 67, in get_verifyPkcs7
    signers = get_json["pkcs7Info"]["signers"][0]
KeyError: 'pkcs7Info'
[2021-03-11 12:29:18 +0000] [70182] [INFO] Handling signal: term
[2021-03-11 12:29:18 +0000] [70185] [INFO] Worker exiting (pid: 70185)
[2021-03-11 12:29:18 +0000] [70182] [INFO] Shutting down: Master
[2021-03-11 12:29:19 +0000] [70538] [INFO] Starting gunicorn 20.0.4
[2021-03-11 12:29:19 +0000] [70538] [INFO] Listening at: http://127.0.0.1:46710 (70538)
[2021-03-11 12:29:19 +0000] [70538] [INFO] Using worker: sync
[2021-03-11 12:29:19 +0000] [70541] [INFO] Booting worker with pid: 70541
Internal Server Error: /report/ajax/verifyPkcs7/
Traceback (most recent call last):
  File "/home/vid/makereport/DTPreport/env/lib/python3.6/site-packages/django/core/handlers/exception.py", line 47, in inner
    response = get_response(request)
  File "/home/vid/makereport/DTPreport/env/lib/python3.6/site-packages/django/core/handlers/base.py", line 181, in _get_response
    response = wrapped_callback(request, *callback_args, **callback_kwargs)
  File "/home/vid/makereport/DTPreport/makereport/utils.py", line 103, in verifyPkcs7
    get_verifyPkcs7(report_id)
  File "/home/vid/makereport/DTPreport/makereport/utils.py", line 69, in get_verifyPkcs7
    signers = get_json["pkcs7Info"]["signers"][0]
KeyError: 'pkcs7Info'
Internal Server Error: /report/ajax/verifyPkcs7/
Traceback (most recent call last):
  File "/home/vid/makereport/DTPreport/env/lib/python3.6/site-packages/django/core/handlers/exception.py", line 47, in inner
    response = get_response(request)
  File "/home/vid/makereport/DTPreport/env/lib/python3.6/site-packages/django/core/handlers/base.py", line 181, in _get_response
    response = wrapped_callback(request, *callback_args, **callback_kwargs)
  File "/home/vid/makereport/DTPreport/makereport/utils.py", line 103, in verifyPkcs7
    get_verifyPkcs7(report_id)
  File "/home/vid/makereport/DTPreport/makereport/utils.py", line 69, in get_verifyPkcs7
    signers = get_json["pkcs7Info"]["signers"][0]
KeyError: 'pkcs7Info'
[2021-03-11 12:32:54 +0000] [70538] [INFO] Handling signal: term
[2021-03-11 12:32:54 +0000] [70541] [INFO] Worker exiting (pid: 70541)
[2021-03-11 12:32:54 +0000] [70538] [INFO] Shutting down: Master
[2021-03-11 12:32:54 +0000] [70758] [INFO] Starting gunicorn 20.0.4
[2021-03-11 12:32:55 +0000] [70758] [INFO] Listening at: http://127.0.0.1:46710 (70758)
[2021-03-11 12:32:55 +0000] [70758] [INFO] Using worker: sync
[2021-03-11 12:32:55 +0000] [70761] [INFO] Booting worker with pid: 70761
[2021-03-11 12:34:03 +0000] [70761] [INFO] Worker exiting (pid: 70761)
[2021-03-11 12:34:03 +0000] [70758] [INFO] Handling signal: term
[2021-03-11 12:34:03 +0000] [70758] [INFO] Shutting down: Master
[2021-03-11 12:34:04 +0000] [70883] [INFO] Starting gunicorn 20.0.4
[2021-03-11 12:34:04 +0000] [70883] [INFO] Listening at: http://127.0.0.1:46710 (70883)
[2021-03-11 12:34:04 +0000] [70883] [INFO] Using worker: sync
[2021-03-11 12:34:04 +0000] [70886] [INFO] Booting worker with pid: 70886
Internal Server Error: /report/ajax/verifyPkcs7/
Traceback (most recent call last):
  File "/home/vid/makereport/DTPreport/env/lib/python3.6/site-packages/urllib3/connection.py", line 170, in _new_conn
    (self._dns_host, self.port), self.timeout, **extra_kw
  File "/home/vid/makereport/DTPreport/env/lib/python3.6/site-packages/urllib3/util/connection.py", line 96, in create_connection
    raise err
  File "/home/vid/makereport/DTPreport/env/lib/python3.6/site-packages/urllib3/util/connection.py", line 86, in create_connection
    sock.connect(sa)
ConnectionRefusedError: [Errno 111] Connection refused

During handling of the above exception, another exception occurred:

Traceback (most recent call last):
  File "/home/vid/makereport/DTPreport/env/lib/python3.6/site-packages/urllib3/connectionpool.py", line 706, in urlopen
    chunked=chunked,
  File "/home/vid/makereport/DTPreport/env/lib/python3.6/site-packages/urllib3/connectionpool.py", line 394, in _make_request
    conn.request(method, url, **httplib_request_kw)
  File "/home/vid/makereport/DTPreport/env/lib/python3.6/site-packages/urllib3/connection.py", line 234, in request
    super(HTTPConnection, self).request(method, url, body=body, headers=headers)
  File "/usr/lib/python3.6/http/client.py", line 1281, in request
    self._send_request(method, url, body, headers, encode_chunked)
  File "/usr/lib/python3.6/http/client.py", line 1327, in _send_request
    self.endheaders(body, encode_chunked=encode_chunked)
  File "/usr/lib/python3.6/http/client.py", line 1276, in endheaders
    self._send_output(message_body, encode_chunked=encode_chunked)
  File "/usr/lib/python3.6/http/client.py", line 1042, in _send_output
    self.send(msg)
  File "/usr/lib/python3.6/http/client.py", line 980, in send
    self.connect()
  File "/home/vid/makereport/DTPreport/env/lib/python3.6/site-packages/urllib3/connection.py", line 200, in connect
    conn = self._new_conn()
  File "/home/vid/makereport/DTPreport/env/lib/python3.6/site-packages/urllib3/connection.py", line 182, in _new_conn
    self, "Failed to establish a new connection: %s" % e
urllib3.exceptions.NewConnectionError: <urllib3.connection.HTTPConnection object at 0x7efe484b6198>: Failed to establish a new connection: [Errno 111] Connection refused

During handling of the above exception, another exception occurred:

Traceback (most recent call last):
  File "/home/vid/makereport/DTPreport/env/lib/python3.6/site-packages/requests/adapters.py", line 449, in send
    timeout=timeout
  File "/home/vid/makereport/DTPreport/env/lib/python3.6/site-packages/urllib3/connectionpool.py", line 756, in urlopen
    method, url, error=e, _pool=self, _stacktrace=sys.exc_info()[2]
  File "/home/vid/makereport/DTPreport/env/lib/python3.6/site-packages/urllib3/util/retry.py", line 573, in increment
    raise MaxRetryError(_pool, url, error or ResponseError(cause))
urllib3.exceptions.MaxRetryError: HTTPConnectionPool(host='127.0.0.1', port=9090): Max retries exceeded with url: /dsvs/pkcs7/v1?WSDL (Caused by NewConnectionError('<urllib3.connection.HTTPConnection object at 0x7efe484b6198>: Failed to establish a new connection: [Errno 111] Connection refused',))

During handling of the above exception, another exception occurred:

Traceback (most recent call last):
  File "/home/vid/makereport/DTPreport/env/lib/python3.6/site-packages/django/core/handlers/exception.py", line 47, in inner
    response = get_response(request)
  File "/home/vid/makereport/DTPreport/env/lib/python3.6/site-packages/django/core/handlers/base.py", line 181, in _get_response
    response = wrapped_callback(request, *callback_args, **callback_kwargs)
  File "/home/vid/makereport/DTPreport/makereport/utils.py", line 103, in verifyPkcs7
    get_verifyPkcs7(report_id)
  File "/home/vid/makereport/DTPreport/makereport/utils.py", line 49, in get_verifyPkcs7
    response = requests.post(url, data=body, headers=headers)
  File "/home/vid/makereport/DTPreport/env/lib/python3.6/site-packages/requests/api.py", line 119, in post
    return request('post', url, data=data, json=json, **kwargs)
  File "/home/vid/makereport/DTPreport/env/lib/python3.6/site-packages/requests/api.py", line 61, in request
    return session.request(method=method, url=url, **kwargs)
  File "/home/vid/makereport/DTPreport/env/lib/python3.6/site-packages/requests/sessions.py", line 542, in request
    resp = self.send(prep, **send_kwargs)
  File "/home/vid/makereport/DTPreport/env/lib/python3.6/site-packages/requests/sessions.py", line 655, in send
    r = adapter.send(request, **kwargs)
  File "/home/vid/makereport/DTPreport/env/lib/python3.6/site-packages/requests/adapters.py", line 516, in send
    raise ConnectionError(e, request=request)
requests.exceptions.ConnectionError: HTTPConnectionPool(host='127.0.0.1', port=9090): Max retries exceeded with url: /dsvs/pkcs7/v1?WSDL (Caused by NewConnectionError('<urllib3.connection.HTTPConnection object at 0x7efe484b6198>: Failed to establish a new connection: [Errno 111] Connection refused',))
Internal Server Error: /report/ajax/verifyPkcs7/
Traceback (most recent call last):
  File "/home/vid/makereport/DTPreport/env/lib/python3.6/site-packages/urllib3/connection.py", line 170, in _new_conn
    (self._dns_host, self.port), self.timeout, **extra_kw
  File "/home/vid/makereport/DTPreport/env/lib/python3.6/site-packages/urllib3/util/connection.py", line 96, in create_connection
    raise err
  File "/home/vid/makereport/DTPreport/env/lib/python3.6/site-packages/urllib3/util/connection.py", line 86, in create_connection
    sock.connect(sa)
ConnectionRefusedError: [Errno 111] Connection refused

During handling of the above exception, another exception occurred:

Traceback (most recent call last):
  File "/home/vid/makereport/DTPreport/env/lib/python3.6/site-packages/urllib3/connectionpool.py", line 706, in urlopen
    chunked=chunked,
  File "/home/vid/makereport/DTPreport/env/lib/python3.6/site-packages/urllib3/connectionpool.py", line 394, in _make_request
    conn.request(method, url, **httplib_request_kw)
  File "/home/vid/makereport/DTPreport/env/lib/python3.6/site-packages/urllib3/connection.py", line 234, in request
    super(HTTPConnection, self).request(method, url, body=body, headers=headers)
  File "/usr/lib/python3.6/http/client.py", line 1281, in request
    self._send_request(method, url, body, headers, encode_chunked)
  File "/usr/lib/python3.6/http/client.py", line 1327, in _send_request
    self.endheaders(body, encode_chunked=encode_chunked)
  File "/usr/lib/python3.6/http/client.py", line 1276, in endheaders
    self._send_output(message_body, encode_chunked=encode_chunked)
  File "/usr/lib/python3.6/http/client.py", line 1042, in _send_output
    self.send(msg)
  File "/usr/lib/python3.6/http/client.py", line 980, in send
    self.connect()
  File "/home/vid/makereport/DTPreport/env/lib/python3.6/site-packages/urllib3/connection.py", line 200, in connect
    conn = self._new_conn()
  File "/home/vid/makereport/DTPreport/env/lib/python3.6/site-packages/urllib3/connection.py", line 182, in _new_conn
    self, "Failed to establish a new connection: %s" % e
urllib3.exceptions.NewConnectionError: <urllib3.connection.HTTPConnection object at 0x7efe4839be80>: Failed to establish a new connection: [Errno 111] Connection refused

During handling of the above exception, another exception occurred:

Traceback (most recent call last):
  File "/home/vid/makereport/DTPreport/env/lib/python3.6/site-packages/requests/adapters.py", line 449, in send
    timeout=timeout
  File "/home/vid/makereport/DTPreport/env/lib/python3.6/site-packages/urllib3/connectionpool.py", line 756, in urlopen
    method, url, error=e, _pool=self, _stacktrace=sys.exc_info()[2]
  File "/home/vid/makereport/DTPreport/env/lib/python3.6/site-packages/urllib3/util/retry.py", line 573, in increment
    raise MaxRetryError(_pool, url, error or ResponseError(cause))
urllib3.exceptions.MaxRetryError: HTTPConnectionPool(host='127.0.0.1', port=9090): Max retries exceeded with url: /dsvs/pkcs7/v1?WSDL (Caused by NewConnectionError('<urllib3.connection.HTTPConnection object at 0x7efe4839be80>: Failed to establish a new connection: [Errno 111] Connection refused',))

During handling of the above exception, another exception occurred:

Traceback (most recent call last):
  File "/home/vid/makereport/DTPreport/env/lib/python3.6/site-packages/django/core/handlers/exception.py", line 47, in inner
    response = get_response(request)
  File "/home/vid/makereport/DTPreport/env/lib/python3.6/site-packages/django/core/handlers/base.py", line 181, in _get_response
    response = wrapped_callback(request, *callback_args, **callback_kwargs)
  File "/home/vid/makereport/DTPreport/makereport/utils.py", line 103, in verifyPkcs7
    get_verifyPkcs7(report_id)
  File "/home/vid/makereport/DTPreport/makereport/utils.py", line 49, in get_verifyPkcs7
    response = requests.post(url, data=body, headers=headers)
  File "/home/vid/makereport/DTPreport/env/lib/python3.6/site-packages/requests/api.py", line 119, in post
    return request('post', url, data=data, json=json, **kwargs)
  File "/home/vid/makereport/DTPreport/env/lib/python3.6/site-packages/requests/api.py", line 61, in request
    return session.request(method=method, url=url, **kwargs)
  File "/home/vid/makereport/DTPreport/env/lib/python3.6/site-packages/requests/sessions.py", line 542, in request
    resp = self.send(prep, **send_kwargs)
  File "/home/vid/makereport/DTPreport/env/lib/python3.6/site-packages/requests/sessions.py", line 655, in send
    r = adapter.send(request, **kwargs)
  File "/home/vid/makereport/DTPreport/env/lib/python3.6/site-packages/requests/adapters.py", line 516, in send
    raise ConnectionError(e, request=request)
requests.exceptions.ConnectionError: HTTPConnectionPool(host='127.0.0.1', port=9090): Max retries exceeded with url: /dsvs/pkcs7/v1?WSDL (Caused by NewConnectionError('<urllib3.connection.HTTPConnection object at 0x7efe4839be80>: Failed to establish a new connection: [Errno 111] Connection refused',))
[2021-03-11 12:34:37 +0000] [70886] [INFO] Worker exiting (pid: 70886)
[2021-03-11 12:34:37 +0000] [70883] [INFO] Handling signal: term
[2021-03-11 12:34:37 +0000] [70883] [INFO] Shutting down: Master
[2021-03-11 12:34:37 +0000] [70893] [INFO] Starting gunicorn 20.0.4
[2021-03-11 12:34:37 +0000] [70893] [INFO] Listening at: http://127.0.0.1:46710 (70893)
[2021-03-11 12:34:37 +0000] [70893] [INFO] Using worker: sync
[2021-03-11 12:34:37 +0000] [70896] [INFO] Booting worker with pid: 70896
[2021-03-11 12:34:47 +0000] [70896] [INFO] Worker exiting (pid: 70896)
[2021-03-11 12:34:47 +0000] [70893] [INFO] Handling signal: term
[2021-03-11 12:34:47 +0000] [70893] [INFO] Shutting down: Master
[2021-03-11 12:34:49 +0000] [70902] [INFO] Starting gunicorn 20.0.4
[2021-03-11 12:34:49 +0000] [70902] [INFO] Listening at: http://127.0.0.1:46710 (70902)
[2021-03-11 12:34:49 +0000] [70902] [INFO] Using worker: sync
[2021-03-11 12:34:49 +0000] [70905] [INFO] Booting worker with pid: 70905
Internal Server Error: /report/ajax/verifyPkcs7/
Traceback (most recent call last):
  File "/home/vid/makereport/DTPreport/env/lib/python3.6/site-packages/urllib3/connection.py", line 170, in _new_conn
    (self._dns_host, self.port), self.timeout, **extra_kw
  File "/home/vid/makereport/DTPreport/env/lib/python3.6/site-packages/urllib3/util/connection.py", line 96, in create_connection
    raise err
  File "/home/vid/makereport/DTPreport/env/lib/python3.6/site-packages/urllib3/util/connection.py", line 86, in create_connection
    sock.connect(sa)
ConnectionRefusedError: [Errno 111] Connection refused

During handling of the above exception, another exception occurred:

Traceback (most recent call last):
  File "/home/vid/makereport/DTPreport/env/lib/python3.6/site-packages/urllib3/connectionpool.py", line 706, in urlopen
    chunked=chunked,
  File "/home/vid/makereport/DTPreport/env/lib/python3.6/site-packages/urllib3/connectionpool.py", line 394, in _make_request
    conn.request(method, url, **httplib_request_kw)
  File "/home/vid/makereport/DTPreport/env/lib/python3.6/site-packages/urllib3/connection.py", line 234, in request
    super(HTTPConnection, self).request(method, url, body=body, headers=headers)
  File "/usr/lib/python3.6/http/client.py", line 1281, in request
    self._send_request(method, url, body, headers, encode_chunked)
  File "/usr/lib/python3.6/http/client.py", line 1327, in _send_request
    self.endheaders(body, encode_chunked=encode_chunked)
  File "/usr/lib/python3.6/http/client.py", line 1276, in endheaders
    self._send_output(message_body, encode_chunked=encode_chunked)
  File "/usr/lib/python3.6/http/client.py", line 1042, in _send_output
    self.send(msg)
  File "/usr/lib/python3.6/http/client.py", line 980, in send
    self.connect()
  File "/home/vid/makereport/DTPreport/env/lib/python3.6/site-packages/urllib3/connection.py", line 200, in connect
    conn = self._new_conn()
  File "/home/vid/makereport/DTPreport/env/lib/python3.6/site-packages/urllib3/connection.py", line 182, in _new_conn
    self, "Failed to establish a new connection: %s" % e
urllib3.exceptions.NewConnectionError: <urllib3.connection.HTTPConnection object at 0x7f976dcb5c88>: Failed to establish a new connection: [Errno 111] Connection refused

During handling of the above exception, another exception occurred:

Traceback (most recent call last):
  File "/home/vid/makereport/DTPreport/env/lib/python3.6/site-packages/requests/adapters.py", line 449, in send
    timeout=timeout
  File "/home/vid/makereport/DTPreport/env/lib/python3.6/site-packages/urllib3/connectionpool.py", line 756, in urlopen
    method, url, error=e, _pool=self, _stacktrace=sys.exc_info()[2]
  File "/home/vid/makereport/DTPreport/env/lib/python3.6/site-packages/urllib3/util/retry.py", line 573, in increment
    raise MaxRetryError(_pool, url, error or ResponseError(cause))
urllib3.exceptions.MaxRetryError: HTTPConnectionPool(host='127.0.0.1', port=9090): Max retries exceeded with url: /dsvs/pkcs7/v1?WSDL (Caused by NewConnectionError('<urllib3.connection.HTTPConnection object at 0x7f976dcb5c88>: Failed to establish a new connection: [Errno 111] Connection refused',))

During handling of the above exception, another exception occurred:

Traceback (most recent call last):
  File "/home/vid/makereport/DTPreport/env/lib/python3.6/site-packages/django/core/handlers/exception.py", line 47, in inner
    response = get_response(request)
  File "/home/vid/makereport/DTPreport/env/lib/python3.6/site-packages/django/core/handlers/base.py", line 181, in _get_response
    response = wrapped_callback(request, *callback_args, **callback_kwargs)
  File "/home/vid/makereport/DTPreport/makereport/utils.py", line 103, in verifyPkcs7
    get_verifyPkcs7(report_id)
  File "/home/vid/makereport/DTPreport/makereport/utils.py", line 49, in get_verifyPkcs7
    response = requests.post(url, data=body, headers=headers)
  File "/home/vid/makereport/DTPreport/env/lib/python3.6/site-packages/requests/api.py", line 119, in post
    return request('post', url, data=data, json=json, **kwargs)
  File "/home/vid/makereport/DTPreport/env/lib/python3.6/site-packages/requests/api.py", line 61, in request
    return session.request(method=method, url=url, **kwargs)
  File "/home/vid/makereport/DTPreport/env/lib/python3.6/site-packages/requests/sessions.py", line 542, in request
    resp = self.send(prep, **send_kwargs)
  File "/home/vid/makereport/DTPreport/env/lib/python3.6/site-packages/requests/sessions.py", line 655, in send
    r = adapter.send(request, **kwargs)
  File "/home/vid/makereport/DTPreport/env/lib/python3.6/site-packages/requests/adapters.py", line 516, in send
    raise ConnectionError(e, request=request)
requests.exceptions.ConnectionError: HTTPConnectionPool(host='127.0.0.1', port=9090): Max retries exceeded with url: /dsvs/pkcs7/v1?WSDL (Caused by NewConnectionError('<urllib3.connection.HTTPConnection object at 0x7f976dcb5c88>: Failed to establish a new connection: [Errno 111] Connection refused',))
Internal Server Error: /report/ajax/verifyPkcs7/
Traceback (most recent call last):
  File "/home/vid/makereport/DTPreport/env/lib/python3.6/site-packages/urllib3/connection.py", line 170, in _new_conn
    (self._dns_host, self.port), self.timeout, **extra_kw
  File "/home/vid/makereport/DTPreport/env/lib/python3.6/site-packages/urllib3/util/connection.py", line 96, in create_connection
    raise err
  File "/home/vid/makereport/DTPreport/env/lib/python3.6/site-packages/urllib3/util/connection.py", line 86, in create_connection
    sock.connect(sa)
ConnectionRefusedError: [Errno 111] Connection refused

During handling of the above exception, another exception occurred:

Traceback (most recent call last):
  File "/home/vid/makereport/DTPreport/env/lib/python3.6/site-packages/urllib3/connectionpool.py", line 706, in urlopen
    chunked=chunked,
  File "/home/vid/makereport/DTPreport/env/lib/python3.6/site-packages/urllib3/connectionpool.py", line 394, in _make_request
    conn.request(method, url, **httplib_request_kw)
  File "/home/vid/makereport/DTPreport/env/lib/python3.6/site-packages/urllib3/connection.py", line 234, in request
    super(HTTPConnection, self).request(method, url, body=body, headers=headers)
  File "/usr/lib/python3.6/http/client.py", line 1281, in request
    self._send_request(method, url, body, headers, encode_chunked)
  File "/usr/lib/python3.6/http/client.py", line 1327, in _send_request
    self.endheaders(body, encode_chunked=encode_chunked)
  File "/usr/lib/python3.6/http/client.py", line 1276, in endheaders
    self._send_output(message_body, encode_chunked=encode_chunked)
  File "/usr/lib/python3.6/http/client.py", line 1042, in _send_output
    self.send(msg)
  File "/usr/lib/python3.6/http/client.py", line 980, in send
    self.connect()
  File "/home/vid/makereport/DTPreport/env/lib/python3.6/site-packages/urllib3/connection.py", line 200, in connect
    conn = self._new_conn()
  File "/home/vid/makereport/DTPreport/env/lib/python3.6/site-packages/urllib3/connection.py", line 182, in _new_conn
    self, "Failed to establish a new connection: %s" % e
urllib3.exceptions.NewConnectionError: <urllib3.connection.HTTPConnection object at 0x7f976dbade48>: Failed to establish a new connection: [Errno 111] Connection refused

During handling of the above exception, another exception occurred:

Traceback (most recent call last):
  File "/home/vid/makereport/DTPreport/env/lib/python3.6/site-packages/requests/adapters.py", line 449, in send
    timeout=timeout
  File "/home/vid/makereport/DTPreport/env/lib/python3.6/site-packages/urllib3/connectionpool.py", line 756, in urlopen
    method, url, error=e, _pool=self, _stacktrace=sys.exc_info()[2]
  File "/home/vid/makereport/DTPreport/env/lib/python3.6/site-packages/urllib3/util/retry.py", line 573, in increment
    raise MaxRetryError(_pool, url, error or ResponseError(cause))
urllib3.exceptions.MaxRetryError: HTTPConnectionPool(host='127.0.0.1', port=9090): Max retries exceeded with url: /dsvs/pkcs7/v1?WSDL (Caused by NewConnectionError('<urllib3.connection.HTTPConnection object at 0x7f976dbade48>: Failed to establish a new connection: [Errno 111] Connection refused',))

During handling of the above exception, another exception occurred:

Traceback (most recent call last):
  File "/home/vid/makereport/DTPreport/env/lib/python3.6/site-packages/django/core/handlers/exception.py", line 47, in inner
    response = get_response(request)
  File "/home/vid/makereport/DTPreport/env/lib/python3.6/site-packages/django/core/handlers/base.py", line 181, in _get_response
    response = wrapped_callback(request, *callback_args, **callback_kwargs)
  File "/home/vid/makereport/DTPreport/makereport/utils.py", line 103, in verifyPkcs7
    get_verifyPkcs7(report_id)
  File "/home/vid/makereport/DTPreport/makereport/utils.py", line 49, in get_verifyPkcs7
    response = requests.post(url, data=body, headers=headers)
  File "/home/vid/makereport/DTPreport/env/lib/python3.6/site-packages/requests/api.py", line 119, in post
    return request('post', url, data=data, json=json, **kwargs)
  File "/home/vid/makereport/DTPreport/env/lib/python3.6/site-packages/requests/api.py", line 61, in request
    return session.request(method=method, url=url, **kwargs)
  File "/home/vid/makereport/DTPreport/env/lib/python3.6/site-packages/requests/sessions.py", line 542, in request
    resp = self.send(prep, **send_kwargs)
  File "/home/vid/makereport/DTPreport/env/lib/python3.6/site-packages/requests/sessions.py", line 655, in send
    r = adapter.send(request, **kwargs)
  File "/home/vid/makereport/DTPreport/env/lib/python3.6/site-packages/requests/adapters.py", line 516, in send
    raise ConnectionError(e, request=request)
requests.exceptions.ConnectionError: HTTPConnectionPool(host='127.0.0.1', port=9090): Max retries exceeded with url: /dsvs/pkcs7/v1?WSDL (Caused by NewConnectionError('<urllib3.connection.HTTPConnection object at 0x7f976dbade48>: Failed to establish a new connection: [Errno 111] Connection refused',))
Internal Server Error: /report/ajax/verifyPkcs7/
Traceback (most recent call last):
  File "/home/vid/makereport/DTPreport/env/lib/python3.6/site-packages/urllib3/connection.py", line 170, in _new_conn
    (self._dns_host, self.port), self.timeout, **extra_kw
  File "/home/vid/makereport/DTPreport/env/lib/python3.6/site-packages/urllib3/util/connection.py", line 96, in create_connection
    raise err
  File "/home/vid/makereport/DTPreport/env/lib/python3.6/site-packages/urllib3/util/connection.py", line 86, in create_connection
    sock.connect(sa)
ConnectionRefusedError: [Errno 111] Connection refused

During handling of the above exception, another exception occurred:

Traceback (most recent call last):
  File "/home/vid/makereport/DTPreport/env/lib/python3.6/site-packages/urllib3/connectionpool.py", line 706, in urlopen
    chunked=chunked,
  File "/home/vid/makereport/DTPreport/env/lib/python3.6/site-packages/urllib3/connectionpool.py", line 394, in _make_request
    conn.request(method, url, **httplib_request_kw)
  File "/home/vid/makereport/DTPreport/env/lib/python3.6/site-packages/urllib3/connection.py", line 234, in request
    super(HTTPConnection, self).request(method, url, body=body, headers=headers)
  File "/usr/lib/python3.6/http/client.py", line 1281, in request
    self._send_request(method, url, body, headers, encode_chunked)
  File "/usr/lib/python3.6/http/client.py", line 1327, in _send_request
    self.endheaders(body, encode_chunked=encode_chunked)
  File "/usr/lib/python3.6/http/client.py", line 1276, in endheaders
    self._send_output(message_body, encode_chunked=encode_chunked)
  File "/usr/lib/python3.6/http/client.py", line 1042, in _send_output
    self.send(msg)
  File "/usr/lib/python3.6/http/client.py", line 980, in send
    self.connect()
  File "/home/vid/makereport/DTPreport/env/lib/python3.6/site-packages/urllib3/connection.py", line 200, in connect
    conn = self._new_conn()
  File "/home/vid/makereport/DTPreport/env/lib/python3.6/site-packages/urllib3/connection.py", line 182, in _new_conn
    self, "Failed to establish a new connection: %s" % e
urllib3.exceptions.NewConnectionError: <urllib3.connection.HTTPConnection object at 0x7f976dbcf940>: Failed to establish a new connection: [Errno 111] Connection refused

During handling of the above exception, another exception occurred:

Traceback (most recent call last):
  File "/home/vid/makereport/DTPreport/env/lib/python3.6/site-packages/requests/adapters.py", line 449, in send
    timeout=timeout
  File "/home/vid/makereport/DTPreport/env/lib/python3.6/site-packages/urllib3/connectionpool.py", line 756, in urlopen
    method, url, error=e, _pool=self, _stacktrace=sys.exc_info()[2]
  File "/home/vid/makereport/DTPreport/env/lib/python3.6/site-packages/urllib3/util/retry.py", line 573, in increment
    raise MaxRetryError(_pool, url, error or ResponseError(cause))
urllib3.exceptions.MaxRetryError: HTTPConnectionPool(host='127.0.0.1', port=9090): Max retries exceeded with url: /dsvs/pkcs7/v1?WSDL (Caused by NewConnectionError('<urllib3.connection.HTTPConnection object at 0x7f976dbcf940>: Failed to establish a new connection: [Errno 111] Connection refused',))

During handling of the above exception, another exception occurred:

Traceback (most recent call last):
  File "/home/vid/makereport/DTPreport/env/lib/python3.6/site-packages/django/core/handlers/exception.py", line 47, in inner
    response = get_response(request)
  File "/home/vid/makereport/DTPreport/env/lib/python3.6/site-packages/django/core/handlers/base.py", line 181, in _get_response
    response = wrapped_callback(request, *callback_args, **callback_kwargs)
  File "/home/vid/makereport/DTPreport/makereport/utils.py", line 103, in verifyPkcs7
    get_verifyPkcs7(report_id)
  File "/home/vid/makereport/DTPreport/makereport/utils.py", line 49, in get_verifyPkcs7
    response = requests.post(url, data=body, headers=headers)
  File "/home/vid/makereport/DTPreport/env/lib/python3.6/site-packages/requests/api.py", line 119, in post
    return request('post', url, data=data, json=json, **kwargs)
  File "/home/vid/makereport/DTPreport/env/lib/python3.6/site-packages/requests/api.py", line 61, in request
    return session.request(method=method, url=url, **kwargs)
  File "/home/vid/makereport/DTPreport/env/lib/python3.6/site-packages/requests/sessions.py", line 542, in request
    resp = self.send(prep, **send_kwargs)
  File "/home/vid/makereport/DTPreport/env/lib/python3.6/site-packages/requests/sessions.py", line 655, in send
    r = adapter.send(request, **kwargs)
  File "/home/vid/makereport/DTPreport/env/lib/python3.6/site-packages/requests/adapters.py", line 516, in send
    raise ConnectionError(e, request=request)
requests.exceptions.ConnectionError: HTTPConnectionPool(host='127.0.0.1', port=9090): Max retries exceeded with url: /dsvs/pkcs7/v1?WSDL (Caused by NewConnectionError('<urllib3.connection.HTTPConnection object at 0x7f976dbcf940>: Failed to establish a new connection: [Errno 111] Connection refused',))
Internal Server Error: /report/ajax/verifyPkcs7/
Traceback (most recent call last):
  File "/home/vid/makereport/DTPreport/env/lib/python3.6/site-packages/django/core/handlers/exception.py", line 47, in inner
    response = get_response(request)
  File "/home/vid/makereport/DTPreport/env/lib/python3.6/site-packages/django/core/handlers/base.py", line 181, in _get_response
    response = wrapped_callback(request, *callback_args, **callback_kwargs)
  File "/home/vid/makereport/DTPreport/makereport/utils.py", line 103, in verifyPkcs7
    get_verifyPkcs7(report_id)
  File "/home/vid/makereport/DTPreport/makereport/utils.py", line 86, in get_verifyPkcs7
    report.pdf_qr_code_user = qr_code(success, signature, signAlgName, statusUpdateAt, LINK,serialNumber)
  File "/home/vid/makereport/DTPreport/makereport/utils.py", line 11, in qr_code
    success=success, signature=signature, signAlgName=signAlgName, updateAt=updateAt, link=link)
KeyError: 'serialNumber'
Internal Server Error: /report/ajax/verifyPkcs7/
Traceback (most recent call last):
  File "/home/vid/makereport/DTPreport/env/lib/python3.6/site-packages/django/core/handlers/exception.py", line 47, in inner
    response = get_response(request)
  File "/home/vid/makereport/DTPreport/env/lib/python3.6/site-packages/django/core/handlers/base.py", line 181, in _get_response
    response = wrapped_callback(request, *callback_args, **callback_kwargs)
  File "/home/vid/makereport/DTPreport/makereport/utils.py", line 103, in verifyPkcs7
    get_verifyPkcs7(report_id)
  File "/home/vid/makereport/DTPreport/makereport/utils.py", line 86, in get_verifyPkcs7
    report.pdf_qr_code_user = qr_code(success, signature, signAlgName, statusUpdateAt, LINK,serialNumber)
  File "/home/vid/makereport/DTPreport/makereport/utils.py", line 11, in qr_code
    success=success, signature=signature, signAlgName=signAlgName, updateAt=updateAt, link=link)
KeyError: 'serialNumber'
[2021-03-11 12:45:34 +0000] [70902] [INFO] Handling signal: term
[2021-03-11 12:45:34 +0000] [70905] [INFO] Worker exiting (pid: 70905)
[2021-03-11 12:45:35 +0000] [70902] [INFO] Shutting down: Master
[2021-03-11 12:45:35 +0000] [71160] [INFO] Starting gunicorn 20.0.4
[2021-03-11 12:45:35 +0000] [71160] [INFO] Listening at: http://127.0.0.1:46710 (71160)
[2021-03-11 12:45:35 +0000] [71160] [INFO] Using worker: sync
[2021-03-11 12:45:35 +0000] [71163] [INFO] Booting worker with pid: 71163
Internal Server Error: /report/ajax/verifyPkcs7/
Traceback (most recent call last):
  File "/home/vid/makereport/DTPreport/env/lib/python3.6/site-packages/django/core/handlers/exception.py", line 47, in inner
    response = get_response(request)
  File "/home/vid/makereport/DTPreport/env/lib/python3.6/site-packages/django/core/handlers/base.py", line 181, in _get_response
    response = wrapped_callback(request, *callback_args, **callback_kwargs)
  File "/home/vid/makereport/DTPreport/makereport/utils.py", line 103, in verifyPkcs7
    get_verifyPkcs7(report_id)
  File "/home/vid/makereport/DTPreport/makereport/utils.py", line 78, in get_verifyPkcs7
    statusUpdateAt = signers['statusUpdatedAt']
KeyError: 'statusUpdatedAt'
Internal Server Error: /report/ajax/verifyPkcs7/
Traceback (most recent call last):
  File "/home/vid/makereport/DTPreport/env/lib/python3.6/site-packages/django/core/handlers/exception.py", line 47, in inner
    response = get_response(request)
  File "/home/vid/makereport/DTPreport/env/lib/python3.6/site-packages/django/core/handlers/base.py", line 181, in _get_response
    response = wrapped_callback(request, *callback_args, **callback_kwargs)
  File "/home/vid/makereport/DTPreport/makereport/utils.py", line 103, in verifyPkcs7
    get_verifyPkcs7(report_id)
  File "/home/vid/makereport/DTPreport/makereport/utils.py", line 78, in get_verifyPkcs7
    statusUpdateAt = signers['statusUpdatedAt']
KeyError: 'statusUpdatedAt'
Internal Server Error: /report/ajax/verifyPkcs7/
Traceback (most recent call last):
  File "/home/vid/makereport/DTPreport/env/lib/python3.6/site-packages/django/core/handlers/exception.py", line 47, in inner
    response = get_response(request)
  File "/home/vid/makereport/DTPreport/env/lib/python3.6/site-packages/django/core/handlers/base.py", line 181, in _get_response
    response = wrapped_callback(request, *callback_args, **callback_kwargs)
  File "/home/vid/makereport/DTPreport/makereport/utils.py", line 103, in verifyPkcs7
    }
  File "/home/vid/makereport/DTPreport/makereport/utils.py", line 78, in get_verifyPkcs7
KeyError: 'statusUpdatedAt'
Internal Server Error: /report/ajax/verifyPkcs7/
Traceback (most recent call last):
  File "/home/vid/makereport/DTPreport/env/lib/python3.6/site-packages/django/core/handlers/exception.py", line 47, in inner
    response = get_response(request)
  File "/home/vid/makereport/DTPreport/env/lib/python3.6/site-packages/django/core/handlers/base.py", line 181, in _get_response
    response = wrapped_callback(request, *callback_args, **callback_kwargs)
  File "/home/vid/makereport/DTPreport/makereport/utils.py", line 103, in verifyPkcs7
    }
  File "/home/vid/makereport/DTPreport/makereport/utils.py", line 78, in get_verifyPkcs7
KeyError: 'statusUpdatedAt'
[2021-03-11 12:54:46 +0000] [71160] [INFO] Handling signal: term
[2021-03-11 12:54:46 +0000] [71163] [INFO] Worker exiting (pid: 71163)
[2021-03-11 12:54:46 +0000] [71160] [INFO] Shutting down: Master
[2021-03-11 12:54:46 +0000] [71349] [INFO] Starting gunicorn 20.0.4
[2021-03-11 12:54:46 +0000] [71349] [INFO] Listening at: http://127.0.0.1:46710 (71349)
[2021-03-11 12:54:46 +0000] [71349] [INFO] Using worker: sync
[2021-03-11 12:54:46 +0000] [71352] [INFO] Booting worker with pid: 71352
Internal Server Error: /pdf/11/
Traceback (most recent call last):
  File "/home/vid/makereport/DTPreport/env/lib/python3.6/site-packages/django/core/handlers/exception.py", line 47, in inner
    response = get_response(request)
  File "/home/vid/makereport/DTPreport/env/lib/python3.6/site-packages/django/core/handlers/base.py", line 181, in _get_response
    response = wrapped_callback(request, *callback_args, **callback_kwargs)
  File "/home/vid/makereport/DTPreport/env/lib/python3.6/site-packages/django/views/generic/base.py", line 70, in view
    return self.dispatch(request, *args, **kwargs)
  File "/home/vid/makereport/DTPreport/env/lib/python3.6/site-packages/django/views/generic/base.py", line 98, in dispatch
    return handler(request, *args, **kwargs)
  File "/home/vid/makereport/DTPreport/pdf_report/views.py", line 16, in get
    get_response(request, id)
  File "/home/vid/makereport/DTPreport/pdf_report/views.py", line 42, in get_response
    pdf.generate(context)
  File "/home/vid/makereport/DTPreport/pdf_report/utils.py", line 602, in generate
    self.parse()
  File "/home/vid/makereport/DTPreport/pdf_report/utils.py", line 576, in parse
    self.parser.Parse(self.xml)
  File "../Modules/pyexpat.c", line 284, in CharacterData
  File "/home/vid/makereport/DTPreport/pdf_report/utils.py", line 560, in handler
    method(cdata)
  File "/home/vid/makereport/DTPreport/pdf_report/utils.py", line 668, in barcode_cdata
    b = self.barcode_stack.pop()
IndexError: pop from empty list
Not Found: /assets/js/bootstrap.min.js
Not Found: /assets/js/script.js
Not Found: /assets/js/script.js
Internal Server Error: /pdf/11/
Traceback (most recent call last):
  File "/home/vid/makereport/DTPreport/env/lib/python3.6/site-packages/django/core/handlers/exception.py", line 47, in inner
    response = get_response(request)
  File "/home/vid/makereport/DTPreport/env/lib/python3.6/site-packages/django/core/handlers/base.py", line 181, in _get_response
    response = wrapped_callback(request, *callback_args, **callback_kwargs)
  File "/home/vid/makereport/DTPreport/env/lib/python3.6/site-packages/django/views/generic/base.py", line 70, in view
    return self.dispatch(request, *args, **kwargs)
  File "/home/vid/makereport/DTPreport/env/lib/python3.6/site-packages/django/views/generic/base.py", line 98, in dispatch
    return handler(request, *args, **kwargs)
  File "/home/vid/makereport/DTPreport/pdf_report/views.py", line 16, in get
    get_response(request, id)
  File "/home/vid/makereport/DTPreport/pdf_report/views.py", line 42, in get_response
    pdf.generate(context)
  File "/home/vid/makereport/DTPreport/pdf_report/utils.py", line 602, in generate
    self.parse()
  File "/home/vid/makereport/DTPreport/pdf_report/utils.py", line 576, in parse
    self.parser.Parse(self.xml)
  File "../Modules/pyexpat.c", line 284, in CharacterData
  File "/home/vid/makereport/DTPreport/pdf_report/utils.py", line 560, in handler
    method(cdata)
  File "/home/vid/makereport/DTPreport/pdf_report/utils.py", line 668, in barcode_cdata
    b = self.barcode_stack.pop()
IndexError: pop from empty list
Internal Server Error: /report/ajax/verifyPkcs7/
Traceback (most recent call last):
  File "/home/vid/makereport/DTPreport/env/lib/python3.6/site-packages/django/core/handlers/exception.py", line 47, in inner
    response = get_response(request)
  File "/home/vid/makereport/DTPreport/env/lib/python3.6/site-packages/django/core/handlers/base.py", line 181, in _get_response
    response = wrapped_callback(request, *callback_args, **callback_kwargs)
  File "/home/vid/makereport/DTPreport/makereport/utils.py", line 100, in verifyPkcs7
    get_verifyPkcs7(report_id)
  File "/home/vid/makereport/DTPreport/makereport/utils.py", line 56, in get_verifyPkcs7
    my_file.write(formatted_output)
UnicodeEncodeError: 'ascii' codec can't encode characters in position 315-322: ordinal not in range(128)
Internal Server Error: /report/ajax/verifyPkcs7/
Traceback (most recent call last):
  File "/home/vid/makereport/DTPreport/env/lib/python3.6/site-packages/django/core/handlers/exception.py", line 47, in inner
    response = get_response(request)
  File "/home/vid/makereport/DTPreport/env/lib/python3.6/site-packages/django/core/handlers/base.py", line 181, in _get_response
    response = wrapped_callback(request, *callback_args, **callback_kwargs)
  File "/home/vid/makereport/DTPreport/makereport/utils.py", line 100, in verifyPkcs7
    get_verifyPkcs7(report_id)
  File "/home/vid/makereport/DTPreport/makereport/utils.py", line 56, in get_verifyPkcs7
    my_file.write(formatted_output)
UnicodeEncodeError: 'ascii' codec can't encode characters in position 315-322: ordinal not in range(128)
Internal Server Error: /pdf/11/
Traceback (most recent call last):
  File "/home/vid/makereport/DTPreport/env/lib/python3.6/site-packages/django/core/handlers/exception.py", line 47, in inner
    response = get_response(request)
  File "/home/vid/makereport/DTPreport/env/lib/python3.6/site-packages/django/core/handlers/base.py", line 181, in _get_response
    response = wrapped_callback(request, *callback_args, **callback_kwargs)
  File "/home/vid/makereport/DTPreport/env/lib/python3.6/site-packages/django/views/generic/base.py", line 70, in view
    return self.dispatch(request, *args, **kwargs)
  File "/home/vid/makereport/DTPreport/env/lib/python3.6/site-packages/django/views/generic/base.py", line 98, in dispatch
    return handler(request, *args, **kwargs)
  File "/home/vid/makereport/DTPreport/pdf_report/views.py", line 16, in get
    get_response(request, id)
  File "/home/vid/makereport/DTPreport/pdf_report/views.py", line 42, in get_response
    pdf.generate(context)
  File "/home/vid/makereport/DTPreport/pdf_report/utils.py", line 602, in generate
    self.parse()
  File "/home/vid/makereport/DTPreport/pdf_report/utils.py", line 576, in parse
    self.parser.Parse(self.xml)
  File "../Modules/pyexpat.c", line 284, in CharacterData
  File "/home/vid/makereport/DTPreport/pdf_report/utils.py", line 560, in handler
    method(cdata)
  File "/home/vid/makereport/DTPreport/pdf_report/utils.py", line 668, in barcode_cdata
    b = self.barcode_stack.pop()
IndexError: pop from empty list
Internal Server Error: /pdf/11/
Traceback (most recent call last):
  File "/home/vid/makereport/DTPreport/env/lib/python3.6/site-packages/django/core/handlers/exception.py", line 47, in inner
    response = get_response(request)
  File "/home/vid/makereport/DTPreport/env/lib/python3.6/site-packages/django/core/handlers/base.py", line 181, in _get_response
    response = wrapped_callback(request, *callback_args, **callback_kwargs)
  File "/home/vid/makereport/DTPreport/env/lib/python3.6/site-packages/django/views/generic/base.py", line 70, in view
    return self.dispatch(request, *args, **kwargs)
  File "/home/vid/makereport/DTPreport/env/lib/python3.6/site-packages/django/views/generic/base.py", line 98, in dispatch
    return handler(request, *args, **kwargs)
  File "/home/vid/makereport/DTPreport/pdf_report/views.py", line 16, in get
    get_response(request, id)
  File "/home/vid/makereport/DTPreport/pdf_report/views.py", line 42, in get_response
    pdf.generate(context)
  File "/home/vid/makereport/DTPreport/pdf_report/utils.py", line 602, in generate
    self.parse()
  File "/home/vid/makereport/DTPreport/pdf_report/utils.py", line 576, in parse
    self.parser.Parse(self.xml)
  File "../Modules/pyexpat.c", line 284, in CharacterData
  File "/home/vid/makereport/DTPreport/pdf_report/utils.py", line 560, in handler
    method(cdata)
  File "/home/vid/makereport/DTPreport/pdf_report/utils.py", line 668, in barcode_cdata
    b = self.barcode_stack.pop()
IndexError: pop from empty list
